package FaithCraft2.Common.common.worldgen;

import java.util.ArrayList;
import java.util.Random;

import net.minecraft.block.Block;
import net.minecraft.block.BlockChest;
import net.minecraft.block.BlockDoor;
import net.minecraft.block.BlockDoor.EnumDoorHalf;
import net.minecraft.block.BlockStainedGlass;
import net.minecraft.block.BlockStainedGlassPane;
import net.minecraft.block.BlockStairs;
import net.minecraft.entity.item.EntityItemFrame;
import net.minecraft.init.Blocks;
import net.minecraft.init.Items;
import net.minecraft.item.EnumDyeColor;
import net.minecraft.item.ItemDoor;
import net.minecraft.item.ItemStack;
import net.minecraft.tileentity.TileEntityChest;
import net.minecraft.util.BlockPos;
import net.minecraft.util.EnumFacing;
import net.minecraft.world.World;
import FaithCraft2.Common.common.FaithCraft2;
import FaithCraft2.Common.common.blocks.Altar;

public class ChurchBuild {
	public boolean generate(World world, Random random, int i2, int k2) {
		int i = i2 + random.nextInt(15);
		int k = k2 + random.nextInt(15);
		
		int j = random.nextInt((230 - 75) + 1) + 75;
		if((random.nextInt(1000000)+1)<=1000){
		 world.setBlockState(new BlockPos(i + 0, j + 0, k + 0), Block.getStateById(201), 1);
	      world.setBlockState(new BlockPos(i + 1, j + 0, k + 0), Block.getStateById(201), 1);
	      world.setBlockState(new BlockPos(i + 2, j + 0, k + 0), Block.getStateById(201), 1);
	      world.setBlockState(new BlockPos(i + 3, j + 0, k + 0), Block.getStateById(201), 1);
	      world.setBlockState(new BlockPos(i + 4, j + 0, k + 0), Block.getStateById(201), 1);
	      world.setBlockState(new BlockPos(i + 5, j + 0, k + 0), Block.getStateById(201), 1);
	      world.setBlockState(new BlockPos(i + 6, j + 0, k + 0), Block.getStateById(201), 1);
	      world.setBlockState(new BlockPos(i + 7, j + 0, k + 0), Block.getStateById(201), 1);
	      world.setBlockState(new BlockPos(i + 8, j + 0, k + 0), Block.getStateById(201), 1);
	      world.setBlockState(new BlockPos(i + 9, j + 0, k + 0), Block.getStateById(201), 1);
	      world.setBlockState(new BlockPos(i + 10, j + 0, k + 0), Block.getStateById(201), 1);
	      world.setBlockState(new BlockPos(i + 11, j + 0, k + 0), Block.getStateById(201), 1);
	      world.setBlockState(new BlockPos(i + 0, j + 0, k + 1), Block.getStateById(201), 1);
	      world.setBlockState(new BlockPos(i + 1, j + 0, k + 1), Block.getStateById(201), 1);
	      world.setBlockState(new BlockPos(i + 2, j + 0, k + 1), Block.getStateById(201), 1);
	      world.setBlockState(new BlockPos(i + 3, j + 0, k + 1), Block.getStateById(201), 1);
	      world.setBlockState(new BlockPos(i + 4, j + 0, k + 1), Block.getStateById(201), 1);
	      world.setBlockState(new BlockPos(i + 5, j + 0, k + 1), Block.getStateById(201), 1);
	      world.setBlockState(new BlockPos(i + 6, j + 0, k + 1), Block.getStateById(201), 1);
	      world.setBlockState(new BlockPos(i + 7, j + 0, k + 1), Block.getStateById(201), 1);
	      world.setBlockState(new BlockPos(i + 8, j + 0, k + 1), Block.getStateById(201), 1);
	      world.setBlockState(new BlockPos(i + 9, j + 0, k + 1), Block.getStateById(201), 1);
	      world.setBlockState(new BlockPos(i + 10, j + 0, k + 1), Block.getStateById(201), 1);
	      world.setBlockState(new BlockPos(i + 11, j + 0, k + 1), Block.getStateById(201), 1);
	      world.setBlockState(new BlockPos(i + 0, j + 0, k + 2), Block.getStateById(201), 1);
	      world.setBlockState(new BlockPos(i + 1, j + 0, k + 2), Block.getStateById(201), 1);
	      world.setBlockState(new BlockPos(i + 2, j + 0, k + 2), Block.getStateById(57), 1);
	      world.setBlockState(new BlockPos(i + 3, j + 0, k + 2), Block.getStateById(203), 1);
	      world.setBlockState(new BlockPos(i + 4, j + 0, k + 2), Block.getStateById(203), 1);
	      world.setBlockState(new BlockPos(i + 5, j + 0, k + 2), Block.getStateById(203), 1);
	      world.setBlockState(new BlockPos(i + 6, j + 0, k + 2), Block.getStateById(203), 1);
	      world.setBlockState(new BlockPos(i + 7, j + 0, k + 2), Block.getStateById(203), 1);
	      world.setBlockState(new BlockPos(i + 8, j + 0, k + 2), Block.getStateById(203), 1);
	      world.setBlockState(new BlockPos(i + 9, j + 0, k + 2), Block.getStateById(57), 1);
	      world.setBlockState(new BlockPos(i + 10, j + 0, k + 2), Block.getStateById(201), 1);
	      world.setBlockState(new BlockPos(i + 11, j + 0, k + 2), Block.getStateById(201), 1);
	      world.setBlockState(new BlockPos(i + 0, j + 0, k + 3), Block.getStateById(201), 1);
	      world.setBlockState(new BlockPos(i + 1, j + 0, k + 3), Block.getStateById(201), 1);
	      world.setBlockState(new BlockPos(i + 2, j + 0, k + 3), Block.getStateById(201), 1);
	      world.setBlockState(new BlockPos(i + 3, j + 0, k + 3), Block.getStateById(201), 1);
	      world.setBlockState(new BlockPos(i + 4, j + 0, k + 3), Block.getStateById(203), 1);
	      world.setBlockState(new BlockPos(i + 5, j + 0, k + 3), Block.getStateById(203), 1);
	      world.setBlockState(new BlockPos(i + 6, j + 0, k + 3), Block.getStateById(203), 1);
	      world.setBlockState(new BlockPos(i + 7, j + 0, k + 3), Block.getStateById(203), 1);
	      world.setBlockState(new BlockPos(i + 8, j + 0, k + 3), Block.getStateById(201), 1);
	      world.setBlockState(new BlockPos(i + 9, j + 0, k + 3), Block.getStateById(201), 1);
	      world.setBlockState(new BlockPos(i + 10, j + 0, k + 3), Block.getStateById(201), 1);
	      world.setBlockState(new BlockPos(i + 11, j + 0, k + 3), Block.getStateById(201), 1);
	      world.setBlockState(new BlockPos(i + 0, j + 0, k + 4), Block.getStateById(201), 1);
	      world.setBlockState(new BlockPos(i + 1, j + 0, k + 4), Block.getStateById(201), 1);
	      world.setBlockState(new BlockPos(i + 2, j + 0, k + 4), Block.getStateById(201), 1);
	      world.setBlockState(new BlockPos(i + 3, j + 0, k + 4), Block.getStateById(201), 1);
	      world.setBlockState(new BlockPos(i + 4, j + 0, k + 4), Block.getStateById(201), 1);
	      world.setBlockState(new BlockPos(i + 5, j + 0, k + 4), Block.getStateById(203), 1);
	      world.setBlockState(new BlockPos(i + 6, j + 0, k + 4), Block.getStateById(203), 1);
	      world.setBlockState(new BlockPos(i + 7, j + 0, k + 4), Block.getStateById(201), 1);
	      world.setBlockState(new BlockPos(i + 8, j + 0, k + 4), Block.getStateById(201), 1);
	      world.setBlockState(new BlockPos(i + 9, j + 0, k + 4), Block.getStateById(201), 1);
	      world.setBlockState(new BlockPos(i + 10, j + 0, k + 4), Block.getStateById(201), 1);
	      world.setBlockState(new BlockPos(i + 11, j + 0, k + 4), Block.getStateById(201), 1);
	      world.setBlockState(new BlockPos(i + 0, j + 0, k + 5), Block.getStateById(201), 1);
	      world.setBlockState(new BlockPos(i + 1, j + 0, k + 5), Block.getStateById(201), 1);
	      world.setBlockState(new BlockPos(i + 2, j + 0, k + 5), Block.getStateById(201), 1);
	      world.setBlockState(new BlockPos(i + 3, j + 0, k + 5), Block.getStateById(201), 1);
	      world.setBlockState(new BlockPos(i + 4, j + 0, k + 5), Block.getStateById(201), 1);
	      world.setBlockState(new BlockPos(i + 5, j + 0, k + 5), Block.getStateById(203), 1);
	      world.setBlockState(new BlockPos(i + 6, j + 0, k + 5), Block.getStateById(203), 1);
	      world.setBlockState(new BlockPos(i + 7, j + 0, k + 5), Block.getStateById(201), 1);
	      world.setBlockState(new BlockPos(i + 8, j + 0, k + 5), Block.getStateById(201), 1);
	      world.setBlockState(new BlockPos(i + 9, j + 0, k + 5), Block.getStateById(201), 1);
	      world.setBlockState(new BlockPos(i + 10, j + 0, k + 5), Block.getStateById(201), 1);
	      world.setBlockState(new BlockPos(i + 11, j + 0, k + 5), Block.getStateById(201), 1);
	      world.setBlockState(new BlockPos(i + 0, j + 0, k + 6), Block.getStateById(201), 1);
	      world.setBlockState(new BlockPos(i + 1, j + 0, k + 6), Block.getStateById(201), 1);
	      world.setBlockState(new BlockPos(i + 2, j + 0, k + 6), Block.getStateById(201), 1);
	      world.setBlockState(new BlockPos(i + 3, j + 0, k + 6), Block.getStateById(201), 1);
	      world.setBlockState(new BlockPos(i + 4, j + 0, k + 6), Block.getStateById(201), 1);
	      world.setBlockState(new BlockPos(i + 5, j + 0, k + 6), Block.getStateById(203), 1);
	      world.setBlockState(new BlockPos(i + 6, j + 0, k + 6), Block.getStateById(203), 1);
	      world.setBlockState(new BlockPos(i + 7, j + 0, k + 6), Block.getStateById(201), 1);
	      world.setBlockState(new BlockPos(i + 8, j + 0, k + 6), Block.getStateById(201), 1);
	      world.setBlockState(new BlockPos(i + 9, j + 0, k + 6), Block.getStateById(201), 1);
	      world.setBlockState(new BlockPos(i + 10, j + 0, k + 6), Block.getStateById(201), 1);
	      world.setBlockState(new BlockPos(i + 11, j + 0, k + 6), Block.getStateById(201), 1);
	      world.setBlockState(new BlockPos(i + 0, j + 0, k + 7), Block.getStateById(201), 1);
	      world.setBlockState(new BlockPos(i + 1, j + 0, k + 7), Block.getStateById(201), 1);
	      world.setBlockState(new BlockPos(i + 2, j + 0, k + 7), Block.getStateById(201), 1);
	      world.setBlockState(new BlockPos(i + 3, j + 0, k + 7), Block.getStateById(201), 1);
	      world.setBlockState(new BlockPos(i + 4, j + 0, k + 7), Block.getStateById(201), 1);
	      world.setBlockState(new BlockPos(i + 5, j + 0, k + 7), Block.getStateById(203), 1);
	      world.setBlockState(new BlockPos(i + 6, j + 0, k + 7), Block.getStateById(203), 1);
	      world.setBlockState(new BlockPos(i + 7, j + 0, k + 7), Block.getStateById(201), 1);
	      world.setBlockState(new BlockPos(i + 8, j + 0, k + 7), Block.getStateById(201), 1);
	      world.setBlockState(new BlockPos(i + 9, j + 0, k + 7), Block.getStateById(201), 1);
	      world.setBlockState(new BlockPos(i + 10, j + 0, k + 7), Block.getStateById(201), 1);
	      world.setBlockState(new BlockPos(i + 11, j + 0, k + 7), Block.getStateById(201), 1);
	      world.setBlockState(new BlockPos(i + 0, j + 0, k + 8), Block.getStateById(201), 1);
	      world.setBlockState(new BlockPos(i + 1, j + 0, k + 8), Block.getStateById(201), 1);
	      world.setBlockState(new BlockPos(i + 2, j + 0, k + 8), Block.getStateById(201), 1);
	      world.setBlockState(new BlockPos(i + 3, j + 0, k + 8), Block.getStateById(201), 1);
	      world.setBlockState(new BlockPos(i + 4, j + 0, k + 8), Block.getStateById(201), 1);
	      world.setBlockState(new BlockPos(i + 5, j + 0, k + 8), Block.getStateById(203), 1);
	      world.setBlockState(new BlockPos(i + 6, j + 0, k + 8), Block.getStateById(203), 1);
	      world.setBlockState(new BlockPos(i + 7, j + 0, k + 8), Block.getStateById(201), 1);
	      world.setBlockState(new BlockPos(i + 8, j + 0, k + 8), Block.getStateById(201), 1);
	      world.setBlockState(new BlockPos(i + 9, j + 0, k + 8), Block.getStateById(201), 1);
	      world.setBlockState(new BlockPos(i + 10, j + 0, k + 8), Block.getStateById(201), 1);
	      world.setBlockState(new BlockPos(i + 11, j + 0, k + 8), Block.getStateById(201), 1);
	      world.setBlockState(new BlockPos(i + 0, j + 0, k + 9), Block.getStateById(201), 1);
	      world.setBlockState(new BlockPos(i + 1, j + 0, k + 9), Block.getStateById(201), 1);
	      world.setBlockState(new BlockPos(i + 2, j + 0, k + 9), Block.getStateById(201), 1);
	      world.setBlockState(new BlockPos(i + 3, j + 0, k + 9), Block.getStateById(201), 1);
	      world.setBlockState(new BlockPos(i + 4, j + 0, k + 9), Block.getStateById(201), 1);
	      world.setBlockState(new BlockPos(i + 5, j + 0, k + 9), Block.getStateById(203), 1);
	      world.setBlockState(new BlockPos(i + 6, j + 0, k + 9), Block.getStateById(203), 1);
	      world.setBlockState(new BlockPos(i + 7, j + 0, k + 9), Block.getStateById(201), 1);
	      world.setBlockState(new BlockPos(i + 8, j + 0, k + 9), Block.getStateById(201), 1);
	      world.setBlockState(new BlockPos(i + 9, j + 0, k + 9), Block.getStateById(201), 1);
	      world.setBlockState(new BlockPos(i + 10, j + 0, k + 9), Block.getStateById(201), 1);
	      world.setBlockState(new BlockPos(i + 11, j + 0, k + 9), Block.getStateById(201), 1);
	      world.setBlockState(new BlockPos(i + 0, j + 0, k + 10), Block.getStateById(201), 1);
	      world.setBlockState(new BlockPos(i + 1, j + 0, k + 10), Block.getStateById(201), 1);
	      world.setBlockState(new BlockPos(i + 2, j + 0, k + 10), Block.getStateById(201), 1);
	      world.setBlockState(new BlockPos(i + 3, j + 0, k + 10), Block.getStateById(201), 1);
	      world.setBlockState(new BlockPos(i + 4, j + 0, k + 10), Block.getStateById(201), 1);
	      world.setBlockState(new BlockPos(i + 5, j + 0, k + 10), Block.getStateById(203), 1);
	      world.setBlockState(new BlockPos(i + 6, j + 0, k + 10), Block.getStateById(203), 1);
	      world.setBlockState(new BlockPos(i + 7, j + 0, k + 10), Block.getStateById(201), 1);
	      world.setBlockState(new BlockPos(i + 8, j + 0, k + 10), Block.getStateById(201), 1);
	      world.setBlockState(new BlockPos(i + 9, j + 0, k + 10), Block.getStateById(201), 1);
	      world.setBlockState(new BlockPos(i + 10, j + 0, k + 10), Block.getStateById(201), 1);
	      world.setBlockState(new BlockPos(i + 11, j + 0, k + 10), Block.getStateById(201), 1);
	      world.setBlockState(new BlockPos(i + 0, j + 0, k + 11), Block.getStateById(201), 1);
	      world.setBlockState(new BlockPos(i + 1, j + 0, k + 11), Block.getStateById(201), 1);
	      world.setBlockState(new BlockPos(i + 2, j + 0, k + 11), Block.getStateById(201), 1);
	      world.setBlockState(new BlockPos(i + 3, j + 0, k + 11), Block.getStateById(201), 1);
	      world.setBlockState(new BlockPos(i + 4, j + 0, k + 11), Block.getStateById(201), 1);
	      world.setBlockState(new BlockPos(i + 5, j + 0, k + 11), Block.getStateById(203), 1);
	      world.setBlockState(new BlockPos(i + 6, j + 0, k + 11), Block.getStateById(203), 1);
	      world.setBlockState(new BlockPos(i + 7, j + 0, k + 11), Block.getStateById(201), 1);
	      world.setBlockState(new BlockPos(i + 8, j + 0, k + 11), Block.getStateById(201), 1);
	      world.setBlockState(new BlockPos(i + 9, j + 0, k + 11), Block.getStateById(201), 1);
	      world.setBlockState(new BlockPos(i + 10, j + 0, k + 11), Block.getStateById(201), 1);
	      world.setBlockState(new BlockPos(i + 11, j + 0, k + 11), Block.getStateById(201), 1);
	      world.setBlockState(new BlockPos(i + 0, j + 0, k + 12), Block.getStateById(201), 1);
	      world.setBlockState(new BlockPos(i + 1, j + 0, k + 12), Block.getStateById(201), 1);
	      world.setBlockState(new BlockPos(i + 2, j + 0, k + 12), Block.getStateById(201), 1);
	      world.setBlockState(new BlockPos(i + 3, j + 0, k + 12), Block.getStateById(201), 1);
	      world.setBlockState(new BlockPos(i + 4, j + 0, k + 12), Block.getStateById(201), 1);
	      world.setBlockState(new BlockPos(i + 5, j + 0, k + 12), Block.getStateById(203), 1);
	      world.setBlockState(new BlockPos(i + 6, j + 0, k + 12), Block.getStateById(203), 1);
	      world.setBlockState(new BlockPos(i + 7, j + 0, k + 12), Block.getStateById(201), 1);
	      world.setBlockState(new BlockPos(i + 8, j + 0, k + 12), Block.getStateById(201), 1);
	      world.setBlockState(new BlockPos(i + 9, j + 0, k + 12), Block.getStateById(201), 1);
	      world.setBlockState(new BlockPos(i + 10, j + 0, k + 12), Block.getStateById(201), 1);
	      world.setBlockState(new BlockPos(i + 11, j + 0, k + 12), Block.getStateById(201), 1);
	      world.setBlockState(new BlockPos(i + 0, j + 0, k + 13), Block.getStateById(201), 1);
	      world.setBlockState(new BlockPos(i + 1, j + 0, k + 13), Block.getStateById(201), 1);
	      world.setBlockState(new BlockPos(i + 2, j + 0, k + 13), Block.getStateById(201), 1);
	      world.setBlockState(new BlockPos(i + 3, j + 0, k + 13), Block.getStateById(201), 1);
	      world.setBlockState(new BlockPos(i + 4, j + 0, k + 13), Block.getStateById(201), 1);
	      world.setBlockState(new BlockPos(i + 5, j + 0, k + 13), Block.getStateById(203), 1);
	      world.setBlockState(new BlockPos(i + 6, j + 0, k + 13), Block.getStateById(203), 1);
	      world.setBlockState(new BlockPos(i + 7, j + 0, k + 13), Block.getStateById(201), 1);
	      world.setBlockState(new BlockPos(i + 8, j + 0, k + 13), Block.getStateById(201), 1);
	      world.setBlockState(new BlockPos(i + 9, j + 0, k + 13), Block.getStateById(201), 1);
	      world.setBlockState(new BlockPos(i + 10, j + 0, k + 13), Block.getStateById(201), 1);
	      world.setBlockState(new BlockPos(i + 11, j + 0, k + 13), Block.getStateById(201), 1);
	      world.setBlockState(new BlockPos(i + 0, j + 0, k + 14), Block.getStateById(201), 1);
	      world.setBlockState(new BlockPos(i + 1, j + 0, k + 14), Block.getStateById(201), 1);
	      world.setBlockState(new BlockPos(i + 2, j + 0, k + 14), Block.getStateById(201), 1);
	      world.setBlockState(new BlockPos(i + 3, j + 0, k + 14), Block.getStateById(201), 1);
	      world.setBlockState(new BlockPos(i + 4, j + 0, k + 14), Block.getStateById(201), 1);
	      world.setBlockState(new BlockPos(i + 5, j + 0, k + 14), Block.getStateById(201), 1);
	      world.setBlockState(new BlockPos(i + 6, j + 0, k + 14), Block.getStateById(201), 1);
	      world.setBlockState(new BlockPos(i + 7, j + 0, k + 14), Block.getStateById(201), 1);
	      world.setBlockState(new BlockPos(i + 8, j + 0, k + 14), Block.getStateById(201), 1);
	      world.setBlockState(new BlockPos(i + 9, j + 0, k + 14), Block.getStateById(201), 1);
	      world.setBlockState(new BlockPos(i + 10, j + 0, k + 14), Block.getStateById(201), 1);
	      world.setBlockState(new BlockPos(i + 11, j + 0, k + 14), Block.getStateById(201), 1);
	      world.setBlockState(new BlockPos(i + 0, j + 0, k + 15), Block.getStateById(201), 1);
	      world.setBlockState(new BlockPos(i + 1, j + 0, k + 15), Block.getStateById(201), 1);
	      world.setBlockState(new BlockPos(i + 2, j + 0, k + 15), Block.getStateById(203), 1);
	      world.setBlockState(new BlockPos(i + 3, j + 0, k + 15), Block.getStateById(201), 1);
	      world.setBlockState(new BlockPos(i + 4, j + 0, k + 15), Block.getStateById(201), 1);
	      world.setBlockState(new BlockPos(i + 5, j + 0, k + 15), Block.getStateById(201), 1);
	      world.setBlockState(new BlockPos(i + 6, j + 0, k + 15), Block.getStateById(201), 1);
	      world.setBlockState(new BlockPos(i + 7, j + 0, k + 15), Block.getStateById(201), 1);
	      world.setBlockState(new BlockPos(i + 8, j + 0, k + 15), Block.getStateById(201), 1);
	      world.setBlockState(new BlockPos(i + 9, j + 0, k + 15), Block.getStateById(203), 1);
	      world.setBlockState(new BlockPos(i + 10, j + 0, k + 15), Block.getStateById(201), 1);
	      world.setBlockState(new BlockPos(i + 11, j + 0, k + 15), Block.getStateById(201), 1);
	      world.setBlockState(new BlockPos(i + 0, j + 0, k + 16), Block.getStateById(201), 1);
	      world.setBlockState(new BlockPos(i + 1, j + 0, k + 16), Block.getStateById(201), 1);
	      world.setBlockState(new BlockPos(i + 2, j + 0, k + 16), Block.getStateById(201), 1);
	      world.setBlockState(new BlockPos(i + 3, j + 0, k + 16), Block.getStateById(201), 1);
	      world.setBlockState(new BlockPos(i + 4, j + 0, k + 16), Block.getStateById(201), 1);
	      world.setBlockState(new BlockPos(i + 5, j + 0, k + 16), Block.getStateById(201), 1);
	      world.setBlockState(new BlockPos(i + 6, j + 0, k + 16), Block.getStateById(201), 1);
	      world.setBlockState(new BlockPos(i + 7, j + 0, k + 16), Block.getStateById(201), 1);
	      world.setBlockState(new BlockPos(i + 8, j + 0, k + 16), Block.getStateById(201), 1);
	      world.setBlockState(new BlockPos(i + 9, j + 0, k + 16), Block.getStateById(201), 1);
	      world.setBlockState(new BlockPos(i + 10, j + 0, k + 16), Block.getStateById(201), 1);
	      world.setBlockState(new BlockPos(i + 11, j + 0, k + 16), Block.getStateById(201), 1);
	      world.setBlockState(new BlockPos(i + 0, j + 0, k + 17), Block.getStateById(201), 1);
	      world.setBlockState(new BlockPos(i + 1, j + 0, k + 17), Block.getStateById(201), 1);
	      world.setBlockState(new BlockPos(i + 2, j + 0, k + 17), Block.getStateById(201), 1);
	      world.setBlockState(new BlockPos(i + 3, j + 0, k + 17), Block.getStateById(201), 1);
	      world.setBlockState(new BlockPos(i + 4, j + 0, k + 17), Block.getStateById(201), 1);
	      world.setBlockState(new BlockPos(i + 5, j + 0, k + 17), Block.getStateById(201), 1);
	      world.setBlockState(new BlockPos(i + 6, j + 0, k + 17), Block.getStateById(201), 1);
	      world.setBlockState(new BlockPos(i + 7, j + 0, k + 17), Block.getStateById(201), 1);
	      world.setBlockState(new BlockPos(i + 8, j + 0, k + 17), Block.getStateById(201), 1);
	      world.setBlockState(new BlockPos(i + 9, j + 0, k + 17), Block.getStateById(201), 1);
	      world.setBlockState(new BlockPos(i + 10, j + 0, k + 17), Block.getStateById(201), 1);
	      world.setBlockState(new BlockPos(i + 11, j + 0, k + 17), Block.getStateById(201), 1);
	      world.setBlockState(new BlockPos(i + 0, j + 0, k + 18), Block.getStateById(0), 1);
	      world.setBlockState(new BlockPos(i + 1, j + 0, k + 18), Block.getStateById(0), 1);
	      world.setBlockState(new BlockPos(i + 2, j + 0, k + 18), Block.getStateById(0), 1);
	      world.setBlockState(new BlockPos(i + 3, j + 0, k + 18), Block.getStateById(0), 1);
	      world.setBlockState(new BlockPos(i + 4, j + 0, k + 18), Block.getStateById(0), 1);
	      world.setBlockState(new BlockPos(i + 5, j + 0, k + 18), Block.getStateById(201), 1);
	      world.setBlockState(new BlockPos(i + 6, j + 0, k + 18), Block.getStateById(201), 1);
	      world.setBlockState(new BlockPos(i + 7, j + 0, k + 18), Block.getStateById(0), 1);
	      world.setBlockState(new BlockPos(i + 8, j + 0, k + 18), Block.getStateById(0), 1);
	      world.setBlockState(new BlockPos(i + 9, j + 0, k + 18), Block.getStateById(0), 1);
	      world.setBlockState(new BlockPos(i + 10, j + 0, k + 18), Block.getStateById(0), 1);
	      world.setBlockState(new BlockPos(i + 11, j + 0, k + 18), Block.getStateById(0), 1);
	      world.setBlockState(new BlockPos(i + 0, j + 0, k + 19), Block.getStateById(0), 1);
	      world.setBlockState(new BlockPos(i + 1, j + 0, k + 19), Block.getStateById(0), 1);
	      world.setBlockState(new BlockPos(i + 2, j + 0, k + 19), Block.getStateById(0), 1);
	      world.setBlockState(new BlockPos(i + 3, j + 0, k + 19), Block.getStateById(0), 1);
	      world.setBlockState(new BlockPos(i + 4, j + 0, k + 19), Block.getStateById(0), 1);
	      world.setBlockState(new BlockPos(i + 5, j + 0, k + 19), Block.getStateById(109).withProperty(BlockStairs.FACING, EnumFacing.NORTH), 1);
	      world.setBlockState(new BlockPos(i + 6, j + 0, k + 19), Block.getStateById(109).withProperty(BlockStairs.FACING, EnumFacing.NORTH), 1);
	      world.setBlockState(new BlockPos(i + 7, j + 0, k + 19), Block.getStateById(0), 1);
	      world.setBlockState(new BlockPos(i + 8, j + 0, k + 19), Block.getStateById(0), 1);
	      world.setBlockState(new BlockPos(i + 9, j + 0, k + 19), Block.getStateById(0), 1);
	      world.setBlockState(new BlockPos(i + 10, j + 0, k + 19), Block.getStateById(0), 1);
	      world.setBlockState(new BlockPos(i + 11, j + 0, k + 19), Block.getStateById(0), 1);
	      world.setBlockState(new BlockPos(i + 0, j + 1, k + 0), Block.getStateById(0), 1);
	      world.setBlockState(new BlockPos(i + 1, j + 1, k + 0), Block.getStateById(0), 1);
	      world.setBlockState(new BlockPos(i + 2, j + 1, k + 0), Block.getStateById(0), 1);
	      world.setBlockState(new BlockPos(i + 3, j + 1, k + 0), Block.getStateById(0), 1);
	      world.setBlockState(new BlockPos(i + 4, j + 1, k + 0), Block.getStateById(0), 1);
	      world.setBlockState(new BlockPos(i + 5, j + 1, k + 0), Block.getStateById(0), 1);
	      world.setBlockState(new BlockPos(i + 6, j + 1, k + 0), Block.getStateById(0), 1);
	      world.setBlockState(new BlockPos(i + 7, j + 1, k + 0), Block.getStateById(0), 1);
	      world.setBlockState(new BlockPos(i + 8, j + 1, k + 0), Block.getStateById(0), 1);
	      world.setBlockState(new BlockPos(i + 9, j + 1, k + 0), Block.getStateById(0), 1);
	      world.setBlockState(new BlockPos(i + 10, j + 1, k + 0), Block.getStateById(0), 1);
	      world.setBlockState(new BlockPos(i + 11, j + 1, k + 0), Block.getStateById(0), 1);
	      world.setBlockState(new BlockPos(i + 0, j + 1, k + 1), Block.getStateById(0), 1);
	      world.setBlockState(new BlockPos(i + 1, j + 1, k + 1), Block.getStateById(201), 1);
	      world.setBlockState(new BlockPos(i + 2, j + 1, k + 1), Block.getStateById(201), 1);
	      world.setBlockState(new BlockPos(i + 3, j + 1, k + 1), Block.getStateById(160), 1);
	      world.setBlockState(new BlockPos(i + 4, j + 1, k + 1), Block.getStateById(160).withProperty(BlockStainedGlassPane.COLOR, EnumDyeColor.YELLOW), 1);
	      world.setBlockState(new BlockPos(i + 5, j + 1, k + 1), Block.getStateById(203), 1);
	      world.setBlockState(new BlockPos(i + 6, j + 1, k + 1), Block.getStateById(203), 1);
	      world.setBlockState(new BlockPos(i + 7, j + 1, k + 1), Block.getStateById(160).withProperty(BlockStainedGlassPane.COLOR, EnumDyeColor.YELLOW), 1);
	      world.setBlockState(new BlockPos(i + 8, j + 1, k + 1), Block.getStateById(160), 1);
	      world.setBlockState(new BlockPos(i + 9, j + 1, k + 1), Block.getStateById(201), 1);
	      world.setBlockState(new BlockPos(i + 10, j + 1, k + 1), Block.getStateById(201), 1);
	      world.setBlockState(new BlockPos(i + 11, j + 1, k + 1), Block.getStateById(0), 1);
	      world.setBlockState(new BlockPos(i + 0, j + 1, k + 2), Block.getStateById(0), 1);
	      world.setBlockState(new BlockPos(i + 1, j + 1, k + 2), Block.getStateById(201), 1);
	      world.setBlockState(new BlockPos(i + 2, j + 1, k + 2), Block.getStateById(203), 1);
	      world.setBlockState(new BlockPos(i + 3, j + 1, k + 2), Block.getStateById(0), 1);
	      world.setBlockState(new BlockPos(i + 4, j + 1, k + 2), Block.getStateById(0), 1);
	      world.setBlockState(new BlockPos(i + 5, j + 1, k + 2), Block.getStateById(198).withProperty(Altar.FACING, EnumFacing.NORTH), 1);
	      world.setBlockState(new BlockPos(i + 6, j + 1, k + 2), Block.getStateById(198).withProperty(Altar.FACING, EnumFacing.NORTH), 1);
	      world.setBlockState(new BlockPos(i + 7, j + 1, k + 2), Block.getStateById(0), 1);
	      world.setBlockState(new BlockPos(i + 8, j + 1, k + 2), Block.getStateById(0), 1);
	      world.setBlockState(new BlockPos(i + 9, j + 1, k + 2), Block.getStateById(203), 1);
	      world.setBlockState(new BlockPos(i + 10, j + 1, k + 2), Block.getStateById(201), 1);
	      world.setBlockState(new BlockPos(i + 11, j + 1, k + 2), Block.getStateById(0), 1);
	      world.setBlockState(new BlockPos(i + 0, j + 1, k + 3), Block.getStateById(0), 1);
	      world.setBlockState(new BlockPos(i + 1, j + 1, k + 3), Block.getStateById(201), 1);
	      world.setBlockState(new BlockPos(i + 2, j + 1, k + 3), Block.getStateById(0), 1);
	      world.setBlockState(new BlockPos(i + 3, j + 1, k + 3), Block.getStateById(0), 1);
	      world.setBlockState(new BlockPos(i + 4, j + 1, k + 3), Block.getStateById(0), 1);
	      world.setBlockState(new BlockPos(i + 5, j + 1, k + 3), Block.getStateById(0), 1);
	      world.setBlockState(new BlockPos(i + 6, j + 1, k + 3), Block.getStateById(0), 1);
	      world.setBlockState(new BlockPos(i + 7, j + 1, k + 3), Block.getStateById(0), 1);
	      world.setBlockState(new BlockPos(i + 8, j + 1, k + 3), Block.getStateById(0), 1);
	      world.setBlockState(new BlockPos(i + 9, j + 1, k + 3), Block.getStateById(0), 1);
	      world.setBlockState(new BlockPos(i + 10, j + 1, k + 3), Block.getStateById(201), 1);
	      world.setBlockState(new BlockPos(i + 11, j + 1, k + 3), Block.getStateById(0), 1);
	      world.setBlockState(new BlockPos(i + 0, j + 1, k + 4), Block.getStateById(0), 1);
	      world.setBlockState(new BlockPos(i + 1, j + 1, k + 4), Block.getStateById(201), 1);
	      world.setBlockState(new BlockPos(i + 2, j + 1, k + 4), Block.getStateById(0), 1);
	      world.setBlockState(new BlockPos(i + 3, j + 1, k + 4), Block.getStateById(0), 1);
	      world.setBlockState(new BlockPos(i + 4, j + 1, k + 4), Block.getStateById(0), 1);
	      world.setBlockState(new BlockPos(i + 5, j + 1, k + 4), Block.getStateById(0), 1);
	      world.setBlockState(new BlockPos(i + 6, j + 1, k + 4), Block.getStateById(0), 1);
	      world.setBlockState(new BlockPos(i + 7, j + 1, k + 4), Block.getStateById(0), 1);
	      world.setBlockState(new BlockPos(i + 8, j + 1, k + 4), Block.getStateById(0), 1);
	      world.setBlockState(new BlockPos(i + 9, j + 1, k + 4), Block.getStateById(0), 1);
	      world.setBlockState(new BlockPos(i + 10, j + 1, k + 4), Block.getStateById(201), 1);
	      world.setBlockState(new BlockPos(i + 11, j + 1, k + 4), Block.getStateById(0), 1);
	      world.setBlockState(new BlockPos(i + 0, j + 1, k + 5), Block.getStateById(0), 1);
	      world.setBlockState(new BlockPos(i + 1, j + 1, k + 5), Block.getStateById(201), 1);
	      world.setBlockState(new BlockPos(i + 2, j + 1, k + 5), Block.getStateById(0), 1);
	      world.setBlockState(new BlockPos(i + 3, j + 1, k + 5), Block.getStateById(0), 1);
	      world.setBlockState(new BlockPos(i + 4, j + 1, k + 5), Block.getStateById(0), 1);
	      world.setBlockState(new BlockPos(i + 5, j + 1, k + 5), Block.getStateById(0), 1);
	      world.setBlockState(new BlockPos(i + 6, j + 1, k + 5), Block.getStateById(0), 1);
	      world.setBlockState(new BlockPos(i + 7, j + 1, k + 5), Block.getStateById(0), 1);
	      world.setBlockState(new BlockPos(i + 8, j + 1, k + 5), Block.getStateById(0), 1);
	      world.setBlockState(new BlockPos(i + 9, j + 1, k + 5), Block.getStateById(0), 1);
	      world.setBlockState(new BlockPos(i + 10, j + 1, k + 5), Block.getStateById(201), 1);
	      world.setBlockState(new BlockPos(i + 11, j + 1, k + 5), Block.getStateById(0), 1);
	      world.setBlockState(new BlockPos(i + 0, j + 1, k + 6), Block.getStateById(0), 1);
	      world.setBlockState(new BlockPos(i + 1, j + 1, k + 6), Block.getStateById(201), 1);
	      world.setBlockState(new BlockPos(i + 2, j + 1, k + 6), Block.getStateById(0), 1);
	      world.setBlockState(new BlockPos(i + 3, j + 1, k + 6), Block.getStateById(0), 1);
	      world.setBlockState(new BlockPos(i + 4, j + 1, k + 6), Block.getStateById(0), 1);
	      world.setBlockState(new BlockPos(i + 5, j + 1, k + 6), Block.getStateById(0), 1);
	      world.setBlockState(new BlockPos(i + 6, j + 1, k + 6), Block.getStateById(0), 1);
	      world.setBlockState(new BlockPos(i + 7, j + 1, k + 6), Block.getStateById(0), 1);
	      world.setBlockState(new BlockPos(i + 8, j + 1, k + 6), Block.getStateById(0), 1);
	      world.setBlockState(new BlockPos(i + 9, j + 1, k + 6), Block.getStateById(0), 1);
	      world.setBlockState(new BlockPos(i + 10, j + 1, k + 6), Block.getStateById(201), 1);
	      world.setBlockState(new BlockPos(i + 11, j + 1, k + 6), Block.getStateById(0), 1);
	      world.setBlockState(new BlockPos(i + 0, j + 1, k + 7), Block.getStateById(0), 1);
	      world.setBlockState(new BlockPos(i + 1, j + 1, k + 7), Block.getStateById(201), 1);
	      world.setBlockState(new BlockPos(i + 2, j + 1, k + 7), Block.getStateById(0), 1);
	      world.setBlockState(new BlockPos(i + 3, j + 1, k + 7), Block.getStateById(0), 1);
	      world.setBlockState(new BlockPos(i + 4, j + 1, k + 7), Block.getStateById(0), 1);
	      world.setBlockState(new BlockPos(i + 5, j + 1, k + 7), Block.getStateById(0), 1);
	      world.setBlockState(new BlockPos(i + 6, j + 1, k + 7), Block.getStateById(0), 1);
	      world.setBlockState(new BlockPos(i + 7, j + 1, k + 7), Block.getStateById(0), 1);
	      world.setBlockState(new BlockPos(i + 8, j + 1, k + 7), Block.getStateById(0), 1);
	      world.setBlockState(new BlockPos(i + 9, j + 1, k + 7), Block.getStateById(0), 1);
	      world.setBlockState(new BlockPos(i + 10, j + 1, k + 7), Block.getStateById(201), 1);
	      world.setBlockState(new BlockPos(i + 11, j + 1, k + 7), Block.getStateById(0), 1);
	      world.setBlockState(new BlockPos(i + 0, j + 1, k + 8), Block.getStateById(0), 1);
	      world.setBlockState(new BlockPos(i + 1, j + 1, k + 8), Block.getStateById(201), 1);
	      world.setBlockState(new BlockPos(i + 2, j + 1, k + 8), Block.getStateById(0), 1);
	      world.setBlockState(new BlockPos(i + 3, j + 1, k + 8), Block.getStateById(202), 1);
	      world.setBlockState(new BlockPos(i + 4, j + 1, k + 8), Block.getStateById(202), 1);
	      world.setBlockState(new BlockPos(i + 5, j + 1, k + 8), Block.getStateById(0), 1);
	      world.setBlockState(new BlockPos(i + 6, j + 1, k + 8), Block.getStateById(0), 1);
	      world.setBlockState(new BlockPos(i + 7, j + 1, k + 8), Block.getStateById(0), 1);
	      world.setBlockState(new BlockPos(i + 8, j + 1, k + 8), Block.getStateById(0), 1);
	      world.setBlockState(new BlockPos(i + 9, j + 1, k + 8), Block.getStateById(0), 1);
	      world.setBlockState(new BlockPos(i + 10, j + 1, k + 8), Block.getStateById(201), 1);
	      world.setBlockState(new BlockPos(i + 11, j + 1, k + 8), Block.getStateById(0), 1);
	      world.setBlockState(new BlockPos(i + 0, j + 1, k + 9), Block.getStateById(0), 1);
	      world.setBlockState(new BlockPos(i + 1, j + 1, k + 9), Block.getStateById(201), 1);
	      world.setBlockState(new BlockPos(i + 2, j + 1, k + 9), Block.getStateById(0), 1);
	      world.setBlockState(new BlockPos(i + 3, j + 1, k + 9), Block.getStateById(202), 1);
	      world.setBlockState(new BlockPos(i + 4, j + 1, k + 9), Block.getStateById(67).withProperty(BlockStairs.FACING, EnumFacing.NORTH), 1);
	      world.setBlockState(new BlockPos(i + 5, j + 1, k + 9), Block.getStateById(0), 1);
	      world.setBlockState(new BlockPos(i + 6, j + 1, k + 9), Block.getStateById(0), 1);
	      world.setBlockState(new BlockPos(i + 7, j + 1, k + 9), Block.getStateById(0), 1);
	      world.setBlockState(new BlockPos(i + 8, j + 1, k + 9), Block.getStateById(0), 1);
	      world.setBlockState(new BlockPos(i + 9, j + 1, k + 9), Block.getStateById(0), 1);
	      world.setBlockState(new BlockPos(i + 10, j + 1, k + 9), Block.getStateById(201), 1);
	      world.setBlockState(new BlockPos(i + 11, j + 1, k + 9), Block.getStateById(0), 1);
	      world.setBlockState(new BlockPos(i + 0, j + 1, k + 10), Block.getStateById(0), 1);
	      world.setBlockState(new BlockPos(i + 1, j + 1, k + 10), Block.getStateById(201), 1);
	      world.setBlockState(new BlockPos(i + 2, j + 1, k + 10), Block.getStateById(0), 1);
	      world.setBlockState(new BlockPos(i + 3, j + 1, k + 10), Block.getStateById(0), 1);
	      world.setBlockState(new BlockPos(i + 4, j + 1, k + 10), Block.getStateById(0), 1);
	      world.setBlockState(new BlockPos(i + 5, j + 1, k + 10), Block.getStateById(0), 1);
	      world.setBlockState(new BlockPos(i + 6, j + 1, k + 10), Block.getStateById(0), 1);
	      world.setBlockState(new BlockPos(i + 7, j + 1, k + 10), Block.getStateById(0), 1);
	      world.setBlockState(new BlockPos(i + 8, j + 1, k + 10), Block.getStateById(0), 1);
	      world.setBlockState(new BlockPos(i + 9, j + 1, k + 10), Block.getStateById(0), 1);
	      world.setBlockState(new BlockPos(i + 10, j + 1, k + 10), Block.getStateById(201), 1);
	      world.setBlockState(new BlockPos(i + 11, j + 1, k + 10), Block.getStateById(0), 1);
	      world.setBlockState(new BlockPos(i + 0, j + 1, k + 11), Block.getStateById(0), 1);
	      world.setBlockState(new BlockPos(i + 1, j + 1, k + 11), Block.getStateById(201), 1);
	      world.setBlockState(new BlockPos(i + 2, j + 1, k + 11), Block.getStateById(0), 1);
	      world.setBlockState(new BlockPos(i + 3, j + 1, k + 11), Block.getStateById(0), 1);
	      world.setBlockState(new BlockPos(i + 4, j + 1, k + 11), Block.getStateById(0), 1);
	      world.setBlockState(new BlockPos(i + 5, j + 1, k + 11), Block.getStateById(0), 1);
	      world.setBlockState(new BlockPos(i + 6, j + 1, k + 11), Block.getStateById(0), 1);
	      world.setBlockState(new BlockPos(i + 7, j + 1, k + 11), Block.getStateById(0), 1);
	      world.setBlockState(new BlockPos(i + 8, j + 1, k + 11), Block.getStateById(0), 1);
	      world.setBlockState(new BlockPos(i + 9, j + 1, k + 11), Block.getStateById(0), 1);
	      world.setBlockState(new BlockPos(i + 10, j + 1, k + 11), Block.getStateById(201), 1);
	      world.setBlockState(new BlockPos(i + 11, j + 1, k + 11), Block.getStateById(0), 1);
	      world.setBlockState(new BlockPos(i + 0, j + 1, k + 12), Block.getStateById(0), 1);
	      world.setBlockState(new BlockPos(i + 1, j + 1, k + 12), Block.getStateById(201), 1);
	      world.setBlockState(new BlockPos(i + 2, j + 1, k + 12), Block.getStateById(0), 1);
	      world.setBlockState(new BlockPos(i + 3, j + 1, k + 12), Block.getStateById(0), 1);
	      world.setBlockState(new BlockPos(i + 4, j + 1, k + 12), Block.getStateById(0), 1);
	      world.setBlockState(new BlockPos(i + 5, j + 1, k + 12), Block.getStateById(0), 1);
	      world.setBlockState(new BlockPos(i + 6, j + 1, k + 12), Block.getStateById(0), 1);
	      world.setBlockState(new BlockPos(i + 7, j + 1, k + 12), Block.getStateById(0), 1);
	      world.setBlockState(new BlockPos(i + 8, j + 1, k + 12), Block.getStateById(0), 1);
	      world.setBlockState(new BlockPos(i + 9, j + 1, k + 12), Block.getStateById(0), 1);
	      world.setBlockState(new BlockPos(i + 10, j + 1, k + 12), Block.getStateById(201), 1);
	      world.setBlockState(new BlockPos(i + 11, j + 1, k + 12), Block.getStateById(0), 1);
	      world.setBlockState(new BlockPos(i + 0, j + 1, k + 13), Block.getStateById(0), 1);
	      world.setBlockState(new BlockPos(i + 1, j + 1, k + 13), Block.getStateById(201), 1);
	      world.setBlockState(new BlockPos(i + 2, j + 1, k + 13), Block.getStateById(0), 1);
	      world.setBlockState(new BlockPos(i + 3, j + 1, k + 13), Block.getStateById(0), 1);
	      world.setBlockState(new BlockPos(i + 4, j + 1, k + 13), Block.getStateById(109).withProperty(BlockStairs.FACING, EnumFacing.EAST), 1);
	      world.setBlockState(new BlockPos(i + 5, j + 1, k + 13), Block.getStateById(109).withProperty(BlockStairs.FACING, EnumFacing.SOUTH), 1);
	      world.setBlockState(new BlockPos(i + 6, j + 1, k + 13), Block.getStateById(109).withProperty(BlockStairs.FACING, EnumFacing.SOUTH), 1);
	      world.setBlockState(new BlockPos(i + 7, j + 1, k + 13), Block.getStateById(109).withProperty(BlockStairs.FACING, EnumFacing.WEST), 1);
	      world.setBlockState(new BlockPos(i + 8, j + 1, k + 13), Block.getStateById(0), 1);
	      world.setBlockState(new BlockPos(i + 9, j + 1, k + 13), Block.getStateById(0), 1);
	      world.setBlockState(new BlockPos(i + 10, j + 1, k + 13), Block.getStateById(201), 1);
	      world.setBlockState(new BlockPos(i + 11, j + 1, k + 13), Block.getStateById(0), 1);
	      world.setBlockState(new BlockPos(i + 0, j + 1, k + 14), Block.getStateById(0), 1);
	      world.setBlockState(new BlockPos(i + 1, j + 1, k + 14), Block.getStateById(201), 1);
	      world.setBlockState(new BlockPos(i + 2, j + 1, k + 14), Block.getStateById(0), 1);
	      world.setBlockState(new BlockPos(i + 3, j + 1, k + 14), Block.getStateById(0), 1);
	      world.setBlockState(new BlockPos(i + 4, j + 1, k + 14), Block.getStateById(109).withProperty(BlockStairs.FACING, EnumFacing.NORTH), 1);
	      world.setBlockState(new BlockPos(i + 5, j + 1, k + 14), Block.getStateById(201), 1);
	      world.setBlockState(new BlockPos(i + 6, j + 1, k + 14), Block.getStateById(201), 1);
	      world.setBlockState(new BlockPos(i + 7, j + 1, k + 14), Block.getStateById(109).withProperty(BlockStairs.FACING, EnumFacing.NORTH), 1);
	      world.setBlockState(new BlockPos(i + 8, j + 1, k + 14), Block.getStateById(0), 1);
	      world.setBlockState(new BlockPos(i + 9, j + 1, k + 14), Block.getStateById(0), 1);
	      world.setBlockState(new BlockPos(i + 10, j + 1, k + 14), Block.getStateById(201), 1);
	      world.setBlockState(new BlockPos(i + 11, j + 1, k + 14), Block.getStateById(0), 1);
	      world.setBlockState(new BlockPos(i + 0, j + 1, k + 15), Block.getStateById(0), 1);
	      world.setBlockState(new BlockPos(i + 1, j + 1, k + 15), Block.getStateById(201), 1);
	      world.setBlockState(new BlockPos(i + 2, j + 1, k + 15), Block.getStateById(0), 1);
	      world.setBlockState(new BlockPos(i + 3, j + 1, k + 15), Block.getStateById(203), 1);
	      world.setBlockState(new BlockPos(i + 4, j + 1, k + 15), Block.getStateById(201), 1);
	      world.setBlockState(new BlockPos(i + 5, j + 1, k + 15), Block.getStateById(201), 1);
	      world.setBlockState(new BlockPos(i + 6, j + 1, k + 15), Block.getStateById(201), 1);
	      world.setBlockState(new BlockPos(i + 7, j + 1, k + 15), Block.getStateById(201), 1);
	      world.setBlockState(new BlockPos(i + 8, j + 1, k + 15), Block.getStateById(203), 1);
	      world.setBlockState(new BlockPos(i + 9, j + 1, k + 15), Block.getStateById(0), 1);
	      world.setBlockState(new BlockPos(i + 10, j + 1, k + 15), Block.getStateById(201), 1);
	      world.setBlockState(new BlockPos(i + 11, j + 1, k + 15), Block.getStateById(0), 1);
	      world.setBlockState(new BlockPos(i + 0, j + 1, k + 16), Block.getStateById(0), 1);
	      world.setBlockState(new BlockPos(i + 1, j + 1, k + 16), Block.getStateById(201), 1);
	      world.setBlockState(new BlockPos(i + 2, j + 1, k + 16), Block.getStateById(201), 1);
	      world.setBlockState(new BlockPos(i + 3, j + 1, k + 16), Block.getStateById(201), 1);
	      world.setBlockState(new BlockPos(i + 4, j + 1, k + 16), Block.getStateById(201), 1);
	      world.setBlockState(new BlockPos(i + 5, j + 1, k + 16), Block.getStateById(201), 1);
	      world.setBlockState(new BlockPos(i + 6, j + 1, k + 16), Block.getStateById(201), 1);
	      world.setBlockState(new BlockPos(i + 7, j + 1, k + 16), Block.getStateById(201), 1);
	      world.setBlockState(new BlockPos(i + 8, j + 1, k + 16), Block.getStateById(201), 1);
	      world.setBlockState(new BlockPos(i + 9, j + 1, k + 16), Block.getStateById(201), 1);
	      world.setBlockState(new BlockPos(i + 10, j + 1, k + 16), Block.getStateById(201), 1);
	      world.setBlockState(new BlockPos(i + 11, j + 1, k + 16), Block.getStateById(0), 1);
	      world.setBlockState(new BlockPos(i + 0, j + 1, k + 17), Block.getStateById(0), 1);
	      world.setBlockState(new BlockPos(i + 1, j + 1, k + 17), Block.getStateById(0), 1);
	      world.setBlockState(new BlockPos(i + 2, j + 1, k + 17), Block.getStateById(0), 1);
	      world.setBlockState(new BlockPos(i + 3, j + 1, k + 17), Block.getStateById(0), 1);
	      world.setBlockState(new BlockPos(i + 4, j + 1, k + 17), Block.getStateById(0), 1);
	      world.setBlockState(new BlockPos(i + 5, j + 1, k + 17), Block.getStateById(109).withProperty(BlockStairs.FACING, EnumFacing.NORTH), 1);
	      world.setBlockState(new BlockPos(i + 6, j + 1, k + 17), Block.getStateById(109).withProperty(BlockStairs.FACING, EnumFacing.NORTH), 1);
	      world.setBlockState(new BlockPos(i + 7, j + 1, k + 17), Block.getStateById(0), 1);
	      world.setBlockState(new BlockPos(i + 8, j + 1, k + 17), Block.getStateById(0), 1);
	      world.setBlockState(new BlockPos(i + 9, j + 1, k + 17), Block.getStateById(0), 1);
	      world.setBlockState(new BlockPos(i + 10, j + 1, k + 17), Block.getStateById(0), 1);
	      world.setBlockState(new BlockPos(i + 11, j + 1, k + 17), Block.getStateById(0), 1);
	      world.setBlockState(new BlockPos(i + 0, j + 1, k + 18), Block.getStateById(0), 1);
	      world.setBlockState(new BlockPos(i + 1, j + 1, k + 18), Block.getStateById(0), 1);
	      world.setBlockState(new BlockPos(i + 2, j + 1, k + 18), Block.getStateById(0), 1);
	      world.setBlockState(new BlockPos(i + 3, j + 1, k + 18), Block.getStateById(0), 1);
	      world.setBlockState(new BlockPos(i + 4, j + 1, k + 18), Block.getStateById(0), 1);
	      world.setBlockState(new BlockPos(i + 5, j + 1, k + 18), Block.getStateById(0), 1);
	      world.setBlockState(new BlockPos(i + 6, j + 1, k + 18), Block.getStateById(0), 1);
	      world.setBlockState(new BlockPos(i + 7, j + 1, k + 18), Block.getStateById(0), 1);
	      world.setBlockState(new BlockPos(i + 8, j + 1, k + 18), Block.getStateById(0), 1);
	      world.setBlockState(new BlockPos(i + 9, j + 1, k + 18), Block.getStateById(0), 1);
	      world.setBlockState(new BlockPos(i + 10, j + 1, k + 18), Block.getStateById(0), 1);
	      world.setBlockState(new BlockPos(i + 11, j + 1, k + 18), Block.getStateById(0), 1);
	      world.setBlockState(new BlockPos(i + 0, j + 1, k + 19), Block.getStateById(0), 1);
	      world.setBlockState(new BlockPos(i + 1, j + 1, k + 19), Block.getStateById(0), 1);
	      world.setBlockState(new BlockPos(i + 2, j + 1, k + 19), Block.getStateById(0), 1);
	      world.setBlockState(new BlockPos(i + 3, j + 1, k + 19), Block.getStateById(0), 1);
	      world.setBlockState(new BlockPos(i + 4, j + 1, k + 19), Block.getStateById(0), 1);
	      world.setBlockState(new BlockPos(i + 5, j + 1, k + 19), Block.getStateById(0), 1);
	      world.setBlockState(new BlockPos(i + 6, j + 1, k + 19), Block.getStateById(0), 1);
	      world.setBlockState(new BlockPos(i + 7, j + 1, k + 19), Block.getStateById(0), 1);
	      world.setBlockState(new BlockPos(i + 8, j + 1, k + 19), Block.getStateById(0), 1);
	      world.setBlockState(new BlockPos(i + 9, j + 1, k + 19), Block.getStateById(0), 1);
	      world.setBlockState(new BlockPos(i + 10, j + 1, k + 19), Block.getStateById(0), 1);
	      world.setBlockState(new BlockPos(i + 11, j + 1, k + 19), Block.getStateById(0), 1);
	      world.setBlockState(new BlockPos(i + 0, j + 2, k + 0), Block.getStateById(0), 1);
	      world.setBlockState(new BlockPos(i + 1, j + 2, k + 0), Block.getStateById(0), 1);
	      world.setBlockState(new BlockPos(i + 2, j + 2, k + 0), Block.getStateById(0), 1);
	      world.setBlockState(new BlockPos(i + 3, j + 2, k + 0), Block.getStateById(0), 1);
	      world.setBlockState(new BlockPos(i + 4, j + 2, k + 0), Block.getStateById(0), 1);
	      world.setBlockState(new BlockPos(i + 5, j + 2, k + 0), Block.getStateById(0), 1);
	      world.setBlockState(new BlockPos(i + 6, j + 2, k + 0), Block.getStateById(0), 1);
	      world.setBlockState(new BlockPos(i + 7, j + 2, k + 0), Block.getStateById(0), 1);
	      world.setBlockState(new BlockPos(i + 8, j + 2, k + 0), Block.getStateById(0), 1);
	      world.setBlockState(new BlockPos(i + 9, j + 2, k + 0), Block.getStateById(0), 1);
	      world.setBlockState(new BlockPos(i + 10, j + 2, k + 0), Block.getStateById(0), 1);
	      world.setBlockState(new BlockPos(i + 11, j + 2, k + 0), Block.getStateById(0), 1);
	      world.setBlockState(new BlockPos(i + 0, j + 2, k + 1), Block.getStateById(0), 1);
	      world.setBlockState(new BlockPos(i + 1, j + 2, k + 1), Block.getStateById(201), 1);
	      world.setBlockState(new BlockPos(i + 2, j + 2, k + 1), Block.getStateById(201), 1);
	      world.setBlockState(new BlockPos(i + 3, j + 2, k + 1), Block.getStateById(160).withProperty(BlockStainedGlassPane.COLOR, EnumDyeColor.YELLOW), 1);
	      world.setBlockState(new BlockPos(i + 4, j + 2, k + 1), Block.getStateById(160), 1);
	      world.setBlockState(new BlockPos(i + 5, j + 2, k + 1), Block.getStateById(203), 1);
	      world.setBlockState(new BlockPos(i + 6, j + 2, k + 1), Block.getStateById(203), 1);
	      world.setBlockState(new BlockPos(i + 7, j + 2, k + 1), Block.getStateById(160), 1);
	      world.setBlockState(new BlockPos(i + 8, j + 2, k + 1), Block.getStateById(160).withProperty(BlockStainedGlassPane.COLOR, EnumDyeColor.YELLOW), 1);
	      world.setBlockState(new BlockPos(i + 9, j + 2, k + 1), Block.getStateById(201), 1);
	      world.setBlockState(new BlockPos(i + 10, j + 2, k + 1), Block.getStateById(201), 1);
	      world.setBlockState(new BlockPos(i + 11, j + 2, k + 1), Block.getStateById(0), 1);
	      world.setBlockState(new BlockPos(i + 0, j + 2, k + 2), Block.getStateById(0), 1);
	      world.setBlockState(new BlockPos(i + 1, j + 2, k + 2), Block.getStateById(201), 1);
	      world.setBlockState(new BlockPos(i + 2, j + 2, k + 2), Block.getStateById(203), 1);
	      world.setBlockState(new BlockPos(i + 3, j + 2, k + 2), Block.getStateById(0), 1);
	      world.setBlockState(new BlockPos(i + 4, j + 2, k + 2), Block.getStateById(0), 1);
	      world.setBlockState(new BlockPos(i + 5, j + 2, k + 2), Block.getStateById(0), 1);
	      world.setBlockState(new BlockPos(i + 6, j + 2, k + 2), Block.getStateById(0), 1);
	      world.setBlockState(new BlockPos(i + 7, j + 2, k + 2), Block.getStateById(0), 1);
	      world.setBlockState(new BlockPos(i + 8, j + 2, k + 2), Block.getStateById(0), 1);
	      world.setBlockState(new BlockPos(i + 9, j + 2, k + 2), Block.getStateById(203), 1);
	      world.setBlockState(new BlockPos(i + 10, j + 2, k + 2), Block.getStateById(201), 1);
	      world.setBlockState(new BlockPos(i + 11, j + 2, k + 2), Block.getStateById(0), 1);
	      world.setBlockState(new BlockPos(i + 0, j + 2, k + 3), Block.getStateById(0), 1);
	      world.setBlockState(new BlockPos(i + 1, j + 2, k + 3), Block.getStateById(201), 1);
	      world.setBlockState(new BlockPos(i + 2, j + 2, k + 3), Block.getStateById(0), 1);
	      world.setBlockState(new BlockPos(i + 3, j + 2, k + 3), Block.getStateById(0), 1);
	      world.setBlockState(new BlockPos(i + 4, j + 2, k + 3), Block.getStateById(0), 1);
	      world.setBlockState(new BlockPos(i + 5, j + 2, k + 3), Block.getStateById(0), 1);
	      world.setBlockState(new BlockPos(i + 6, j + 2, k + 3), Block.getStateById(0), 1);
	      world.setBlockState(new BlockPos(i + 7, j + 2, k + 3), Block.getStateById(0), 1);
	      world.setBlockState(new BlockPos(i + 8, j + 2, k + 3), Block.getStateById(0), 1);
	      world.setBlockState(new BlockPos(i + 9, j + 2, k + 3), Block.getStateById(0), 1);
	      world.setBlockState(new BlockPos(i + 10, j + 2, k + 3), Block.getStateById(201), 1);
	      world.setBlockState(new BlockPos(i + 11, j + 2, k + 3), Block.getStateById(0), 1);
	      world.setBlockState(new BlockPos(i + 0, j + 2, k + 4), Block.getStateById(0), 1);
	      world.setBlockState(new BlockPos(i + 1, j + 2, k + 4), Block.getStateById(201), 1);
	      world.setBlockState(new BlockPos(i + 2, j + 2, k + 4), Block.getStateById(0), 1);
	      world.setBlockState(new BlockPos(i + 3, j + 2, k + 4), Block.getStateById(0), 1);
	      world.setBlockState(new BlockPos(i + 4, j + 2, k + 4), Block.getStateById(0), 1);
	      world.setBlockState(new BlockPos(i + 5, j + 2, k + 4), Block.getStateById(0), 1);
	      world.setBlockState(new BlockPos(i + 6, j + 2, k + 4), Block.getStateById(0), 1);
	      world.setBlockState(new BlockPos(i + 7, j + 2, k + 4), Block.getStateById(0), 1);
	      world.setBlockState(new BlockPos(i + 8, j + 2, k + 4), Block.getStateById(0), 1);
	      world.setBlockState(new BlockPos(i + 9, j + 2, k + 4), Block.getStateById(0), 1);
	      world.setBlockState(new BlockPos(i + 10, j + 2, k + 4), Block.getStateById(201), 1);
	      world.setBlockState(new BlockPos(i + 11, j + 2, k + 4), Block.getStateById(0), 1);
	      world.setBlockState(new BlockPos(i + 0, j + 2, k + 5), Block.getStateById(0), 1);
	      world.setBlockState(new BlockPos(i + 1, j + 2, k + 5), Block.getStateById(201), 1);
	      world.setBlockState(new BlockPos(i + 2, j + 2, k + 5), Block.getStateById(0), 1);
	      world.setBlockState(new BlockPos(i + 3, j + 2, k + 5), Block.getStateById(0), 1);
	      world.setBlockState(new BlockPos(i + 4, j + 2, k + 5), Block.getStateById(0), 1);
	      world.setBlockState(new BlockPos(i + 5, j + 2, k + 5), Block.getStateById(0), 1);
	      world.setBlockState(new BlockPos(i + 6, j + 2, k + 5), Block.getStateById(0), 1);
	      world.setBlockState(new BlockPos(i + 7, j + 2, k + 5), Block.getStateById(0), 1);
	      world.setBlockState(new BlockPos(i + 8, j + 2, k + 5), Block.getStateById(0), 1);
	      world.setBlockState(new BlockPos(i + 9, j + 2, k + 5), Block.getStateById(0), 1);
	      world.setBlockState(new BlockPos(i + 10, j + 2, k + 5), Block.getStateById(201), 1);
	      world.setBlockState(new BlockPos(i + 11, j + 2, k + 5), Block.getStateById(0), 1);
	      world.setBlockState(new BlockPos(i + 0, j + 2, k + 6), Block.getStateById(0), 1);
	      world.setBlockState(new BlockPos(i + 1, j + 2, k + 6), Block.getStateById(201), 1);
	      world.setBlockState(new BlockPos(i + 2, j + 2, k + 6), Block.getStateById(0), 1);
	      world.setBlockState(new BlockPos(i + 3, j + 2, k + 6), Block.getStateById(0), 1);
	      world.setBlockState(new BlockPos(i + 4, j + 2, k + 6), Block.getStateById(0), 1);
	      world.setBlockState(new BlockPos(i + 5, j + 2, k + 6), Block.getStateById(0), 1);
	      world.setBlockState(new BlockPos(i + 6, j + 2, k + 6), Block.getStateById(0), 1);
	      world.setBlockState(new BlockPos(i + 7, j + 2, k + 6), Block.getStateById(0), 1);
	      world.setBlockState(new BlockPos(i + 8, j + 2, k + 6), Block.getStateById(0), 1);
	      world.setBlockState(new BlockPos(i + 9, j + 2, k + 6), Block.getStateById(0), 1);
	      world.setBlockState(new BlockPos(i + 10, j + 2, k + 6), Block.getStateById(201), 1);
	      world.setBlockState(new BlockPos(i + 11, j + 2, k + 6), Block.getStateById(0), 1);
	      world.setBlockState(new BlockPos(i + 0, j + 2, k + 7), Block.getStateById(0), 1);
	      world.setBlockState(new BlockPos(i + 1, j + 2, k + 7), Block.getStateById(201), 1);
	      world.setBlockState(new BlockPos(i + 2, j + 2, k + 7), Block.getStateById(0), 1);
	      world.setBlockState(new BlockPos(i + 3, j + 2, k + 7), Block.getStateById(0), 1);
	      world.setBlockState(new BlockPos(i + 4, j + 2, k + 7), Block.getStateById(0), 1);
	      world.setBlockState(new BlockPos(i + 5, j + 2, k + 7), Block.getStateById(0), 1);
	      world.setBlockState(new BlockPos(i + 6, j + 2, k + 7), Block.getStateById(0), 1);
	      world.setBlockState(new BlockPos(i + 7, j + 2, k + 7), Block.getStateById(0), 1);
	      world.setBlockState(new BlockPos(i + 8, j + 2, k + 7), Block.getStateById(0), 1);
	      world.setBlockState(new BlockPos(i + 9, j + 2, k + 7), Block.getStateById(0), 1);
	      world.setBlockState(new BlockPos(i + 10, j + 2, k + 7), Block.getStateById(201), 1);
	      world.setBlockState(new BlockPos(i + 11, j + 2, k + 7), Block.getStateById(0), 1);
	      world.setBlockState(new BlockPos(i + 0, j + 2, k + 8), Block.getStateById(0), 1);
	      world.setBlockState(new BlockPos(i + 1, j + 2, k + 8), Block.getStateById(201), 1);
	      world.setBlockState(new BlockPos(i + 2, j + 2, k + 8), Block.getStateById(202), 1);
	      world.setBlockState(new BlockPos(i + 3, j + 2, k + 8), Block.getStateById(67).withProperty(BlockStairs.FACING, EnumFacing.WEST), 1);
	      world.setBlockState(new BlockPos(i + 4, j + 2, k + 8), Block.getStateById(0), 1);
	      world.setBlockState(new BlockPos(i + 5, j + 2, k + 8), Block.getStateById(0), 1);
	      world.setBlockState(new BlockPos(i + 6, j + 2, k + 8), Block.getStateById(0), 1);
	      world.setBlockState(new BlockPos(i + 7, j + 2, k + 8), Block.getStateById(0), 1);
	      world.setBlockState(new BlockPos(i + 8, j + 2, k + 8), Block.getStateById(0), 1);
	      world.setBlockState(new BlockPos(i + 9, j + 2, k + 8), Block.getStateById(0), 1);
	      world.setBlockState(new BlockPos(i + 10, j + 2, k + 8), Block.getStateById(201), 1);
	      world.setBlockState(new BlockPos(i + 11, j + 2, k + 8), Block.getStateById(0), 1);
	      world.setBlockState(new BlockPos(i + 0, j + 2, k + 9), Block.getStateById(0), 1);
	      world.setBlockState(new BlockPos(i + 1, j + 2, k + 9), Block.getStateById(201), 1);
	      world.setBlockState(new BlockPos(i + 2, j + 2, k + 9), Block.getStateById(202), 1);
	      world.setBlockState(new BlockPos(i + 3, j + 2, k + 9), Block.getStateById(202), 1);
	      world.setBlockState(new BlockPos(i + 4, j + 2, k + 9), Block.getStateById(0), 1);
	      world.setBlockState(new BlockPos(i + 5, j + 2, k + 9), Block.getStateById(0), 1);
	      world.setBlockState(new BlockPos(i + 6, j + 2, k + 9), Block.getStateById(0), 1);
	      world.setBlockState(new BlockPos(i + 7, j + 2, k + 9), Block.getStateById(0), 1);
	      world.setBlockState(new BlockPos(i + 8, j + 2, k + 9), Block.getStateById(0), 1);
	      world.setBlockState(new BlockPos(i + 9, j + 2, k + 9), Block.getStateById(0), 1);
	      world.setBlockState(new BlockPos(i + 10, j + 2, k + 9), Block.getStateById(201), 1);
	      world.setBlockState(new BlockPos(i + 11, j + 2, k + 9), Block.getStateById(0), 1);
	      world.setBlockState(new BlockPos(i + 0, j + 2, k + 10), Block.getStateById(0), 1);
	      world.setBlockState(new BlockPos(i + 1, j + 2, k + 10), Block.getStateById(201), 1);
	      world.setBlockState(new BlockPos(i + 2, j + 2, k + 10), Block.getStateById(0), 1);
	      world.setBlockState(new BlockPos(i + 3, j + 2, k + 10), Block.getStateById(0), 1);
	      world.setBlockState(new BlockPos(i + 4, j + 2, k + 10), Block.getStateById(0), 1);
	      world.setBlockState(new BlockPos(i + 5, j + 2, k + 10), Block.getStateById(0), 1);
	      world.setBlockState(new BlockPos(i + 6, j + 2, k + 10), Block.getStateById(0), 1);
	      world.setBlockState(new BlockPos(i + 7, j + 2, k + 10), Block.getStateById(0), 1);
	      world.setBlockState(new BlockPos(i + 8, j + 2, k + 10), Block.getStateById(0), 1);
	      world.setBlockState(new BlockPos(i + 9, j + 2, k + 10), Block.getStateById(0), 1);
	      world.setBlockState(new BlockPos(i + 10, j + 2, k + 10), Block.getStateById(201), 1);
	      world.setBlockState(new BlockPos(i + 11, j + 2, k + 10), Block.getStateById(0), 1);
	      world.setBlockState(new BlockPos(i + 0, j + 2, k + 11), Block.getStateById(0), 1);
	      world.setBlockState(new BlockPos(i + 1, j + 2, k + 11), Block.getStateById(201), 1);
	      world.setBlockState(new BlockPos(i + 2, j + 2, k + 11), Block.getStateById(0), 1);
	      world.setBlockState(new BlockPos(i + 3, j + 2, k + 11), Block.getStateById(0), 1);
	      world.setBlockState(new BlockPos(i + 4, j + 2, k + 11), Block.getStateById(0), 1);
	      world.setBlockState(new BlockPos(i + 5, j + 2, k + 11), Block.getStateById(0), 1);
	      world.setBlockState(new BlockPos(i + 6, j + 2, k + 11), Block.getStateById(0), 1);
	      world.setBlockState(new BlockPos(i + 7, j + 2, k + 11), Block.getStateById(0), 1);
	      world.setBlockState(new BlockPos(i + 8, j + 2, k + 11), Block.getStateById(0), 1);
	      world.setBlockState(new BlockPos(i + 9, j + 2, k + 11), Block.getStateById(0), 1);
	      world.setBlockState(new BlockPos(i + 10, j + 2, k + 11), Block.getStateById(201), 1);
	      world.setBlockState(new BlockPos(i + 11, j + 2, k + 11), Block.getStateById(0), 1);
	      world.setBlockState(new BlockPos(i + 0, j + 2, k + 12), Block.getStateById(0), 1);
	      world.setBlockState(new BlockPos(i + 1, j + 2, k + 12), Block.getStateById(201), 1);
	      world.setBlockState(new BlockPos(i + 2, j + 2, k + 12), Block.getStateById(0), 1);
	      world.setBlockState(new BlockPos(i + 3, j + 2, k + 12), Block.getStateById(0), 1);
	      world.setBlockState(new BlockPos(i + 4, j + 2, k + 12), Block.getStateById(0), 1);
	      world.setBlockState(new BlockPos(i + 5, j + 2, k + 12), Block.getStateById(0), 1);
	      world.setBlockState(new BlockPos(i + 6, j + 2, k + 12), Block.getStateById(0), 1);
	      world.setBlockState(new BlockPos(i + 7, j + 2, k + 12), Block.getStateById(0), 1);
	      world.setBlockState(new BlockPos(i + 8, j + 2, k + 12), Block.getStateById(0), 1);
	      world.setBlockState(new BlockPos(i + 9, j + 2, k + 12), Block.getStateById(0), 1);
	      world.setBlockState(new BlockPos(i + 10, j + 2, k + 12), Block.getStateById(201), 1);
	      world.setBlockState(new BlockPos(i + 11, j + 2, k + 12), Block.getStateById(0), 1);
	      world.setBlockState(new BlockPos(i + 0, j + 2, k + 13), Block.getStateById(0), 1);
	      world.setBlockState(new BlockPos(i + 1, j + 2, k + 13), Block.getStateById(201), 1);
	      world.setBlockState(new BlockPos(i + 2, j + 2, k + 13), Block.getStateById(0), 1);
	      world.setBlockState(new BlockPos(i + 3, j + 2, k + 13), Block.getStateById(0), 1);
	      world.setBlockState(new BlockPos(i + 4, j + 2, k + 13), Block.getStateById(0), 1);
	      world.setBlockState(new BlockPos(i + 5, j + 2, k + 13), Block.getStateById(0), 1);
	      world.setBlockState(new BlockPos(i + 6, j + 2, k + 13), Block.getStateById(0), 1);
	      world.setBlockState(new BlockPos(i + 7, j + 2, k + 13), Block.getStateById(0), 1);
	      world.setBlockState(new BlockPos(i + 8, j + 2, k + 13), Block.getStateById(0), 1);
	      world.setBlockState(new BlockPos(i + 9, j + 2, k + 13), Block.getStateById(0), 1);
	      world.setBlockState(new BlockPos(i + 10, j + 2, k + 13), Block.getStateById(201), 1);
	      world.setBlockState(new BlockPos(i + 11, j + 2, k + 13), Block.getStateById(0), 1);
	      world.setBlockState(new BlockPos(i + 0, j + 2, k + 14), Block.getStateById(0), 1);
	      world.setBlockState(new BlockPos(i + 1, j + 2, k + 14), Block.getStateById(201), 1);
	      world.setBlockState(new BlockPos(i + 2, j + 2, k + 14), Block.getStateById(0), 1);
	      world.setBlockState(new BlockPos(i + 3, j + 2, k + 14), Block.getStateById(0), 1);
	      world.setBlockState(new BlockPos(i + 4, j + 2, k + 14), Block.getStateById(0), 1);
	      world.setBlockState(new BlockPos(i + 5, j + 2, k + 14), Block.getStateById(148), 1);
	      world.setBlockState(new BlockPos(i + 6, j + 2, k + 14), Block.getStateById(148), 1);
	      world.setBlockState(new BlockPos(i + 7, j + 2, k + 14), Block.getStateById(0), 1);
	      world.setBlockState(new BlockPos(i + 8, j + 2, k + 14), Block.getStateById(0), 1);
	      world.setBlockState(new BlockPos(i + 9, j + 2, k + 14), Block.getStateById(0), 1);
	      world.setBlockState(new BlockPos(i + 10, j + 2, k + 14), Block.getStateById(201), 1);
	      world.setBlockState(new BlockPos(i + 11, j + 2, k + 14), Block.getStateById(0), 1);
	      world.setBlockState(new BlockPos(i + 0, j + 2, k + 15), Block.getStateById(0), 1);
	      world.setBlockState(new BlockPos(i + 1, j + 2, k + 15), Block.getStateById(201), 1);
	      world.setBlockState(new BlockPos(i + 2, j + 2, k + 15), Block.getStateById(0), 1);
	      world.setBlockState(new BlockPos(i + 3, j + 2, k + 15), Block.getStateById(0), 1);
	      world.setBlockState(new BlockPos(i + 4, j + 2, k + 15), Block.getStateById(201), 1);
	      world.setBlockState(new BlockPos(i + 5, j + 2, k + 15), Block.getStateById(0), 1);
	      world.setBlockState(new BlockPos(i + 6, j + 2, k + 15), Block.getStateById(0), 1);
	      world.setBlockState(new BlockPos(i + 7, j + 2, k + 15), Block.getStateById(201), 1);
	      world.setBlockState(new BlockPos(i + 8, j + 2, k + 15), Block.getStateById(0), 1);
	      world.setBlockState(new BlockPos(i + 9, j + 2, k + 15), Block.getStateById(0), 1);
	      world.setBlockState(new BlockPos(i + 10, j + 2, k + 15), Block.getStateById(201), 1);
	      world.setBlockState(new BlockPos(i + 11, j + 2, k + 15), Block.getStateById(0), 1);
	      world.setBlockState(new BlockPos(i + 0, j + 2, k + 16), Block.getStateById(0), 1);
	      world.setBlockState(new BlockPos(i + 1, j + 2, k + 16), Block.getStateById(201), 1);
	      world.setBlockState(new BlockPos(i + 2, j + 2, k + 16), Block.getStateById(201), 1);
	      world.setBlockState(new BlockPos(i + 3, j + 2, k + 16), Block.getStateById(201), 1);
	      world.setBlockState(new BlockPos(i + 4, j + 2, k + 16), Block.getStateById(201), 1);
	      world.setBlockState(new BlockPos(i + 5, j + 2, k + 16), Block.getStateById(148), 1);
	      world.setBlockState(new BlockPos(i + 6, j + 2, k + 16), Block.getStateById(148), 1);
	      world.setBlockState(new BlockPos(i + 7, j + 2, k + 16), Block.getStateById(201), 1);
	      world.setBlockState(new BlockPos(i + 8, j + 2, k + 16), Block.getStateById(201), 1);
	      world.setBlockState(new BlockPos(i + 9, j + 2, k + 16), Block.getStateById(201), 1);
	      world.setBlockState(new BlockPos(i + 10, j + 2, k + 16), Block.getStateById(201), 1);
	      world.setBlockState(new BlockPos(i + 11, j + 2, k + 16), Block.getStateById(0), 1);
	      world.setBlockState(new BlockPos(i + 0, j + 2, k + 17), Block.getStateById(0), 1);
	      world.setBlockState(new BlockPos(i + 1, j + 2, k + 17), Block.getStateById(0), 1);
	      world.setBlockState(new BlockPos(i + 2, j + 2, k + 17), Block.getStateById(0), 1);
	      world.setBlockState(new BlockPos(i + 3, j + 2, k + 17), Block.getStateById(0), 1);
	      world.setBlockState(new BlockPos(i + 4, j + 2, k + 17), Block.getStateById(0), 1);
	      world.setBlockState(new BlockPos(i + 5, j + 2, k + 17), Block.getStateById(0), 1);
	      world.setBlockState(new BlockPos(i + 6, j + 2, k + 17), Block.getStateById(0), 1);
	      world.setBlockState(new BlockPos(i + 7, j + 2, k + 17), Block.getStateById(0), 1);
	      world.setBlockState(new BlockPos(i + 8, j + 2, k + 17), Block.getStateById(0), 1);
	      world.setBlockState(new BlockPos(i + 9, j + 2, k + 17), Block.getStateById(0), 1);
	      world.setBlockState(new BlockPos(i + 10, j + 2, k + 17), Block.getStateById(0), 1);
	      world.setBlockState(new BlockPos(i + 11, j + 2, k + 17), Block.getStateById(0), 1);
	      world.setBlockState(new BlockPos(i + 0, j + 2, k + 18), Block.getStateById(0), 1);
	      world.setBlockState(new BlockPos(i + 1, j + 2, k + 18), Block.getStateById(0), 1);
	      world.setBlockState(new BlockPos(i + 2, j + 2, k + 18), Block.getStateById(0), 1);
	      world.setBlockState(new BlockPos(i + 3, j + 2, k + 18), Block.getStateById(0), 1);
	      world.setBlockState(new BlockPos(i + 4, j + 2, k + 18), Block.getStateById(0), 1);
	      world.setBlockState(new BlockPos(i + 5, j + 2, k + 18), Block.getStateById(0), 1);
	      world.setBlockState(new BlockPos(i + 6, j + 2, k + 18), Block.getStateById(0), 1);
	      world.setBlockState(new BlockPos(i + 7, j + 2, k + 18), Block.getStateById(0), 1);
	      world.setBlockState(new BlockPos(i + 8, j + 2, k + 18), Block.getStateById(0), 1);
	      world.setBlockState(new BlockPos(i + 9, j + 2, k + 18), Block.getStateById(0), 1);
	      world.setBlockState(new BlockPos(i + 10, j + 2, k + 18), Block.getStateById(0), 1);
	      world.setBlockState(new BlockPos(i + 11, j + 2, k + 18), Block.getStateById(0), 1);
	      world.setBlockState(new BlockPos(i + 0, j + 2, k + 19), Block.getStateById(0), 1);
	      world.setBlockState(new BlockPos(i + 1, j + 2, k + 19), Block.getStateById(0), 1);
	      world.setBlockState(new BlockPos(i + 2, j + 2, k + 19), Block.getStateById(0), 1);
	      world.setBlockState(new BlockPos(i + 3, j + 2, k + 19), Block.getStateById(0), 1);
	      world.setBlockState(new BlockPos(i + 4, j + 2, k + 19), Block.getStateById(0), 1);
	      world.setBlockState(new BlockPos(i + 5, j + 2, k + 19), Block.getStateById(0), 1);
	      world.setBlockState(new BlockPos(i + 6, j + 2, k + 19), Block.getStateById(0), 1);
	      world.setBlockState(new BlockPos(i + 7, j + 2, k + 19), Block.getStateById(0), 1);
	      world.setBlockState(new BlockPos(i + 8, j + 2, k + 19), Block.getStateById(0), 1);
	      world.setBlockState(new BlockPos(i + 9, j + 2, k + 19), Block.getStateById(0), 1);
	      world.setBlockState(new BlockPos(i + 10, j + 2, k + 19), Block.getStateById(0), 1);
	      world.setBlockState(new BlockPos(i + 11, j + 2, k + 19), Block.getStateById(0), 1);
	      world.setBlockState(new BlockPos(i + 0, j + 3, k + 0), Block.getStateById(0), 1);
	      world.setBlockState(new BlockPos(i + 1, j + 3, k + 0), Block.getStateById(0), 1);
	      world.setBlockState(new BlockPos(i + 2, j + 3, k + 0), Block.getStateById(0), 1);
	      world.setBlockState(new BlockPos(i + 3, j + 3, k + 0), Block.getStateById(0), 1);
	      world.setBlockState(new BlockPos(i + 4, j + 3, k + 0), Block.getStateById(0), 1);
	      world.setBlockState(new BlockPos(i + 5, j + 3, k + 0), Block.getStateById(0), 1);
	      world.setBlockState(new BlockPos(i + 6, j + 3, k + 0), Block.getStateById(0), 1);
	      world.setBlockState(new BlockPos(i + 7, j + 3, k + 0), Block.getStateById(0), 1);
	      world.setBlockState(new BlockPos(i + 8, j + 3, k + 0), Block.getStateById(0), 1);
	      world.setBlockState(new BlockPos(i + 9, j + 3, k + 0), Block.getStateById(0), 1);
	      world.setBlockState(new BlockPos(i + 10, j + 3, k + 0), Block.getStateById(0), 1);
	      world.setBlockState(new BlockPos(i + 11, j + 3, k + 0), Block.getStateById(0), 1);
	      world.setBlockState(new BlockPos(i + 0, j + 3, k + 1), Block.getStateById(0), 1);
	      world.setBlockState(new BlockPos(i + 1, j + 3, k + 1), Block.getStateById(201), 1);
	      world.setBlockState(new BlockPos(i + 2, j + 3, k + 1), Block.getStateById(201), 1);
	      world.setBlockState(new BlockPos(i + 3, j + 3, k + 1), Block.getStateById(160), 1);
	      world.setBlockState(new BlockPos(i + 4, j + 3, k + 1), Block.getStateById(160).withProperty(BlockStainedGlassPane.COLOR, EnumDyeColor.YELLOW), 1);
	      world.setBlockState(new BlockPos(i + 5, j + 3, k + 1), Block.getStateById(203), 1);
	      world.setBlockState(new BlockPos(i + 6, j + 3, k + 1), Block.getStateById(203), 1);
	      world.setBlockState(new BlockPos(i + 7, j + 3, k + 1), Block.getStateById(160).withProperty(BlockStainedGlassPane.COLOR, EnumDyeColor.YELLOW), 1);
	      world.setBlockState(new BlockPos(i + 8, j + 3, k + 1), Block.getStateById(160), 1);
	      world.setBlockState(new BlockPos(i + 9, j + 3, k + 1), Block.getStateById(201), 1);
	      world.setBlockState(new BlockPos(i + 10, j + 3, k + 1), Block.getStateById(201), 1);
	      world.setBlockState(new BlockPos(i + 11, j + 3, k + 1), Block.getStateById(0), 1);
	      world.setBlockState(new BlockPos(i + 0, j + 3, k + 2), Block.getStateById(0), 1);
	      world.setBlockState(new BlockPos(i + 1, j + 3, k + 2), Block.getStateById(201), 1);
	      world.setBlockState(new BlockPos(i + 2, j + 3, k + 2), Block.getStateById(203), 1);
	      world.setBlockState(new BlockPos(i + 3, j + 3, k + 2), Block.getStateById(0), 1);
	      world.setBlockState(new BlockPos(i + 4, j + 3, k + 2), Block.getStateById(0), 1);
	      world.setBlockState(new BlockPos(i + 5, j + 3, k + 2), Block.getStateById(0), 1);
	      world.setBlockState(new BlockPos(i + 6, j + 3, k + 2), Block.getStateById(0), 1);
	      world.setBlockState(new BlockPos(i + 7, j + 3, k + 2), Block.getStateById(0), 1);
	      world.setBlockState(new BlockPos(i + 8, j + 3, k + 2), Block.getStateById(0), 1);
	      world.setBlockState(new BlockPos(i + 9, j + 3, k + 2), Block.getStateById(203), 1);
	      world.setBlockState(new BlockPos(i + 10, j + 3, k + 2), Block.getStateById(201), 1);
	      world.setBlockState(new BlockPos(i + 11, j + 3, k + 2), Block.getStateById(0), 1);
	      world.setBlockState(new BlockPos(i + 0, j + 3, k + 3), Block.getStateById(0), 1);
	      world.setBlockState(new BlockPos(i + 1, j + 3, k + 3), Block.getStateById(201), 1);
	      world.setBlockState(new BlockPos(i + 2, j + 3, k + 3), Block.getStateById(0), 1);
	      world.setBlockState(new BlockPos(i + 3, j + 3, k + 3), Block.getStateById(0), 1);
	      world.setBlockState(new BlockPos(i + 4, j + 3, k + 3), Block.getStateById(0), 1);
	      world.setBlockState(new BlockPos(i + 5, j + 3, k + 3), Block.getStateById(0), 1);
	      world.setBlockState(new BlockPos(i + 6, j + 3, k + 3), Block.getStateById(0), 1);
	      world.setBlockState(new BlockPos(i + 7, j + 3, k + 3), Block.getStateById(0), 1);
	      world.setBlockState(new BlockPos(i + 8, j + 3, k + 3), Block.getStateById(0), 1);
	      world.setBlockState(new BlockPos(i + 9, j + 3, k + 3), Block.getStateById(0), 1);
	      world.setBlockState(new BlockPos(i + 10, j + 3, k + 3), Block.getStateById(201), 1);
	      world.setBlockState(new BlockPos(i + 11, j + 3, k + 3), Block.getStateById(0), 1);
	      world.setBlockState(new BlockPos(i + 0, j + 3, k + 4), Block.getStateById(0), 1);
	      world.setBlockState(new BlockPos(i + 1, j + 3, k + 4), Block.getStateById(201), 1);
	      world.setBlockState(new BlockPos(i + 2, j + 3, k + 4), Block.getStateById(0), 1);
	      world.setBlockState(new BlockPos(i + 3, j + 3, k + 4), Block.getStateById(0), 1);
	      world.setBlockState(new BlockPos(i + 4, j + 3, k + 4), Block.getStateById(0), 1);
	      world.setBlockState(new BlockPos(i + 5, j + 3, k + 4), Block.getStateById(0), 1);
	      world.setBlockState(new BlockPos(i + 6, j + 3, k + 4), Block.getStateById(0), 1);
	      world.setBlockState(new BlockPos(i + 7, j + 3, k + 4), Block.getStateById(0), 1);
	      world.setBlockState(new BlockPos(i + 8, j + 3, k + 4), Block.getStateById(0), 1);
	      world.setBlockState(new BlockPos(i + 9, j + 3, k + 4), Block.getStateById(0), 1);
	      world.setBlockState(new BlockPos(i + 10, j + 3, k + 4), Block.getStateById(201), 1);
	      world.setBlockState(new BlockPos(i + 11, j + 3, k + 4), Block.getStateById(0), 1);
	      world.setBlockState(new BlockPos(i + 0, j + 3, k + 5), Block.getStateById(0), 1);
	      world.setBlockState(new BlockPos(i + 1, j + 3, k + 5), Block.getStateById(201), 1);
	      world.setBlockState(new BlockPos(i + 2, j + 3, k + 5), Block.getStateById(0), 1);
	      world.setBlockState(new BlockPos(i + 3, j + 3, k + 5), Block.getStateById(0), 1);
	      world.setBlockState(new BlockPos(i + 4, j + 3, k + 5), Block.getStateById(0), 1);
	      world.setBlockState(new BlockPos(i + 5, j + 3, k + 5), Block.getStateById(0), 1);
	      world.setBlockState(new BlockPos(i + 6, j + 3, k + 5), Block.getStateById(0), 1);
	      world.setBlockState(new BlockPos(i + 7, j + 3, k + 5), Block.getStateById(0), 1);
	      world.setBlockState(new BlockPos(i + 8, j + 3, k + 5), Block.getStateById(0), 1);
	      world.setBlockState(new BlockPos(i + 9, j + 3, k + 5), Block.getStateById(0), 1);
	      world.setBlockState(new BlockPos(i + 10, j + 3, k + 5), Block.getStateById(201), 1);
	      world.setBlockState(new BlockPos(i + 11, j + 3, k + 5), Block.getStateById(0), 1);
	      world.setBlockState(new BlockPos(i + 0, j + 3, k + 6), Block.getStateById(0), 1);
	      world.setBlockState(new BlockPos(i + 1, j + 3, k + 6), Block.getStateById(201), 1);
	      world.setBlockState(new BlockPos(i + 2, j + 3, k + 6), Block.getStateById(0), 1);
	      world.setBlockState(new BlockPos(i + 3, j + 3, k + 6), Block.getStateById(0), 1);
	      world.setBlockState(new BlockPos(i + 4, j + 3, k + 6), Block.getStateById(0), 1);
	      world.setBlockState(new BlockPos(i + 5, j + 3, k + 6), Block.getStateById(0), 1);
	      world.setBlockState(new BlockPos(i + 6, j + 3, k + 6), Block.getStateById(0), 1);
	      world.setBlockState(new BlockPos(i + 7, j + 3, k + 6), Block.getStateById(0), 1);
	      world.setBlockState(new BlockPos(i + 8, j + 3, k + 6), Block.getStateById(0), 1);
	      world.setBlockState(new BlockPos(i + 9, j + 3, k + 6), Block.getStateById(0), 1);
	      world.setBlockState(new BlockPos(i + 10, j + 3, k + 6), Block.getStateById(201), 1);
	      world.setBlockState(new BlockPos(i + 11, j + 3, k + 6), Block.getStateById(0), 1);
	      world.setBlockState(new BlockPos(i + 0, j + 3, k + 7), Block.getStateById(0), 1);
	      world.setBlockState(new BlockPos(i + 1, j + 3, k + 7), Block.getStateById(201), 1);
	      world.setBlockState(new BlockPos(i + 2, j + 3, k + 7), Block.getStateById(0), 1);
	      world.setBlockState(new BlockPos(i + 3, j + 3, k + 7), Block.getStateById(0), 1);
	      world.setBlockState(new BlockPos(i + 4, j + 3, k + 7), Block.getStateById(0), 1);
	      world.setBlockState(new BlockPos(i + 5, j + 3, k + 7), Block.getStateById(0), 1);
	      world.setBlockState(new BlockPos(i + 6, j + 3, k + 7), Block.getStateById(0), 1);
	      world.setBlockState(new BlockPos(i + 7, j + 3, k + 7), Block.getStateById(0), 1);
	      world.setBlockState(new BlockPos(i + 8, j + 3, k + 7), Block.getStateById(0), 1);
	      world.setBlockState(new BlockPos(i + 9, j + 3, k + 7), Block.getStateById(0), 1);
	      world.setBlockState(new BlockPos(i + 10, j + 3, k + 7), Block.getStateById(201), 1);
	      world.setBlockState(new BlockPos(i + 11, j + 3, k + 7), Block.getStateById(0), 1);
	      world.setBlockState(new BlockPos(i + 0, j + 3, k + 8), Block.getStateById(0), 1);
	      world.setBlockState(new BlockPos(i + 1, j + 3, k + 8), Block.getStateById(201), 1);
	      world.setBlockState(new BlockPos(i + 2, j + 3, k + 8), Block.getStateById(0), 1);
	      world.setBlockState(new BlockPos(i + 3, j + 3, k + 8), Block.getStateById(0), 1);
	      world.setBlockState(new BlockPos(i + 4, j + 3, k + 8), Block.getStateById(0), 1);
	      world.setBlockState(new BlockPos(i + 5, j + 3, k + 8), Block.getStateById(0), 1);
	      world.setBlockState(new BlockPos(i + 6, j + 3, k + 8), Block.getStateById(0), 1);
	      world.setBlockState(new BlockPos(i + 7, j + 3, k + 8), Block.getStateById(0), 1);
	      world.setBlockState(new BlockPos(i + 8, j + 3, k + 8), Block.getStateById(0), 1);
	      world.setBlockState(new BlockPos(i + 9, j + 3, k + 8), Block.getStateById(0), 1);
	      world.setBlockState(new BlockPos(i + 10, j + 3, k + 8), Block.getStateById(201), 1);
	      world.setBlockState(new BlockPos(i + 11, j + 3, k + 8), Block.getStateById(0), 1);
	      world.setBlockState(new BlockPos(i + 0, j + 3, k + 9), Block.getStateById(0), 1);
	      world.setBlockState(new BlockPos(i + 1, j + 3, k + 9), Block.getStateById(201), 1);
	      world.setBlockState(new BlockPos(i + 2, j + 3, k + 9), Block.getStateById(67).withProperty(BlockStairs.FACING, EnumFacing.SOUTH), 1);
	      world.setBlockState(new BlockPos(i + 3, j + 3, k + 9), Block.getStateById(202), 1);
	      world.setBlockState(new BlockPos(i + 4, j + 3, k + 9), Block.getStateById(0), 1);
	      world.setBlockState(new BlockPos(i + 5, j + 3, k + 9), Block.getStateById(0), 1);
	      world.setBlockState(new BlockPos(i + 6, j + 3, k + 9), Block.getStateById(0), 1);
	      world.setBlockState(new BlockPos(i + 7, j + 3, k + 9), Block.getStateById(0), 1);
	      world.setBlockState(new BlockPos(i + 8, j + 3, k + 9), Block.getStateById(0), 1);
	      world.setBlockState(new BlockPos(i + 9, j + 3, k + 9), Block.getStateById(0), 1);
	      world.setBlockState(new BlockPos(i + 10, j + 3, k + 9), Block.getStateById(201), 1);
	      world.setBlockState(new BlockPos(i + 11, j + 3, k + 9), Block.getStateById(0), 1);
	      world.setBlockState(new BlockPos(i + 0, j + 3, k + 10), Block.getStateById(0), 1);
	      world.setBlockState(new BlockPos(i + 1, j + 3, k + 10), Block.getStateById(201), 1);
	      world.setBlockState(new BlockPos(i + 2, j + 3, k + 10), Block.getStateById(202), 1);
	      world.setBlockState(new BlockPos(i + 3, j + 3, k + 10), Block.getStateById(202), 1);
	      world.setBlockState(new BlockPos(i + 4, j + 3, k + 10), Block.getStateById(0), 1);
	      world.setBlockState(new BlockPos(i + 5, j + 3, k + 10), Block.getStateById(0), 1);
	      world.setBlockState(new BlockPos(i + 6, j + 3, k + 10), Block.getStateById(0), 1);
	      world.setBlockState(new BlockPos(i + 7, j + 3, k + 10), Block.getStateById(0), 1);
	      world.setBlockState(new BlockPos(i + 8, j + 3, k + 10), Block.getStateById(0), 1);
	      world.setBlockState(new BlockPos(i + 9, j + 3, k + 10), Block.getStateById(0), 1);
	      world.setBlockState(new BlockPos(i + 10, j + 3, k + 10), Block.getStateById(201), 1);
	      world.setBlockState(new BlockPos(i + 11, j + 3, k + 10), Block.getStateById(0), 1);
	      world.setBlockState(new BlockPos(i + 0, j + 3, k + 11), Block.getStateById(0), 1);
	      world.setBlockState(new BlockPos(i + 1, j + 3, k + 11), Block.getStateById(201), 1);
	      world.setBlockState(new BlockPos(i + 2, j + 3, k + 11), Block.getStateById(0), 1);
	      world.setBlockState(new BlockPos(i + 3, j + 3, k + 11), Block.getStateById(0), 1);
	      world.setBlockState(new BlockPos(i + 4, j + 3, k + 11), Block.getStateById(0), 1);
	      world.setBlockState(new BlockPos(i + 5, j + 3, k + 11), Block.getStateById(0), 1);
	      world.setBlockState(new BlockPos(i + 6, j + 3, k + 11), Block.getStateById(0), 1);
	      world.setBlockState(new BlockPos(i + 7, j + 3, k + 11), Block.getStateById(0), 1);
	      world.setBlockState(new BlockPos(i + 8, j + 3, k + 11), Block.getStateById(0), 1);
	      world.setBlockState(new BlockPos(i + 9, j + 3, k + 11), Block.getStateById(0), 1);
	      world.setBlockState(new BlockPos(i + 10, j + 3, k + 11), Block.getStateById(201), 1);
	      world.setBlockState(new BlockPos(i + 11, j + 3, k + 11), Block.getStateById(0), 1);
	      world.setBlockState(new BlockPos(i + 0, j + 3, k + 12), Block.getStateById(0), 1);
	      world.setBlockState(new BlockPos(i + 1, j + 3, k + 12), Block.getStateById(201), 1);
	      world.setBlockState(new BlockPos(i + 2, j + 3, k + 12), Block.getStateById(0), 1);
	      world.setBlockState(new BlockPos(i + 3, j + 3, k + 12), Block.getStateById(0), 1);
	      world.setBlockState(new BlockPos(i + 4, j + 3, k + 12), Block.getStateById(0), 1);
	      world.setBlockState(new BlockPos(i + 5, j + 3, k + 12), Block.getStateById(0), 1);
	      world.setBlockState(new BlockPos(i + 6, j + 3, k + 12), Block.getStateById(0), 1);
	      world.setBlockState(new BlockPos(i + 7, j + 3, k + 12), Block.getStateById(0), 1);
	      world.setBlockState(new BlockPos(i + 8, j + 3, k + 12), Block.getStateById(0), 1);
	      world.setBlockState(new BlockPos(i + 9, j + 3, k + 12), Block.getStateById(0), 1);
	      world.setBlockState(new BlockPos(i + 10, j + 3, k + 12), Block.getStateById(201), 1);
	      world.setBlockState(new BlockPos(i + 11, j + 3, k + 12), Block.getStateById(0), 1);
	      world.setBlockState(new BlockPos(i + 0, j + 3, k + 13), Block.getStateById(0), 1);
	      world.setBlockState(new BlockPos(i + 1, j + 3, k + 13), Block.getStateById(201), 1);
	      world.setBlockState(new BlockPos(i + 2, j + 3, k + 13), Block.getStateById(0), 1);
	      world.setBlockState(new BlockPos(i + 3, j + 3, k + 13), Block.getStateById(0), 1);
	      world.setBlockState(new BlockPos(i + 4, j + 3, k + 13), Block.getStateById(0), 1);
	      world.setBlockState(new BlockPos(i + 5, j + 3, k + 13), Block.getStateById(0), 1);
	      world.setBlockState(new BlockPos(i + 6, j + 3, k + 13), Block.getStateById(0), 1);
	      world.setBlockState(new BlockPos(i + 7, j + 3, k + 13), Block.getStateById(0), 1);
	      world.setBlockState(new BlockPos(i + 8, j + 3, k + 13), Block.getStateById(0), 1);
	      world.setBlockState(new BlockPos(i + 9, j + 3, k + 13), Block.getStateById(0), 1);
	      world.setBlockState(new BlockPos(i + 10, j + 3, k + 13), Block.getStateById(201), 1);
	      world.setBlockState(new BlockPos(i + 11, j + 3, k + 13), Block.getStateById(0), 1);
	      world.setBlockState(new BlockPos(i + 0, j + 3, k + 14), Block.getStateById(0), 1);
	      world.setBlockState(new BlockPos(i + 1, j + 3, k + 14), Block.getStateById(201), 1);
	      world.setBlockState(new BlockPos(i + 2, j + 3, k + 14), Block.getStateById(0), 1);
	      world.setBlockState(new BlockPos(i + 3, j + 3, k + 14), Block.getStateById(0), 1);
	      world.setBlockState(new BlockPos(i + 4, j + 3, k + 14), Block.getStateById(0), 1);
	      world.setBlockState(new BlockPos(i + 5, j + 3, k + 14), Block.getStateById(0), 1);
	      world.setBlockState(new BlockPos(i + 6, j + 3, k + 14), Block.getStateById(0), 1);
	      world.setBlockState(new BlockPos(i + 7, j + 3, k + 14), Block.getStateById(0), 1);
	      world.setBlockState(new BlockPos(i + 8, j + 3, k + 14), Block.getStateById(0), 1);
	      world.setBlockState(new BlockPos(i + 9, j + 3, k + 14), Block.getStateById(0), 1);
	      world.setBlockState(new BlockPos(i + 10, j + 3, k + 14), Block.getStateById(201), 1);
	      world.setBlockState(new BlockPos(i + 11, j + 3, k + 14), Block.getStateById(0), 1);
	      world.setBlockState(new BlockPos(i + 0, j + 3, k + 15), Block.getStateById(0), 1);
	      world.setBlockState(new BlockPos(i + 1, j + 3, k + 15), Block.getStateById(201), 1);
	      world.setBlockState(new BlockPos(i + 2, j + 3, k + 15), Block.getStateById(0), 1);
	      world.setBlockState(new BlockPos(i + 3, j + 3, k + 15), Block.getStateById(0), 1);
	      world.setBlockState(new BlockPos(i + 4, j + 3, k + 15), Block.getStateById(201), 1);
	      world.setBlockState(new BlockPos(i + 5, j + 3, k + 15), Block.getStateById(71).withProperty(BlockDoor.HALF, EnumDoorHalf.UPPER), 1);
	      world.setBlockState(new BlockPos(i + 6, j + 3, k + 15), Block.getStateById(71).withProperty(BlockDoor.HALF, EnumDoorHalf.UPPER), 1);
	      world.setBlockState(new BlockPos(i + 7, j + 3, k + 15), Block.getStateById(201), 1);
	      world.setBlockState(new BlockPos(i + 8, j + 3, k + 15), Block.getStateById(0), 1);
	      world.setBlockState(new BlockPos(i + 9, j + 3, k + 15), Block.getStateById(0), 1);
	      world.setBlockState(new BlockPos(i + 10, j + 3, k + 15), Block.getStateById(201), 1);
	      world.setBlockState(new BlockPos(i + 11, j + 3, k + 15), Block.getStateById(0), 1);
	      world.setBlockState(new BlockPos(i + 0, j + 3, k + 16), Block.getStateById(0), 1);
	      world.setBlockState(new BlockPos(i + 1, j + 3, k + 16), Block.getStateById(201), 1);
	      world.setBlockState(new BlockPos(i + 2, j + 3, k + 16), Block.getStateById(201), 1);
	      world.setBlockState(new BlockPos(i + 3, j + 3, k + 16), Block.getStateById(201), 1);
	      world.setBlockState(new BlockPos(i + 4, j + 3, k + 16), Block.getStateById(201), 1);
	      world.setBlockState(new BlockPos(i + 5, j + 3, k + 16), Block.getStateById(0), 1);
	      world.setBlockState(new BlockPos(i + 6, j + 3, k + 16), Block.getStateById(0), 1);
	      world.setBlockState(new BlockPos(i + 7, j + 3, k + 16), Block.getStateById(201), 1);
	      world.setBlockState(new BlockPos(i + 8, j + 3, k + 16), Block.getStateById(201), 1);
	      world.setBlockState(new BlockPos(i + 9, j + 3, k + 16), Block.getStateById(201), 1);
	      world.setBlockState(new BlockPos(i + 10, j + 3, k + 16), Block.getStateById(201), 1);
	      world.setBlockState(new BlockPos(i + 11, j + 3, k + 16), Block.getStateById(0), 1);
	      world.setBlockState(new BlockPos(i + 0, j + 3, k + 17), Block.getStateById(0), 1);
	      world.setBlockState(new BlockPos(i + 1, j + 3, k + 17), Block.getStateById(0), 1);
	      world.setBlockState(new BlockPos(i + 2, j + 3, k + 17), Block.getStateById(0), 1);
	      world.setBlockState(new BlockPos(i + 3, j + 3, k + 17), Block.getStateById(0), 1);
	      world.setBlockState(new BlockPos(i + 4, j + 3, k + 17), Block.getStateById(0), 1);
	      world.setBlockState(new BlockPos(i + 5, j + 3, k + 17), Block.getStateById(0), 1);
	      world.setBlockState(new BlockPos(i + 6, j + 3, k + 17), Block.getStateById(0), 1);
	      world.setBlockState(new BlockPos(i + 7, j + 3, k + 17), Block.getStateById(0), 1);
	      world.setBlockState(new BlockPos(i + 8, j + 3, k + 17), Block.getStateById(0), 1);
	      world.setBlockState(new BlockPos(i + 9, j + 3, k + 17), Block.getStateById(0), 1);
	      world.setBlockState(new BlockPos(i + 10, j + 3, k + 17), Block.getStateById(0), 1);
	      world.setBlockState(new BlockPos(i + 11, j + 3, k + 17), Block.getStateById(0), 1);
	      world.setBlockState(new BlockPos(i + 0, j + 3, k + 18), Block.getStateById(0), 1);
	      world.setBlockState(new BlockPos(i + 1, j + 3, k + 18), Block.getStateById(0), 1);
	      world.setBlockState(new BlockPos(i + 2, j + 3, k + 18), Block.getStateById(0), 1);
	      world.setBlockState(new BlockPos(i + 3, j + 3, k + 18), Block.getStateById(0), 1);
	      world.setBlockState(new BlockPos(i + 4, j + 3, k + 18), Block.getStateById(0), 1);
	      world.setBlockState(new BlockPos(i + 5, j + 3, k + 18), Block.getStateById(0), 1);
	      world.setBlockState(new BlockPos(i + 6, j + 3, k + 18), Block.getStateById(0), 1);
	      world.setBlockState(new BlockPos(i + 7, j + 3, k + 18), Block.getStateById(0), 1);
	      world.setBlockState(new BlockPos(i + 8, j + 3, k + 18), Block.getStateById(0), 1);
	      world.setBlockState(new BlockPos(i + 9, j + 3, k + 18), Block.getStateById(0), 1);
	      world.setBlockState(new BlockPos(i + 10, j + 3, k + 18), Block.getStateById(0), 1);
	      world.setBlockState(new BlockPos(i + 11, j + 3, k + 18), Block.getStateById(0), 1);
	      world.setBlockState(new BlockPos(i + 0, j + 3, k + 19), Block.getStateById(0), 1);
	      world.setBlockState(new BlockPos(i + 1, j + 3, k + 19), Block.getStateById(0), 1);
	      world.setBlockState(new BlockPos(i + 2, j + 3, k + 19), Block.getStateById(0), 1);
	      world.setBlockState(new BlockPos(i + 3, j + 3, k + 19), Block.getStateById(0), 1);
	      world.setBlockState(new BlockPos(i + 4, j + 3, k + 19), Block.getStateById(0), 1);
	      world.setBlockState(new BlockPos(i + 5, j + 3, k + 19), Block.getStateById(0), 1);
	      world.setBlockState(new BlockPos(i + 6, j + 3, k + 19), Block.getStateById(0), 1);
	      world.setBlockState(new BlockPos(i + 7, j + 3, k + 19), Block.getStateById(0), 1);
	      world.setBlockState(new BlockPos(i + 8, j + 3, k + 19), Block.getStateById(0), 1);
	      world.setBlockState(new BlockPos(i + 9, j + 3, k + 19), Block.getStateById(0), 1);
	      world.setBlockState(new BlockPos(i + 10, j + 3, k + 19), Block.getStateById(0), 1);
	      world.setBlockState(new BlockPos(i + 11, j + 3, k + 19), Block.getStateById(0), 1);
	      world.setBlockState(new BlockPos(i + 0, j + 4, k + 0), Block.getStateById(0), 1);
	      world.setBlockState(new BlockPos(i + 1, j + 4, k + 0), Block.getStateById(0), 1);
	      world.setBlockState(new BlockPos(i + 2, j + 4, k + 0), Block.getStateById(0), 1);
	      world.setBlockState(new BlockPos(i + 3, j + 4, k + 0), Block.getStateById(0), 1);
	      world.setBlockState(new BlockPos(i + 4, j + 4, k + 0), Block.getStateById(0), 1);
	      world.setBlockState(new BlockPos(i + 5, j + 4, k + 0), Block.getStateById(0), 1);
	      world.setBlockState(new BlockPos(i + 6, j + 4, k + 0), Block.getStateById(0), 1);
	      world.setBlockState(new BlockPos(i + 7, j + 4, k + 0), Block.getStateById(0), 1);
	      world.setBlockState(new BlockPos(i + 8, j + 4, k + 0), Block.getStateById(0), 1);
	      world.setBlockState(new BlockPos(i + 9, j + 4, k + 0), Block.getStateById(0), 1);
	      world.setBlockState(new BlockPos(i + 10, j + 4, k + 0), Block.getStateById(0), 1);
	      world.setBlockState(new BlockPos(i + 11, j + 4, k + 0), Block.getStateById(0), 1);
	      world.setBlockState(new BlockPos(i + 0, j + 4, k + 1), Block.getStateById(0), 1);
	      world.setBlockState(new BlockPos(i + 1, j + 4, k + 1), Block.getStateById(201), 1);
	      world.setBlockState(new BlockPos(i + 2, j + 4, k + 1), Block.getStateById(201), 1);
	      world.setBlockState(new BlockPos(i + 3, j + 4, k + 1), Block.getStateById(203), 1);
	      world.setBlockState(new BlockPos(i + 4, j + 4, k + 1), Block.getStateById(203), 1);
	      world.setBlockState(new BlockPos(i + 5, j + 4, k + 1), Block.getStateById(203), 1);
	      world.setBlockState(new BlockPos(i + 6, j + 4, k + 1), Block.getStateById(203), 1);
	      world.setBlockState(new BlockPos(i + 7, j + 4, k + 1), Block.getStateById(203), 1);
	      world.setBlockState(new BlockPos(i + 8, j + 4, k + 1), Block.getStateById(203), 1);
	      world.setBlockState(new BlockPos(i + 9, j + 4, k + 1), Block.getStateById(201), 1);
	      world.setBlockState(new BlockPos(i + 10, j + 4, k + 1), Block.getStateById(201), 1);
	      world.setBlockState(new BlockPos(i + 11, j + 4, k + 1), Block.getStateById(0), 1);
	      world.setBlockState(new BlockPos(i + 0, j + 4, k + 2), Block.getStateById(0), 1);
	      world.setBlockState(new BlockPos(i + 1, j + 4, k + 2), Block.getStateById(201), 1);
	      world.setBlockState(new BlockPos(i + 2, j + 4, k + 2), Block.getStateById(203), 1);
	      world.setBlockState(new BlockPos(i + 3, j + 4, k + 2), Block.getStateById(0), 1);
	      world.setBlockState(new BlockPos(i + 4, j + 4, k + 2), Block.getStateById(0), 1);
	      world.setBlockState(new BlockPos(i + 5, j + 4, k + 2), Block.getStateById(0), 1);
	      world.setBlockState(new BlockPos(i + 6, j + 4, k + 2), Block.getStateById(0), 1);
	      world.setBlockState(new BlockPos(i + 7, j + 4, k + 2), Block.getStateById(0), 1);
	      world.setBlockState(new BlockPos(i + 8, j + 4, k + 2), Block.getStateById(0), 1);
	      world.setBlockState(new BlockPos(i + 9, j + 4, k + 2), Block.getStateById(203), 1);
	      world.setBlockState(new BlockPos(i + 10, j + 4, k + 2), Block.getStateById(201), 1);
	      world.setBlockState(new BlockPos(i + 11, j + 4, k + 2), Block.getStateById(0), 1);
	      world.setBlockState(new BlockPos(i + 0, j + 4, k + 3), Block.getStateById(0), 1);
	      world.setBlockState(new BlockPos(i + 1, j + 4, k + 3), Block.getStateById(201), 1);
	      world.setBlockState(new BlockPos(i + 2, j + 4, k + 3), Block.getStateById(0), 1);
	      world.setBlockState(new BlockPos(i + 3, j + 4, k + 3), Block.getStateById(0), 1);
	      world.setBlockState(new BlockPos(i + 4, j + 4, k + 3), Block.getStateById(0), 1);
	      world.setBlockState(new BlockPos(i + 5, j + 4, k + 3), Block.getStateById(0), 1);
	      world.setBlockState(new BlockPos(i + 6, j + 4, k + 3), Block.getStateById(0), 1);
	      world.setBlockState(new BlockPos(i + 7, j + 4, k + 3), Block.getStateById(0), 1);
	      world.setBlockState(new BlockPos(i + 8, j + 4, k + 3), Block.getStateById(0), 1);
	      world.setBlockState(new BlockPos(i + 9, j + 4, k + 3), Block.getStateById(0), 1);
	      world.setBlockState(new BlockPos(i + 10, j + 4, k + 3), Block.getStateById(201), 1);
	      world.setBlockState(new BlockPos(i + 11, j + 4, k + 3), Block.getStateById(0), 1);
	      world.setBlockState(new BlockPos(i + 0, j + 4, k + 4), Block.getStateById(0), 1);
	      world.setBlockState(new BlockPos(i + 1, j + 4, k + 4), Block.getStateById(201), 1);
	      world.setBlockState(new BlockPos(i + 2, j + 4, k + 4), Block.getStateById(0), 1);
	      world.setBlockState(new BlockPos(i + 3, j + 4, k + 4), Block.getStateById(0), 1);
	      world.setBlockState(new BlockPos(i + 4, j + 4, k + 4), Block.getStateById(0), 1);
	      world.setBlockState(new BlockPos(i + 5, j + 4, k + 4), Block.getStateById(0), 1);
	      world.setBlockState(new BlockPos(i + 6, j + 4, k + 4), Block.getStateById(0), 1);
	      world.setBlockState(new BlockPos(i + 7, j + 4, k + 4), Block.getStateById(0), 1);
	      world.setBlockState(new BlockPos(i + 8, j + 4, k + 4), Block.getStateById(0), 1);
	      world.setBlockState(new BlockPos(i + 9, j + 4, k + 4), Block.getStateById(0), 1);
	      world.setBlockState(new BlockPos(i + 10, j + 4, k + 4), Block.getStateById(201), 1);
	      world.setBlockState(new BlockPos(i + 11, j + 4, k + 4), Block.getStateById(0), 1);
	      world.setBlockState(new BlockPos(i + 0, j + 4, k + 5), Block.getStateById(0), 1);
	      world.setBlockState(new BlockPos(i + 1, j + 4, k + 5), Block.getStateById(201), 1);
	      world.setBlockState(new BlockPos(i + 2, j + 4, k + 5), Block.getStateById(0), 1);
	      world.setBlockState(new BlockPos(i + 3, j + 4, k + 5), Block.getStateById(0), 1);
	      world.setBlockState(new BlockPos(i + 4, j + 4, k + 5), Block.getStateById(0), 1);
	      world.setBlockState(new BlockPos(i + 5, j + 4, k + 5), Block.getStateById(0), 1);
	      world.setBlockState(new BlockPos(i + 6, j + 4, k + 5), Block.getStateById(0), 1);
	      world.setBlockState(new BlockPos(i + 7, j + 4, k + 5), Block.getStateById(0), 1);
	      world.setBlockState(new BlockPos(i + 8, j + 4, k + 5), Block.getStateById(0), 1);
	      world.setBlockState(new BlockPos(i + 9, j + 4, k + 5), Block.getStateById(0), 1);
	      world.setBlockState(new BlockPos(i + 10, j + 4, k + 5), Block.getStateById(201), 1);
	      world.setBlockState(new BlockPos(i + 11, j + 4, k + 5), Block.getStateById(0), 1);
	      world.setBlockState(new BlockPos(i + 0, j + 4, k + 6), Block.getStateById(0), 1);
	      world.setBlockState(new BlockPos(i + 1, j + 4, k + 6), Block.getStateById(201), 1);
	      world.setBlockState(new BlockPos(i + 2, j + 4, k + 6), Block.getStateById(0), 1);
	      world.setBlockState(new BlockPos(i + 3, j + 4, k + 6), Block.getStateById(0), 1);
	      world.setBlockState(new BlockPos(i + 4, j + 4, k + 6), Block.getStateById(0), 1);
	      world.setBlockState(new BlockPos(i + 5, j + 4, k + 6), Block.getStateById(0), 1);
	      world.setBlockState(new BlockPos(i + 6, j + 4, k + 6), Block.getStateById(0), 1);
	      world.setBlockState(new BlockPos(i + 7, j + 4, k + 6), Block.getStateById(0), 1);
	      world.setBlockState(new BlockPos(i + 8, j + 4, k + 6), Block.getStateById(0), 1);
	      world.setBlockState(new BlockPos(i + 9, j + 4, k + 6), Block.getStateById(0), 1);
	      world.setBlockState(new BlockPos(i + 10, j + 4, k + 6), Block.getStateById(201), 1);
	      world.setBlockState(new BlockPos(i + 11, j + 4, k + 6), Block.getStateById(0), 1);
	      world.setBlockState(new BlockPos(i + 0, j + 4, k + 7), Block.getStateById(0), 1);
	      world.setBlockState(new BlockPos(i + 1, j + 4, k + 7), Block.getStateById(201), 1);
	      world.setBlockState(new BlockPos(i + 2, j + 4, k + 7), Block.getStateById(0), 1);
	      world.setBlockState(new BlockPos(i + 3, j + 4, k + 7), Block.getStateById(0), 1);
	      world.setBlockState(new BlockPos(i + 4, j + 4, k + 7), Block.getStateById(0), 1);
	      world.setBlockState(new BlockPos(i + 5, j + 4, k + 7), Block.getStateById(0), 1);
	      world.setBlockState(new BlockPos(i + 6, j + 4, k + 7), Block.getStateById(0), 1);
	      world.setBlockState(new BlockPos(i + 7, j + 4, k + 7), Block.getStateById(0), 1);
	      world.setBlockState(new BlockPos(i + 8, j + 4, k + 7), Block.getStateById(0), 1);
	      world.setBlockState(new BlockPos(i + 9, j + 4, k + 7), Block.getStateById(0), 1);
	      world.setBlockState(new BlockPos(i + 10, j + 4, k + 7), Block.getStateById(201), 1);
	      world.setBlockState(new BlockPos(i + 11, j + 4, k + 7), Block.getStateById(0), 1);
	      world.setBlockState(new BlockPos(i + 0, j + 4, k + 8), Block.getStateById(0), 1);
	      world.setBlockState(new BlockPos(i + 1, j + 4, k + 8), Block.getStateById(201), 1);
	      world.setBlockState(new BlockPos(i + 2, j + 4, k + 8), Block.getStateById(0), 1);
	      world.setBlockState(new BlockPos(i + 3, j + 4, k + 8), Block.getStateById(0), 1);
	      world.setBlockState(new BlockPos(i + 4, j + 4, k + 8), Block.getStateById(0), 1);
	      world.setBlockState(new BlockPos(i + 5, j + 4, k + 8), Block.getStateById(0), 1);
	      world.setBlockState(new BlockPos(i + 6, j + 4, k + 8), Block.getStateById(0), 1);
	      world.setBlockState(new BlockPos(i + 7, j + 4, k + 8), Block.getStateById(0), 1);
	      world.setBlockState(new BlockPos(i + 8, j + 4, k + 8), Block.getStateById(0), 1);
	      world.setBlockState(new BlockPos(i + 9, j + 4, k + 8), Block.getStateById(0), 1);
	      world.setBlockState(new BlockPos(i + 10, j + 4, k + 8), Block.getStateById(201), 1);
	      world.setBlockState(new BlockPos(i + 11, j + 4, k + 8), Block.getStateById(0), 1);
	      world.setBlockState(new BlockPos(i + 0, j + 4, k + 9), Block.getStateById(0), 1);
	      world.setBlockState(new BlockPos(i + 1, j + 4, k + 9), Block.getStateById(201), 1);
	      world.setBlockState(new BlockPos(i + 2, j + 4, k + 9), Block.getStateById(0), 1);
	      world.setBlockState(new BlockPos(i + 3, j + 4, k + 9), Block.getStateById(202), 1);
	      world.setBlockState(new BlockPos(i + 4, j + 4, k + 9), Block.getStateById(202), 1);
	      world.setBlockState(new BlockPos(i + 5, j + 4, k + 9), Block.getStateById(0), 1);
	      world.setBlockState(new BlockPos(i + 6, j + 4, k + 9), Block.getStateById(0), 1);
	      world.setBlockState(new BlockPos(i + 7, j + 4, k + 9), Block.getStateById(0), 1);
	      world.setBlockState(new BlockPos(i + 8, j + 4, k + 9), Block.getStateById(0), 1);
	      world.setBlockState(new BlockPos(i + 9, j + 4, k + 9), Block.getStateById(0), 1);
	      world.setBlockState(new BlockPos(i + 10, j + 4, k + 9), Block.getStateById(201), 1);
