//Schematic to java Structure by jajo_11 | inspired by "MITHION'S .SCHEMATIC TO JAVA CONVERTING TOOL"

package FaithCraft2.Common.common.worldgen;

import java.util.Random;

import cpw.mods.fml.common.IWorldGenerator;
import net.minecraft.block.Block;
import net.minecraft.block.material.Material;
import net.minecraft.init.Blocks;
import net.minecraft.item.ItemDoor;
import net.minecraft.world.World;
import net.minecraft.world.chunk.IChunkProvider;
import net.minecraft.world.gen.feature.WorldGenerator;
import FaithCraft2.Common.common.FaithCraft2;

public class WorldGenChurch extends WorldGenerator implements IWorldGenerator
{
	protected Block[] GetValidSpawnBlocks()
	{
		return new Block[]
		{
			Blocks.grass,
			Blocks.dirt,
			FaithCraft2.HolyCobbleStone,
			FaithCraft2.HolyStone,
			FaithCraft2.HolyStone
		};
	}

	public boolean LocationIsValidSpawn(World world, int x, int y, int z)
	{
		int distanceToAir = 0;
		Block checkBlock = world.getBlock(x, y, z);

		while (checkBlock != Blocks.air)
		{
			distanceToAir++;
			checkBlock = world.getBlock(x, y + distanceToAir, z);
		}

		if (distanceToAir > 1)
		{
			return false;
		}

		y += distanceToAir - 1;

		Block block = world.getBlock(x, y, z);
		Block blockAbove = world.getBlock(x, y + 1, z);
		Block blockBelow = world.getBlock(x, y - 1, z);

		for (Block i : GetValidSpawnBlocks())
		{
			if (blockAbove != Blocks.air)
			{
				return false;
			}
			if (block == i)
			{
				return true;
			}
			else if (block == Blocks.snow_layer && blockBelow == i)
			if (block.getMaterial() == Material.plants && blockBelow == i)
			{
				return true;
			}
		}
		return false;
	}

	public void generate(Random random, int chunkX, int chunkZ, World world, IChunkProvider chunkGenerator, IChunkProvider chunkProvider) {
		switch(world.provider.dimensionId)
		{
		case -1:
		generateNether(world, random, chunkX * 16, chunkZ * 16);
		break;
		case 0:
		generateSurface(world, random, chunkX * 16, chunkZ * 16);
		break;
		case 1:
		generateEnd(world, random, chunkX * 16, chunkZ * 16);
		break;
		}
	}
	
	private void generateEnd(World world, Random random, int i, int j) {
		// TODO Auto-generated method stub
		
	}

	private void generateNether(World world, Random random, int i, int j) {
		// TODO Auto-generated method stub
		
	}

	public void generateSurface(World world, Random rand, int x2, int z2)
	{
		
		int x = x2 + rand.nextInt(15);
		int z = z2 + rand.nextInt(15);

		int y = world.getHeightValue(x,z)-1;
		
		if((rand.nextInt(1000000)+1)<=100000){
			boolean place = true;

		world.setBlock(x + 0, y + 0, z + 0, FaithCraft2.HolyStone, 0, 3);
		world.setBlock(x + 1, y + 0, z + 0, FaithCraft2.HolyStone, 0, 3);
		world.setBlock(x + 2, y + 0, z + 0, FaithCraft2.HolyStone, 0, 3);
		world.setBlock(x + 3, y + 0, z + 0, FaithCraft2.HolyStone, 0, 3);
		world.setBlock(x + 4, y + 0, z + 0, FaithCraft2.HolyStone, 0, 3);
		world.setBlock(x + 5, y + 0, z + 0, FaithCraft2.HolyStone, 0, 3);
		world.setBlock(x + 6, y + 0, z + 0, FaithCraft2.HolyStone, 0, 3);
		world.setBlock(x + 7, y + 0, z + 0, FaithCraft2.HolyStone, 0, 3);
		world.setBlock(x + 8, y + 0, z + 0, FaithCraft2.HolyStone, 0, 3);
		world.setBlock(x + 9, y + 0, z + 0, FaithCraft2.HolyStone, 0, 3);
		world.setBlock(x + 10, y + 0, z + 0, FaithCraft2.HolyStone, 0, 3);
		world.setBlock(x + 11, y + 0, z + 0, FaithCraft2.HolyStone, 0, 3);
		world.setBlock(x + 0, y + 0, z + 1, FaithCraft2.HolyStone, 0, 3);
		world.setBlock(x + 1, y + 0, z + 1, Blocks.glowstone, 0, 3);
		world.setBlock(x + 2, y + 0, z + 1, FaithCraft2.HolyStone, 0, 3);
		world.setBlock(x + 3, y + 0, z + 1, FaithCraft2.HolyStone, 0, 3);
		world.setBlock(x + 4, y + 0, z + 1, FaithCraft2.HolyStone, 0, 3);
		world.setBlock(x + 5, y + 0, z + 1, FaithCraft2.HolyStone, 0, 3);
		world.setBlock(x + 6, y + 0, z + 1, FaithCraft2.HolyStone, 0, 3);
		world.setBlock(x + 7, y + 0, z + 1, FaithCraft2.HolyStone, 0, 3);
		world.setBlock(x + 8, y + 0, z + 1, FaithCraft2.HolyStone, 0, 3);
		world.setBlock(x + 9, y + 0, z + 1, FaithCraft2.HolyStone, 0, 3);
		world.setBlock(x + 10, y + 0, z + 1, Blocks.glowstone, 0, 3);
		world.setBlock(x + 11, y + 0, z + 1, FaithCraft2.HolyStone, 0, 3);
		world.setBlock(x + 0, y + 0, z + 2, FaithCraft2.HolyStone, 0, 3);
		world.setBlock(x + 1, y + 0, z + 2, FaithCraft2.HolyStone, 0, 3);
		world.setBlock(x + 2, y + 0, z + 2, FaithCraft2.HolyStone, 0, 3);
		world.setBlock(x + 3, y + 0, z + 2, FaithCraft2.HolyStone, 0, 3);
		world.setBlock(x + 4, y + 0, z + 2, FaithCraft2.HolyStone, 0, 3);
		world.setBlock(x + 5, y + 0, z + 2, FaithCraft2.HolyStone, 0, 3);
		world.setBlock(x + 6, y + 0, z + 2, FaithCraft2.HolyStone, 0, 3);
		world.setBlock(x + 7, y + 0, z + 2, FaithCraft2.HolyStone, 0, 3);
		world.setBlock(x + 8, y + 0, z + 2, FaithCraft2.HolyStone, 0, 3);
		world.setBlock(x + 9, y + 0, z + 2, FaithCraft2.HolyStone, 0, 3);
		world.setBlock(x + 10, y + 0, z + 2, FaithCraft2.HolyStone, 0, 3);
		world.setBlock(x + 11, y + 0, z + 2, FaithCraft2.HolyStone, 0, 3);
		world.setBlock(x + 0, y + 0, z + 3, FaithCraft2.HolyStone, 0, 3);
		world.setBlock(x + 1, y + 0, z + 3, FaithCraft2.HolyStone, 0, 3);
		world.setBlock(x + 2, y + 0, z + 3, FaithCraft2.HolyStone, 0, 3);
		world.setBlock(x + 3, y + 0, z + 3, FaithCraft2.HolyStone, 0, 3);
		world.setBlock(x + 4, y + 0, z + 3, FaithCraft2.HolyStone, 0, 3);
		world.setBlock(x + 5, y + 0, z + 3, FaithCraft2.HolyStone, 0, 3);
		world.setBlock(x + 6, y + 0, z + 3, FaithCraft2.HolyStone, 0, 3);
		world.setBlock(x + 7, y + 0, z + 3, FaithCraft2.HolyStone, 0, 3);
		world.setBlock(x + 8, y + 0, z + 3, FaithCraft2.HolyStone, 0, 3);
		world.setBlock(x + 9, y + 0, z + 3, FaithCraft2.HolyStone, 0, 3);
		world.setBlock(x + 10, y + 0, z + 3, FaithCraft2.HolyStone, 0, 3);
		world.setBlock(x + 11, y + 0, z + 3, FaithCraft2.HolyStone, 0, 3);
		world.setBlock(x + 0, y + 0, z + 4, FaithCraft2.HolyStone, 0, 3);
		world.setBlock(x + 1, y + 0, z + 4, FaithCraft2.HolyStone, 0, 3);
		world.setBlock(x + 2, y + 0, z + 4, FaithCraft2.HolyStone, 0, 3);
		world.setBlock(x + 3, y + 0, z + 4, FaithCraft2.HolyStone, 0, 3);
		world.setBlock(x + 4, y + 0, z + 4, FaithCraft2.HolyStone, 0, 3);
		world.setBlock(x + 5, y + 0, z + 4, FaithCraft2.HolyStone, 0, 3);
		world.setBlock(x + 6, y + 0, z + 4, FaithCraft2.HolyStone, 0, 3);
		world.setBlock(x + 7, y + 0, z + 4, FaithCraft2.HolyStone, 0, 3);
		world.setBlock(x + 8, y + 0, z + 4, FaithCraft2.HolyStone, 0, 3);
		world.setBlock(x + 9, y + 0, z + 4, FaithCraft2.HolyStone, 0, 3);
		world.setBlock(x + 10, y + 0, z + 4, FaithCraft2.HolyStone, 0, 3);
		world.setBlock(x + 11, y + 0, z + 4, FaithCraft2.HolyStone, 0, 3);
		world.setBlock(x + 0, y + 0, z + 5, FaithCraft2.HolyStone, 0, 3);
		world.setBlock(x + 1, y + 0, z + 5, FaithCraft2.HolyStone, 0, 3);
		world.setBlock(x + 2, y + 0, z + 5, FaithCraft2.HolyStone, 0, 3);
		world.setBlock(x + 3, y + 0, z + 5, FaithCraft2.HolyStone, 0, 3);
		world.setBlock(x + 4, y + 0, z + 5, FaithCraft2.HolyStone, 0, 3);
		world.setBlock(x + 5, y + 0, z + 5, FaithCraft2.HolyStone, 0, 3);
		world.setBlock(x + 6, y + 0, z + 5, FaithCraft2.HolyStone, 0, 3);
		world.setBlock(x + 7, y + 0, z + 5, FaithCraft2.HolyStone, 0, 3);
		world.setBlock(x + 8, y + 0, z + 5, FaithCraft2.HolyStone, 0, 3);
		world.setBlock(x + 9, y + 0, z + 5, FaithCraft2.HolyStone, 0, 3);
		world.setBlock(x + 10, y + 0, z + 5, FaithCraft2.HolyStone, 0, 3);
		world.setBlock(x + 11, y + 0, z + 5, FaithCraft2.HolyStone, 0, 3);
		world.setBlock(x + 0, y + 0, z + 6, FaithCraft2.HolyStone, 0, 3);
		world.setBlock(x + 1, y + 0, z + 6, FaithCraft2.HolyStone, 0, 3);
		world.setBlock(x + 2, y + 0, z + 6, FaithCraft2.HolyStone, 0, 3);
		world.setBlock(x + 3, y + 0, z + 6, FaithCraft2.HolyStone, 0, 3);
		world.setBlock(x + 4, y + 0, z + 6, FaithCraft2.HolyStone, 0, 3);
		world.setBlock(x + 5, y + 0, z + 6, FaithCraft2.HolyStone, 0, 3);
		world.setBlock(x + 6, y + 0, z + 6, FaithCraft2.HolyStone, 0, 3);
		world.setBlock(x + 7, y + 0, z + 6, FaithCraft2.HolyStone, 0, 3);
		world.setBlock(x + 8, y + 0, z + 6, FaithCraft2.HolyStone, 0, 3);
		world.setBlock(x + 9, y + 0, z + 6, FaithCraft2.HolyStone, 0, 3);
		world.setBlock(x + 10, y + 0, z + 6, FaithCraft2.HolyStone, 0, 3);
		world.setBlock(x + 11, y + 0, z + 6, FaithCraft2.HolyStone, 0, 3);
		world.setBlock(x + 0, y + 0, z + 7, FaithCraft2.HolyStone, 0, 3);
		world.setBlock(x + 1, y + 0, z + 7, FaithCraft2.HolyStone, 0, 3);
		world.setBlock(x + 2, y + 0, z + 7, FaithCraft2.HolyStone, 0, 3);
		world.setBlock(x + 3, y + 0, z + 7, FaithCraft2.HolyStone, 0, 3);
		world.setBlock(x + 4, y + 0, z + 7, FaithCraft2.HolyStone, 0, 3);
		world.setBlock(x + 5, y + 0, z + 7, FaithCraft2.HolyStone, 0, 3);
		world.setBlock(x + 6, y + 0, z + 7, FaithCraft2.HolyStone, 0, 3);
		world.setBlock(x + 7, y + 0, z + 7, FaithCraft2.HolyStone, 0, 3);
		world.setBlock(x + 8, y + 0, z + 7, FaithCraft2.HolyStone, 0, 3);
		world.setBlock(x + 9, y + 0, z + 7, FaithCraft2.HolyStone, 0, 3);
		world.setBlock(x + 10, y + 0, z + 7, FaithCraft2.HolyStone, 0, 3);
		world.setBlock(x + 11, y + 0, z + 7, FaithCraft2.HolyStone, 0, 3);
		world.setBlock(x + 0, y + 0, z + 8, FaithCraft2.HolyStone, 0, 3);
		world.setBlock(x + 1, y + 0, z + 8, FaithCraft2.HolyStone, 0, 3);
		world.setBlock(x + 2, y + 0, z + 8, FaithCraft2.HolyStone, 0, 3);
		world.setBlock(x + 3, y + 0, z + 8, FaithCraft2.HolyStone, 0, 3);
		world.setBlock(x + 4, y + 0, z + 8, FaithCraft2.HolyStone, 0, 3);
		world.setBlock(x + 5, y + 0, z + 8, FaithCraft2.HolyStone, 0, 3);
		world.setBlock(x + 6, y + 0, z + 8, FaithCraft2.HolyStone, 0, 3);
		world.setBlock(x + 7, y + 0, z + 8, FaithCraft2.HolyStone, 0, 3);
		world.setBlock(x + 8, y + 0, z + 8, FaithCraft2.HolyStone, 0, 3);
		world.setBlock(x + 9, y + 0, z + 8, FaithCraft2.HolyStone, 0, 3);
		world.setBlock(x + 10, y + 0, z + 8, FaithCraft2.HolyStone, 0, 3);
		world.setBlock(x + 11, y + 0, z + 8, FaithCraft2.HolyStone, 0, 3);
		world.setBlock(x + 0, y + 0, z + 9, FaithCraft2.HolyStone, 0, 3);
		world.setBlock(x + 1, y + 0, z + 9, FaithCraft2.HolyStone, 0, 3);
		world.setBlock(x + 2, y + 0, z + 9, FaithCraft2.HolyStone, 0, 3);
		world.setBlock(x + 3, y + 0, z + 9, FaithCraft2.HolyStone, 0, 3);
		world.setBlock(x + 4, y + 0, z + 9, FaithCraft2.HolyStone, 0, 3);
		world.setBlock(x + 5, y + 0, z + 9, FaithCraft2.HolyStone, 0, 3);
		world.setBlock(x + 6, y + 0, z + 9, FaithCraft2.HolyStone, 0, 3);
		world.setBlock(x + 7, y + 0, z + 9, FaithCraft2.HolyStone, 0, 3);
		world.setBlock(x + 8, y + 0, z + 9, FaithCraft2.HolyStone, 0, 3);
		world.setBlock(x + 9, y + 0, z + 9, FaithCraft2.HolyStone, 0, 3);
		world.setBlock(x + 10, y + 0, z + 9, FaithCraft2.HolyStone, 0, 3);
		world.setBlock(x + 11, y + 0, z + 9, FaithCraft2.HolyStone, 0, 3);
		world.setBlock(x + 0, y + 0, z + 10, FaithCraft2.HolyStone, 0, 3);
		world.setBlock(x + 1, y + 0, z + 10, FaithCraft2.HolyStone, 0, 3);
		world.setBlock(x + 2, y + 0, z + 10, FaithCraft2.HolyStone, 0, 3);
		world.setBlock(x + 3, y + 0, z + 10, FaithCraft2.HolyStone, 0, 3);
		world.setBlock(x + 4, y + 0, z + 10, FaithCraft2.HolyStone, 0, 3);
		world.setBlock(x + 5, y + 0, z + 10, FaithCraft2.HolyStone, 0, 3);
		world.setBlock(x + 6, y + 0, z + 10, FaithCraft2.HolyStone, 0, 3);
		world.setBlock(x + 7, y + 0, z + 10, FaithCraft2.HolyStone, 0, 3);
		world.setBlock(x + 8, y + 0, z + 10, FaithCraft2.HolyStone, 0, 3);
		world.setBlock(x + 9, y + 0, z + 10, FaithCraft2.HolyStone, 0, 3);
		world.setBlock(x + 10, y + 0, z + 10, FaithCraft2.HolyStone, 0, 3);
		world.setBlock(x + 11, y + 0, z + 10, FaithCraft2.HolyStone, 0, 3);
		world.setBlock(x + 0, y + 0, z + 11, FaithCraft2.HolyStone, 0, 3);
		world.setBlock(x + 1, y + 0, z + 11, FaithCraft2.HolyStone, 0, 3);
		world.setBlock(x + 2, y + 0, z + 11, FaithCraft2.HolyStone, 0, 3);
		world.setBlock(x + 3, y + 0, z + 11, FaithCraft2.HolyStone, 0, 3);
		world.setBlock(x + 4, y + 0, z + 11, FaithCraft2.HolyStone, 0, 3);
		world.setBlock(x + 5, y + 0, z + 11, FaithCraft2.HolyStone, 0, 3);
		world.setBlock(x + 6, y + 0, z + 11, FaithCraft2.HolyStone, 0, 3);
		world.setBlock(x + 7, y + 0, z + 11, FaithCraft2.HolyStone, 0, 3);
		world.setBlock(x + 8, y + 0, z + 11, FaithCraft2.HolyStone, 0, 3);
		world.setBlock(x + 9, y + 0, z + 11, FaithCraft2.HolyStone, 0, 3);
		world.setBlock(x + 10, y + 0, z + 11, FaithCraft2.HolyStone, 0, 3);
		world.setBlock(x + 11, y + 0, z + 11, FaithCraft2.HolyStone, 0, 3);
		world.setBlock(x + 0, y + 0, z + 12, FaithCraft2.HolyStone, 0, 3);
		world.setBlock(x + 1, y + 0, z + 12, FaithCraft2.HolyStone, 0, 3);
		world.setBlock(x + 2, y + 0, z + 12, FaithCraft2.HolyStone, 0, 3);
		world.setBlock(x + 3, y + 0, z + 12, FaithCraft2.HolyStone, 0, 3);
		world.setBlock(x + 4, y + 0, z + 12, FaithCraft2.HolyStone, 0, 3);
		world.setBlock(x + 5, y + 0, z + 12, FaithCraft2.HolyStone, 0, 3);
		world.setBlock(x + 6, y + 0, z + 12, FaithCraft2.HolyStone, 0, 3);
		world.setBlock(x + 7, y + 0, z + 12, FaithCraft2.HolyStone, 0, 3);
		world.setBlock(x + 8, y + 0, z + 12, FaithCraft2.HolyStone, 0, 3);
		world.setBlock(x + 9, y + 0, z + 12, FaithCraft2.HolyStone, 0, 3);
		world.setBlock(x + 10, y + 0, z + 12, FaithCraft2.HolyStone, 0, 3);
		world.setBlock(x + 11, y + 0, z + 12, FaithCraft2.HolyStone, 0, 3);
		world.setBlock(x + 0, y + 0, z + 13, FaithCraft2.HolyStone, 0, 3);
		world.setBlock(x + 1, y + 0, z + 13, FaithCraft2.HolyStone, 0, 3);
		world.setBlock(x + 2, y + 0, z + 13, FaithCraft2.HolyStone, 0, 3);
		world.setBlock(x + 3, y + 0, z + 13, FaithCraft2.HolyStone, 0, 3);
		world.setBlock(x + 4, y + 0, z + 13, FaithCraft2.HolyStone, 0, 3);
		world.setBlock(x + 5, y + 0, z + 13, FaithCraft2.HolyStone, 0, 3);
		world.setBlock(x + 6, y + 0, z + 13, FaithCraft2.HolyStone, 0, 3);
		world.setBlock(x + 7, y + 0, z + 13, FaithCraft2.HolyStone, 0, 3);
		world.setBlock(x + 8, y + 0, z + 13, FaithCraft2.HolyStone, 0, 3);
		world.setBlock(x + 9, y + 0, z + 13, FaithCraft2.HolyStone, 0, 3);
		world.setBlock(x + 10, y + 0, z + 13, FaithCraft2.HolyStone, 0, 3);
		world.setBlock(x + 11, y + 0, z + 13, FaithCraft2.HolyStone, 0, 3);
		world.setBlock(x + 0, y + 0, z + 14, FaithCraft2.HolyStone, 0, 3);
		world.setBlock(x + 1, y + 0, z + 14, FaithCraft2.HolyStone, 0, 3);
		world.setBlock(x + 2, y + 0, z + 14, FaithCraft2.HolyStone, 0, 3);
		world.setBlock(x + 3, y + 0, z + 14, FaithCraft2.HolyStone, 0, 3);
		world.setBlock(x + 4, y + 0, z + 14, FaithCraft2.HolyStone, 0, 3);
		world.setBlock(x + 5, y + 0, z + 14, FaithCraft2.HolyStone, 0, 3);
		world.setBlock(x + 6, y + 0, z + 14, FaithCraft2.HolyStone, 0, 3);
		world.setBlock(x + 7, y + 0, z + 14, FaithCraft2.HolyStone, 0, 3);
		world.setBlock(x + 8, y + 0, z + 14, FaithCraft2.HolyStone, 0, 3);
		world.setBlock(x + 9, y + 0, z + 14, FaithCraft2.HolyStone, 0, 3);
		world.setBlock(x + 10, y + 0, z + 14, FaithCraft2.HolyStone, 0, 3);
		world.setBlock(x + 11, y + 0, z + 14, FaithCraft2.HolyStone, 0, 3);
		world.setBlock(x + 0, y + 0, z + 15, FaithCraft2.HolyStone, 0, 3);
		world.setBlock(x + 1, y + 0, z + 15, FaithCraft2.HolyStone, 0, 3);
		world.setBlock(x + 2, y + 0, z + 15, FaithCraft2.HolyStone, 0, 3);
		world.setBlock(x + 3, y + 0, z + 15, FaithCraft2.HolyStone, 0, 3);
		world.setBlock(x + 4, y + 0, z + 15, FaithCraft2.HolyStone, 0, 3);
		world.setBlock(x + 5, y + 0, z + 15, FaithCraft2.HolyStone, 0, 3);
		world.setBlock(x + 6, y + 0, z + 15, FaithCraft2.HolyStone, 0, 3);
		world.setBlock(x + 7, y + 0, z + 15, FaithCraft2.HolyStone, 0, 3);
		world.setBlock(x + 8, y + 0, z + 15, FaithCraft2.HolyStone, 0, 3);
		world.setBlock(x + 9, y + 0, z + 15, FaithCraft2.HolyStone, 0, 3);
		world.setBlock(x + 10, y + 0, z + 15, FaithCraft2.HolyStone, 0, 3);
		world.setBlock(x + 11, y + 0, z + 15, FaithCraft2.HolyStone, 0, 3);
		world.setBlock(x + 0, y + 0, z + 16, Blocks.stone_slab, 0, 3);
		world.setBlock(x + 1, y + 0, z + 16, Blocks.stone_slab, 0, 3);
		world.setBlock(x + 2, y + 0, z + 16, Blocks.stone_slab, 0, 3);
		world.setBlock(x + 3, y + 0, z + 16, Blocks.stone_slab, 0, 3);
		world.setBlock(x + 4, y + 0, z + 16, Blocks.stone_slab, 0, 3);
		world.setBlock(x + 5, y + 0, z + 16, Blocks.stone_slab, 0, 3);
		world.setBlock(x + 6, y + 0, z + 16, Blocks.stone_slab, 0, 3);
		world.setBlock(x + 7, y + 0, z + 16, Blocks.stone_slab, 0, 3);
		world.setBlock(x + 8, y + 0, z + 16, Blocks.stone_slab, 0, 3);
		world.setBlock(x + 9, y + 0, z + 16, Blocks.stone_slab, 0, 3);
		world.setBlock(x + 10, y + 0, z + 16, Blocks.stone_slab, 0, 3);
		world.setBlock(x + 11, y + 0, z + 16, Blocks.stone_slab, 0, 3);
		world.setBlock(x + 0, y + 1, z + 0, FaithCraft2.HolyStone, 0, 3);
		world.setBlock(x + 1, y + 1, z + 0, FaithCraft2.HolyStone, 0, 3);
		world.setBlock(x + 2, y + 1, z + 0, FaithCraft2.HolyStone, 0, 3);
		world.setBlock(x + 3, y + 1, z + 0, FaithCraft2.HolyStone, 0, 3);
		world.setBlock(x + 4, y + 1, z + 0, FaithCraft2.HolyStone, 0, 3);
		world.setBlock(x + 5, y + 1, z + 0, FaithCraft2.HolyStone, 0, 3);
		world.setBlock(x + 6, y + 1, z + 0, FaithCraft2.HolyStone, 0, 3);
		world.setBlock(x + 7, y + 1, z + 0, FaithCraft2.HolyStone, 0, 3);
		world.setBlock(x + 8, y + 1, z + 0, FaithCraft2.HolyStone, 0, 3);
		world.setBlock(x + 9, y + 1, z + 0, FaithCraft2.HolyStone, 0, 3);
		world.setBlock(x + 10, y + 1, z + 0, FaithCraft2.HolyStone, 0, 3);
		world.setBlock(x + 11, y + 1, z + 0, FaithCraft2.HolyStone, 0, 3);
		world.setBlock(x + 0, y + 1, z + 1, FaithCraft2.HolyStone, 0, 3);
		world.setBlock(x + 11, y + 1, z + 1, FaithCraft2.HolyStone, 0, 3);
		world.setBlock(x + 0, y + 1, z + 2, FaithCraft2.HolyStone, 0, 3);
		world.setBlock(x + 11, y + 1, z + 2, FaithCraft2.HolyStone, 0, 3);
		world.setBlock(x + 0, y + 1, z + 3, FaithCraft2.HolyStone, 0, 3);
		world.setBlock(x + 11, y + 1, z + 3, FaithCraft2.HolyStone, 0, 3);
		world.setBlock(x + 0, y + 1, z + 4, FaithCraft2.HolyStone, 0, 3);
		world.setBlock(x + 11, y + 1, z + 4, FaithCraft2.HolyStone, 0, 3);
		world.setBlock(x + 0, y + 1, z + 5, FaithCraft2.HolyStone, 0, 3);
		world.setBlock(x + 11, y + 1, z + 5, FaithCraft2.HolyStone, 0, 3);
		world.setBlock(x + 0, y + 1, z + 6, FaithCraft2.HolyStone, 0, 3);
		world.setBlock(x + 11, y + 1, z + 6, FaithCraft2.HolyStone, 0, 3);
		world.setBlock(x + 0, y + 1, z + 7, FaithCraft2.HolyStone, 0, 3);
		world.setBlock(x + 11, y + 1, z + 7, FaithCraft2.HolyStone, 0, 3);
		world.setBlock(x + 0, y + 1, z + 8, FaithCraft2.HolyStone, 0, 3);
		world.setBlock(x + 2, y + 1, z + 8, FaithCraft2.HolyCobbleStone, 0, 3);
		world.setBlock(x + 9, y + 1, z + 8, FaithCraft2.HolyCobbleStone, 0, 3);
		world.setBlock(x + 11, y + 1, z + 8, FaithCraft2.HolyStone, 0, 3);
		world.setBlock(x + 0, y + 1, z + 9, FaithCraft2.HolyStone, 0, 3);
		world.setBlock(x + 3, y + 1, z + 9, Blocks.stone_brick_stairs, 1, 3);
		world.setBlock(x + 5, y + 1, z + 9, Blocks.stone_pressure_plate, 0, 3);
		world.setBlock(x + 6, y + 1, z + 9, Blocks.stone_pressure_plate, 0, 3);
		world.setBlock(x + 8, y + 1, z + 9, Blocks.stone_brick_stairs, 0, 3);
		world.setBlock(x + 11, y + 1, z + 9, FaithCraft2.HolyStone, 0, 3);
		world.setBlock(x + 0, y + 1, z + 10, FaithCraft2.HolyStone, 0, 3);
		world.setBlock(x + 1, y + 1, z + 10, FaithCraft2.HolyStone, 0, 3);
		world.setBlock(x + 2, y + 1, z + 10, FaithCraft2.HolyStone, 0, 3);
		world.setBlock(x + 3, y + 1, z + 10, FaithCraft2.HolyCobbleStone, 0, 3);
		world.setBlock(x + 4, y + 1, z + 10, FaithCraft2.HolyStone, 0, 3);
		world.setBlock(x + 5, y + 1, z + 10, Blocks.iron_door, 3, 3);
		world.setBlock(x + 6, y + 1, z + 10, Blocks.iron_door, 3, 3);
		world.setBlock(x + 7, y + 1, z + 10, FaithCraft2.HolyStone, 0, 3);
		world.setBlock(x + 8, y + 1, z + 10, FaithCraft2.HolyCobbleStone, 0, 3);
		world.setBlock(x + 9, y + 1, z + 10, FaithCraft2.HolyStone, 0, 3);
		world.setBlock(x + 10, y + 1, z + 10, FaithCraft2.HolyStone, 0, 3);
		world.setBlock(x + 11, y + 1, z + 10, FaithCraft2.HolyStone, 0, 3);
		world.setBlock(x + 0, y + 1, z + 11, FaithCraft2.HolyStone, 0, 3);
		world.setBlock(x + 5, y + 1, z + 11, Blocks.stone_pressure_plate, 0, 3);
		world.setBlock(x + 6, y + 1, z + 11, Blocks.stone_pressure_plate, 0, 3);
		world.setBlock(x + 11, y + 1, z + 11, FaithCraft2.HolyStone, 0, 3);
		world.setBlock(x + 0, y + 1, z + 12, FaithCraft2.HolyStone, 0, 3);
		world.setBlock(x + 11, y + 1, z + 12, FaithCraft2.HolyStone, 0, 3);
		world.setBlock(x + 0, y + 1, z + 13, FaithCraft2.HolyStone, 0, 3);
		world.setBlock(x + 11, y + 1, z + 13, FaithCraft2.HolyStone, 0, 3);
		world.setBlock(x + 0, y + 2, z + 0, FaithCraft2.HolyStone, 0, 3);
		world.setBlock(x + 1, y + 2, z + 0, FaithCraft2.HolyStone, 0, 3);
		world.setBlock(x + 2, y + 2, z + 0, FaithCraft2.HolyStone, 0, 3);
		world.setBlock(x + 3, y + 2, z + 0, FaithCraft2.HolyStone, 0, 3);
		world.setBlock(x + 4, y + 2, z + 0, FaithCraft2.HolyStone, 0, 3);
		world.setBlock(x + 5, y + 2, z + 0, FaithCraft2.HolyStone, 0, 3);
		world.setBlock(x + 6, y + 2, z + 0, FaithCraft2.HolyStone, 0, 3);
		world.setBlock(x + 7, y + 2, z + 0, FaithCraft2.HolyStone, 0, 3);
		world.setBlock(x + 8, y + 2, z + 0, FaithCraft2.HolyStone, 0, 3);
		world.setBlock(x + 9, y + 2, z + 0, FaithCraft2.HolyStone, 0, 3);
		world.setBlock(x + 10, y + 2, z + 0, FaithCraft2.HolyStone, 0, 3);
		world.setBlock(x + 11, y + 2, z + 0, FaithCraft2.HolyStone, 0, 3);
		world.setBlock(x + 0, y + 2, z + 1, FaithCraft2.HolyStone, 0, 3);
		world.setBlock(x + 11, y + 2, z + 1, FaithCraft2.HolyStone, 0, 3);
		world.setBlock(x + 0, y + 2, z + 2, FaithCraft2.HolyStone, 0, 3);
		world.setBlock(x + 11, y + 2, z + 2, FaithCraft2.HolyStone, 0, 3);
		world.setBlock(x + 0, y + 2, z + 3, FaithCraft2.HolyStone, 0, 3);
		world.setBlock(x + 11, y + 2, z + 3, FaithCraft2.HolyStone, 0, 3);
		world.setBlock(x + 0, y + 2, z + 4, FaithCraft2.HolyStone, 0, 3);
		world.setBlock(x + 11, y + 2, z + 4, FaithCraft2.HolyStone, 0, 3);
		world.setBlock(x + 0, y + 2, z + 5, FaithCraft2.HolyStone, 0, 3);
		world.setBlock(x + 11, y + 2, z + 5, FaithCraft2.HolyStone, 0, 3);
		world.setBlock(x + 0, y + 2, z + 6, FaithCraft2.HolyStone, 0, 3);
		world.setBlock(x + 11, y + 2, z + 6, FaithCraft2.HolyStone, 0, 3);
		world.setBlock(x + 0, y + 2, z + 7, FaithCraft2.HolyStone, 0, 3);
		world.setBlock(x + 11, y + 2, z + 7, FaithCraft2.HolyStone, 0, 3);
		world.setBlock(x + 0, y + 2, z + 8, FaithCraft2.HolyStone, 0, 3);
		world.setBlock(x + 2, y + 2, z + 8, FaithCraft2.HolyCobbleStone, 0, 3);
		world.setBlock(x + 9, y + 2, z + 8, FaithCraft2.HolyCobbleStone, 0, 3);
		world.setBlock(x + 11, y + 2, z + 8, FaithCraft2.HolyStone, 0, 3);
		world.setBlock(x + 0, y + 2, z + 9, FaithCraft2.HolyStone, 0, 3);
		world.setBlock(x + 1, y + 2, z + 9, Blocks.stonebrick, 0, 3);
		world.setBlock(x + 2, y + 2, z + 9, Blocks.stone_brick_stairs, 1, 3);
		world.setBlock(x + 9, y + 2, z + 9, Blocks.stone_brick_stairs, 0, 3);
		world.setBlock(x + 10, y + 2, z + 9, Blocks.stonebrick, 0, 3);
		world.setBlock(x + 11, y + 2, z + 9, FaithCraft2.HolyStone, 0, 3);
		world.setBlock(x + 0, y + 2, z + 10, FaithCraft2.HolyStone, 0, 3);
		world.setBlock(x + 1, y + 2, z + 10, FaithCraft2.HolyStone, 0, 3);
		world.setBlock(x + 2, y + 2, z + 10, FaithCraft2.HolyStone, 0, 3);
		world.setBlock(x + 3, y + 2, z + 10, FaithCraft2.HolyCobbleStone, 0, 3);
		world.setBlock(x + 4, y + 2, z + 10, FaithCraft2.HolyStone, 0, 3);
		ItemDoor.placeDoorBlock(world, x + 5, y + 2, z + 10, -1, Blocks.iron_door);
		ItemDoor.placeDoorBlock(world, x + 6, y + 2, z + 10, -1, Blocks.iron_door);
		world.setBlock(x + 7, y + 2, z + 10, FaithCraft2.HolyStone, 0, 3);
		world.setBlock(x + 8, y + 2, z + 10, FaithCraft2.HolyCobbleStone, 0, 3);
		world.setBlock(x + 9, y + 2, z + 10, FaithCraft2.HolyStone, 0, 3);
		world.setBlock(x + 10, y + 2, z + 10, FaithCraft2.HolyStone, 0, 3);
		world.setBlock(x + 11, y + 2, z + 10, FaithCraft2.HolyStone, 0, 3);
		world.setBlock(x + 0, y + 2, z + 11, FaithCraft2.HolyStone, 0, 3);
		world.setBlock(x + 11, y + 2, z + 11, FaithCraft2.HolyStone, 0, 3);
		world.setBlock(x + 0, y + 2, z + 12, FaithCraft2.HolyStone, 0, 3);
		world.setBlock(x + 11, y + 2, z + 12, FaithCraft2.HolyStone, 0, 3);
		world.setBlock(x + 0, y + 3, z + 0, FaithCraft2.HolyStone, 0, 3);
		world.setBlock(x + 1, y + 3, z + 0, FaithCraft2.HolyStone, 0, 3);
		world.setBlock(x + 2, y + 3, z + 0, FaithCraft2.HolyStone, 0, 3);
		world.setBlock(x + 3, y + 3, z + 0, FaithCraft2.HolyStone, 0, 3);
		world.setBlock(x + 4, y + 3, z + 0, FaithCraft2.HolyStone, 0, 3);
		world.setBlock(x + 5, y + 3, z + 0, FaithCraft2.HolyStone, 0, 3);
		world.setBlock(x + 6, y + 3, z + 0, FaithCraft2.HolyStone, 0, 3);
		world.setBlock(x + 7, y + 3, z + 0, FaithCraft2.HolyStone, 0, 3);
		world.setBlock(x + 8, y + 3, z + 0, FaithCraft2.HolyStone, 0, 3);
		world.setBlock(x + 9, y + 3, z + 0, FaithCraft2.HolyStone, 0, 3);
		world.setBlock(x + 10, y + 3, z + 0, FaithCraft2.HolyStone, 0, 3);
		world.setBlock(x + 11, y + 3, z + 0, FaithCraft2.HolyStone, 0, 3);
		world.setBlock(x + 0, y + 3, z + 1, FaithCraft2.HolyStone, 0, 3);
		world.setBlock(x + 11, y + 3, z + 1, FaithCraft2.HolyStone, 0, 3);
		world.setBlock(x + 0, y + 3, z + 2, FaithCraft2.HolyStone, 0, 3);
		world.setBlock(x + 11, y + 3, z + 2, FaithCraft2.HolyStone, 0, 3);
		world.setBlock(x + 0, y + 3, z + 3, FaithCraft2.HolyStone, 0, 3);
		world.setBlock(x + 11, y + 3, z + 3, FaithCraft2.HolyStone, 0, 3);
		world.setBlock(x + 0, y + 3, z + 4, FaithCraft2.HolyStone, 0, 3);
		world.setBlock(x + 11, y + 3, z + 4, FaithCraft2.HolyStone, 0, 3);
		world.setBlock(x + 0, y + 3, z + 5, FaithCraft2.HolyStone, 0, 3);
		world.setBlock(x + 11, y + 3, z + 5, FaithCraft2.HolyStone, 0, 3);
		world.setBlock(x + 0, y + 3, z + 6, FaithCraft2.HolyStone, 0, 3);
		world.setBlock(x + 11, y + 3, z + 6, FaithCraft2.HolyStone, 0, 3);
		world.setBlock(x + 0, y + 3, z + 7, FaithCraft2.HolyStone, 0, 3);
		world.setBlock(x + 11, y + 3, z + 7, FaithCraft2.HolyStone, 0, 3);
		world.setBlock(x + 0, y + 3, z + 8, FaithCraft2.HolyStone, 0, 3);
		world.setBlock(x + 1, y + 3, z + 8, Blocks.stone_brick_stairs, 3, 3);
		world.setBlock(x + 2, y + 3, z + 8, FaithCraft2.HolyCobbleStone, 0, 3);
		world.setBlock(x + 9, y + 3, z + 8, FaithCraft2.HolyCobbleStone, 0, 3);
		world.setBlock(x + 10, y + 3, z + 8, Blocks.stone_brick_stairs, 3, 3);
		world.setBlock(x + 11, y + 3, z + 8, FaithCraft2.HolyStone, 0, 3);
		world.setBlock(x + 0, y + 3, z + 9, FaithCraft2.HolyStone, 0, 3);
		world.setBlock(x + 11, y + 3, z + 9, FaithCraft2.HolyStone, 0, 3);
		world.setBlock(x + 0, y + 3, z + 10, FaithCraft2.HolyCobbleStone, 0, 3);
		world.setBlock(x + 1, y + 3, z + 10, FaithCraft2.HolyCobbleStone, 0, 3);
		world.setBlock(x + 2, y + 3, z + 10, FaithCraft2.HolyCobbleStone, 0, 3);
		world.setBlock(x + 3, y + 3, z + 10, FaithCraft2.HolyCobbleStone, 0, 3);
		world.setBlock(x + 4, y + 3, z + 10, FaithCraft2.HolyCobbleStone, 0, 3);
		world.setBlock(x + 5, y + 3, z + 10, FaithCraft2.HolyCobbleStone, 0, 3);
		world.setBlock(x + 6, y + 3, z + 10, FaithCraft2.HolyCobbleStone, 0, 3);
		world.setBlock(x + 7, y + 3, z + 10, FaithCraft2.HolyCobbleStone, 0, 3);
		world.setBlock(x + 8, y + 3, z + 10, FaithCraft2.HolyCobbleStone, 0, 3);
		world.setBlock(x + 9, y + 3, z + 10, FaithCraft2.HolyCobbleStone, 0, 3);
		world.setBlock(x + 10, y + 3, z + 10, FaithCraft2.HolyCobbleStone, 0, 3);
		world.setBlock(x + 11, y + 3, z + 10, FaithCraft2.HolyCobbleStone, 0, 3);
		world.setBlock(x + 0, y + 3, z + 11, FaithCraft2.HolyStone, 0, 3);
		world.setBlock(x + 11, y + 3, z + 11, FaithCraft2.HolyStone, 0, 3);
		world.setBlock(x + 0, y + 4, z + 0, FaithCraft2.HolyStone, 0, 3);
		world.setBlock(x + 1, y + 4, z + 0, FaithCraft2.HolyStone, 0, 3);
		world.setBlock(x + 2, y + 4, z + 0, FaithCraft2.HolyStone, 0, 3);
		world.setBlock(x + 3, y + 4, z + 0, FaithCraft2.HolyStone, 0, 3);
		world.setBlock(x + 4, y + 4, z + 0, FaithCraft2.HolyStone, 0, 3);
		world.setBlock(x + 5, y + 4, z + 0, FaithCraft2.HolyStone, 0, 3);
		world.setBlock(x + 6, y + 4, z + 0, FaithCraft2.HolyStone, 0, 3);
		world.setBlock(x + 7, y + 4, z + 0, FaithCraft2.HolyStone, 0, 3);
		world.setBlock(x + 8, y + 4, z + 0, FaithCraft2.HolyStone, 0, 3);
		world.setBlock(x + 9, y + 4, z + 0, FaithCraft2.HolyStone, 0, 3);
		world.setBlock(x + 10, y + 4, z + 0, FaithCraft2.HolyStone, 0, 3);
		world.setBlock(x + 11, y + 4, z + 0, FaithCraft2.HolyStone, 0, 3);
		world.setBlock(x + 0, y + 4, z + 1, FaithCraft2.HolyStone, 0, 3);
		world.setBlock(x + 11, y + 4, z + 1, FaithCraft2.HolyStone, 0, 3);
		world.setBlock(x + 0, y + 4, z + 2, FaithCraft2.HolyStone, 0, 3);
		world.setBlock(x + 11, y + 4, z + 2, FaithCraft2.HolyStone, 0, 3);
		world.setBlock(x + 0, y + 4, z + 3, FaithCraft2.HolyStone, 0, 3);
		world.setBlock(x + 11, y + 4, z + 3, FaithCraft2.HolyStone, 0, 3);
		world.setBlock(x + 0, y + 4, z + 4, FaithCraft2.HolyStone, 0, 3);
		world.setBlock(x + 11, y + 4, z + 4, FaithCraft2.HolyStone, 0, 3);
		world.setBlock(x + 0, y + 4, z + 5, FaithCraft2.HolyStone, 0, 3);
		world.setBlock(x + 11, y + 4, z + 5, FaithCraft2.HolyStone, 0, 3);
		world.setBlock(x + 0, y + 4, z + 6, FaithCraft2.HolyStone, 0, 3);
		world.setBlock(x + 11, y + 4, z + 6, FaithCraft2.HolyStone, 0, 3);
		world.setBlock(x + 0, y + 4, z + 7, FaithCraft2.HolyStone, 0, 3);
		world.setBlock(x + 1, y + 4, z + 7, Blocks.stone_brick_stairs, 3, 3);
		world.setBlock(x + 2, y + 4, z + 7, FaithCraft2.HolyCobbleStone, 0, 3);
		world.setBlock(x + 9, y + 4, z + 7, FaithCraft2.HolyCobbleStone, 0, 3);
		world.setBlock(x + 10, y + 4, z + 7, Blocks.stone_brick_stairs, 3, 3);
		world.setBlock(x + 11, y + 4, z + 7, FaithCraft2.HolyStone, 0, 3);
		world.setBlock(x + 0, y + 4, z + 8, FaithCraft2.HolyStone, 0, 3);
		world.setBlock(x + 2, y + 4, z + 8, FaithCraft2.HolyCobbleStone, 0, 3);
		world.setBlock(x + 9, y + 4, z + 8, FaithCraft2.HolyCobbleStone, 0, 3);
		world.setBlock(x + 11, y + 4, z + 8, FaithCraft2.HolyStone, 0, 3);
		world.setBlock(x + 0, y + 4, z + 9, FaithCraft2.HolyStone, 0, 3);
		world.setBlock(x + 11, y + 4, z + 9, FaithCraft2.HolyStone, 0, 3);
		world.setBlock(x + 0, y + 4, z + 10, FaithCraft2.HolyStone, 0, 3);
		world.setBlock(x + 1, y + 4, z + 10, FaithCraft2.HolyStone, 0, 3);
		world.setBlock(x + 2, y + 4, z + 10, FaithCraft2.HolyStone, 0, 3);
		world.setBlock(x + 3, y + 4, z + 10, Blocks.glowstone, 0, 3);
		world.setBlock(x + 4, y + 4, z + 10, FaithCraft2.HolyStone, 0, 3);
		world.setBlock(x + 5, y + 4, z + 10, FaithCraft2.HolyStone, 0, 3);
		world.setBlock(x + 6, y + 4, z + 10, FaithCraft2.HolyStone, 0, 3);
		world.setBlock(x + 7, y + 4, z + 10, FaithCraft2.HolyStone, 0, 3);
		world.setBlock(x + 8, y + 4, z + 10, Blocks.glowstone, 0, 3);
		world.setBlock(x + 9, y + 4, z + 10, FaithCraft2.HolyStone, 0, 3);
		world.setBlock(x + 10, y + 4, z + 10, FaithCraft2.HolyStone, 0, 3);
		world.setBlock(x + 11, y + 4, z + 10, FaithCraft2.HolyStone, 0, 3);
		world.setBlock(x + 0, y + 5, z + 0, FaithCraft2.HolyStone, 0, 3);
		world.setBlock(x + 1, y + 5, z + 0, FaithCraft2.HolyStone, 0, 3);
		world.setBlock(x + 2, y + 5, z + 0, FaithCraft2.HolyStone, 0, 3);
		world.setBlock(x + 3, y + 5, z + 0, FaithCraft2.HolyStone, 0, 3);
		world.setBlock(x + 4, y + 5, z + 0, FaithCraft2.HolyStone, 0, 3);
		world.setBlock(x + 5, y + 5, z + 0, FaithCraft2.HolyStone, 0, 3);
		world.setBlock(x + 6, y + 5, z + 0, FaithCraft2.HolyStone, 0, 3);
		world.setBlock(x + 7, y + 5, z + 0, FaithCraft2.HolyStone, 0, 3);
		world.setBlock(x + 8, y + 5, z + 0, FaithCraft2.HolyStone, 0, 3);
		world.setBlock(x + 9, y + 5, z + 0, FaithCraft2.HolyStone, 0, 3);
		world.setBlock(x + 10, y + 5, z + 0, FaithCraft2.HolyStone, 0, 3);
		world.setBlock(x + 11, y + 5, z + 0, FaithCraft2.HolyStone, 0, 3);
		world.setBlock(x + 0, y + 5, z + 1, FaithCraft2.HolyStone, 0, 3);
		world.setBlock(x + 1, y + 5, z + 1, FaithCraft2.HolyStone, 0, 3);
		world.setBlock(x + 2, y + 5, z + 1, FaithCraft2.HolyStone, 0, 3);
		world.setBlock(x + 3, y + 5, z + 1, FaithCraft2.HolyStone, 0, 3);
		world.setBlock(x + 4, y + 5, z + 1, Blocks.glowstone, 0, 3);
		world.setBlock(x + 5, y + 5, z + 1, Blocks.glowstone, 0, 3);
		world.setBlock(x + 6, y + 5, z + 1, Blocks.glowstone, 0, 3);
		world.setBlock(x + 7, y + 5, z + 1, Blocks.glowstone, 0, 3);
		world.setBlock(x + 8, y + 5, z + 1, FaithCraft2.HolyStone, 0, 3);
		world.setBlock(x + 9, y + 5, z + 1, FaithCraft2.HolyStone, 0, 3);
		world.setBlock(x + 10, y + 5, z + 1, FaithCraft2.HolyStone, 0, 3);
		world.setBlock(x + 11, y + 5, z + 1, FaithCraft2.HolyStone, 0, 3);
		world.setBlock(x + 0, y + 5, z + 2, FaithCraft2.HolyStone, 0, 3);
		world.setBlock(x + 1, y + 5, z + 2, FaithCraft2.HolyStone, 0, 3);
		world.setBlock(x + 2, y + 5, z + 2, FaithCraft2.HolyStone, 0, 3);
		world.setBlock(x + 3, y + 5, z + 2, FaithCraft2.HolyStone, 0, 3);
		world.setBlock(x + 4, y + 5, z + 2, FaithCraft2.HolyStone, 0, 3);
		world.setBlock(x + 5, y + 5, z + 2, FaithCraft2.HolyStone, 0, 3);
		world.setBlock(x + 6, y + 5, z + 2, FaithCraft2.HolyStone, 0, 3);
		world.setBlock(x + 7, y + 5, z + 2, FaithCraft2.HolyStone, 0, 3);
		world.setBlock(x + 8, y + 5, z + 2, FaithCraft2.HolyStone, 0, 3);
		world.setBlock(x + 9, y + 5, z + 2, FaithCraft2.HolyStone, 0, 3);
		world.setBlock(x + 10, y + 5, z + 2, FaithCraft2.HolyStone, 0, 3);
		world.setBlock(x + 11, y + 5, z + 2, FaithCraft2.HolyStone, 0, 3);
		world.setBlock(x + 0, y + 5, z + 3, FaithCraft2.HolyStone, 0, 3);
		world.setBlock(x + 1, y + 5, z + 3, FaithCraft2.HolyStone, 0, 3);
		world.setBlock(x + 2, y + 5, z + 3, FaithCraft2.HolyStone, 0, 3);
		world.setBlock(x + 3, y + 5, z + 3, FaithCraft2.HolyStone, 0, 3);
		world.setBlock(x + 4, y + 5, z + 3, FaithCraft2.HolyStone, 0, 3);
		world.setBlock(x + 5, y + 5, z + 3, FaithCraft2.HolyStone, 0, 3);
		world.setBlock(x + 6, y + 5, z + 3, FaithCraft2.HolyStone, 0, 3);
		world.setBlock(x + 7, y + 5, z + 3, FaithCraft2.HolyStone, 0, 3);
		world.setBlock(x + 8, y + 5, z + 3, FaithCraft2.HolyStone, 0, 3);
		world.setBlock(x + 9, y + 5, z + 3, FaithCraft2.HolyStone, 0, 3);
		world.setBlock(x + 10, y + 5, z + 3, FaithCraft2.HolyStone, 0, 3);
		world.setBlock(x + 11, y + 5, z + 3, FaithCraft2.HolyStone, 0, 3);
		world.setBlock(x + 0, y + 5, z + 4, FaithCraft2.HolyStone, 0, 3);
		world.setBlock(x + 1, y + 5, z + 4, FaithCraft2.HolyStone, 0, 3);
		world.setBlock(x + 2, y + 5, z + 4, FaithCraft2.HolyStone, 0, 3);
		world.setBlock(x + 3, y + 5, z + 4, FaithCraft2.HolyStone, 0, 3);
		world.setBlock(x + 4, y + 5, z + 4, FaithCraft2.HolyStone, 0, 3);
		world.setBlock(x + 5, y + 5, z + 4, FaithCraft2.HolyStone, 0, 3);
		world.setBlock(x + 6, y + 5, z + 4, FaithCraft2.HolyStone, 0, 3);
		world.setBlock(x + 7, y + 5, z + 4, FaithCraft2.HolyStone, 0, 3);
		world.setBlock(x + 8, y + 5, z + 4, FaithCraft2.HolyStone, 0, 3);
		world.setBlock(x + 9, y + 5, z + 4, FaithCraft2.HolyStone, 0, 3);
		world.setBlock(x + 10, y + 5, z + 4, FaithCraft2.HolyStone, 0, 3);
		world.setBlock(x + 11, y + 5, z + 4, FaithCraft2.HolyStone, 0, 3);
		world.setBlock(x + 0, y + 5, z + 5, FaithCraft2.HolyStone, 0, 3);
		world.setBlock(x + 1, y + 5, z + 5, FaithCraft2.HolyStone, 0, 3);
		world.setBlock(x + 2, y + 5, z + 5, FaithCraft2.HolyStone, 0, 3);
		world.setBlock(x + 3, y + 5, z + 5, FaithCraft2.HolyStone, 0, 3);
		world.setBlock(x + 4, y + 5, z + 5, FaithCraft2.HolyStone, 0, 3);
		world.setBlock(x + 5, y + 5, z + 5, FaithCraft2.HolyStone, 0, 3);
		world.setBlock(x + 6, y + 5, z + 5, FaithCraft2.HolyStone, 0, 3);
		world.setBlock(x + 7, y + 5, z + 5, FaithCraft2.HolyStone, 0, 3);
		world.setBlock(x + 8, y + 5, z + 5, FaithCraft2.HolyStone, 0, 3);
		world.setBlock(x + 9, y + 5, z + 5, FaithCraft2.HolyStone, 0, 3);
		world.setBlock(x + 10, y + 5, z + 5, FaithCraft2.HolyStone, 0, 3);
		world.setBlock(x + 11, y + 5, z + 5, FaithCraft2.HolyStone, 0, 3);
		world.setBlock(x + 0, y + 5, z + 6, FaithCraft2.HolyStone, 0, 3);
		world.setBlock(x + 1, y + 5, z + 6, Blocks.stone_brick_stairs, 3, 3);
		world.setBlock(x + 2, y + 5, z + 6, FaithCraft2.HolyStone, 0, 3);
		world.setBlock(x + 3, y + 5, z + 6, FaithCraft2.HolyStone, 0, 3);
		world.setBlock(x + 4, y + 5, z + 6, FaithCraft2.HolyStone, 0, 3);
		world.setBlock(x + 5, y + 5, z + 6, FaithCraft2.HolyStone, 0, 3);
		world.setBlock(x + 6, y + 5, z + 6, FaithCraft2.HolyStone, 0, 3);
		world.setBlock(x + 7, y + 5, z + 6, FaithCraft2.HolyStone, 0, 3);
		world.setBlock(x + 8, y + 5, z + 6, FaithCraft2.HolyStone, 0, 3);
		world.setBlock(x + 9, y + 5, z + 6, FaithCraft2.HolyStone, 0, 3);
		world.setBlock(x + 10, y + 5, z + 6, Blocks.stone_brick_stairs, 3, 3);
		world.setBlock(x + 11, y + 5, z + 6, FaithCraft2.HolyStone, 0, 3);
		world.setBlock(x + 0, y + 5, z + 7, FaithCraft2.HolyStone, 0, 3);
		world.setBlock(x + 2, y + 5, z + 7, FaithCraft2.HolyStone, 0, 3);
		world.setBlock(x + 3, y + 5, z + 7, FaithCraft2.HolyStone, 0, 3);
		world.setBlock(x + 4, y + 5, z + 7, FaithCraft2.HolyStone, 0, 3);
		world.setBlock(x + 5, y + 5, z + 7, FaithCraft2.HolyStone, 0, 3);
		world.setBlock(x + 6, y + 5, z + 7, FaithCraft2.HolyStone, 0, 3);
		world.setBlock(x + 7, y + 5, z + 7, FaithCraft2.HolyStone, 0, 3);
		world.setBlock(x + 8, y + 5, z + 7, FaithCraft2.HolyStone, 0, 3);
		world.setBlock(x + 9, y + 5, z + 7, FaithCraft2.HolyStone, 0, 3);
		world.setBlock(x + 11, y + 5, z + 7, FaithCraft2.HolyStone, 0, 3);
		world.setBlock(x + 0, y + 5, z + 8, FaithCraft2.HolyStone, 0, 3);
		world.setBlock(x + 2, y + 5, z + 8, FaithCraft2.HolyStone, 0, 3);
		world.setBlock(x + 3, y + 5, z + 8, FaithCraft2.HolyStone, 0, 3);
		world.setBlock(x + 4, y + 5, z + 8, FaithCraft2.HolyStone, 0, 3);
		world.setBlock(x + 5, y + 5, z + 8, FaithCraft2.HolyStone, 0, 3);
		world.setBlock(x + 6, y + 5, z + 8, FaithCraft2.HolyStone, 0, 3);
		world.setBlock(x + 7, y + 5, z + 8, FaithCraft2.HolyStone, 0, 3);
		world.setBlock(x + 8, y + 5, z + 8, FaithCraft2.HolyStone, 0, 3);
		world.setBlock(x + 9, y + 5, z + 8, FaithCraft2.HolyStone, 0, 3);
		world.setBlock(x + 11, y + 5, z + 8, FaithCraft2.HolyStone, 0, 3);
		world.setBlock(x + 0, y + 5, z + 9, FaithCraft2.HolyStone, 0, 3);
		world.setBlock(x + 2, y + 5, z + 9, FaithCraft2.HolyStone, 0, 3);
		world.setBlock(x + 3, y + 5, z + 9, FaithCraft2.HolyStone, 0, 3);
		world.setBlock(x + 4, y + 5, z + 9, FaithCraft2.HolyStone, 0, 3);
		world.setBlock(x + 5, y + 5, z + 9, FaithCraft2.HolyStone, 0, 3);
		world.setBlock(x + 6, y + 5, z + 9, FaithCraft2.HolyStone, 0, 3);
		world.setBlock(x + 7, y + 5, z + 9, FaithCraft2.HolyStone, 0, 3);
		world.setBlock(x + 8, y + 5, z + 9, FaithCraft2.HolyStone, 0, 3);
		world.setBlock(x + 9, y + 5, z + 9, FaithCraft2.HolyStone, 0, 3);
		world.setBlock(x + 11, y + 5, z + 9, FaithCraft2.HolyStone, 0, 3);
		world.setBlock(x + 0, y + 5, z + 10, FaithCraft2.HolyStone, 0, 3);
		world.setBlock(x + 1, y + 5, z + 10, FaithCraft2.HolyStone, 0, 3);
		world.setBlock(x + 2, y + 5, z + 10, FaithCraft2.HolyStone, 0, 3);
		world.setBlock(x + 3, y + 5, z + 10, FaithCraft2.HolyCobbleStone, 0, 3);
		world.setBlock(x + 4, y + 5, z + 10, FaithCraft2.HolyStone, 0, 3);
		world.setBlock(x + 5, y + 5, z + 10, FaithCraft2.HolyStone, 0, 3);
		world.setBlock(x + 6, y + 5, z + 10, FaithCraft2.HolyStone, 0, 3);
		world.setBlock(x + 7, y + 5, z + 10, FaithCraft2.HolyStone, 0, 3);
		world.setBlock(x + 8, y + 5, z + 10, FaithCraft2.HolyCobbleStone, 0, 3);
		world.setBlock(x + 9, y + 5, z + 10, FaithCraft2.HolyStone, 0, 3);
		world.setBlock(x + 10, y + 5, z + 10, FaithCraft2.HolyStone, 0, 3);
		world.setBlock(x + 11, y + 5, z + 10, FaithCraft2.HolyStone, 0, 3);
		world.setBlock(x + 0, y + 6, z + 0, FaithCraft2.HolyStone, 0, 3);
		world.setBlock(x + 1, y + 6, z + 0, FaithCraft2.HolyStone, 0, 3);
		world.setBlock(x + 2, y + 6, z + 0, FaithCraft2.HolyStone, 0, 3);
		world.setBlock(x + 3, y + 6, z + 0, FaithCraft2.HolyStone, 0, 3);
		world.setBlock(x + 4, y + 6, z + 0, FaithCraft2.HolyStone, 0, 3);
		world.setBlock(x + 5, y + 6, z + 0, FaithCraft2.HolyStone, 0, 3);
		world.setBlock(x + 6, y + 6, z + 0, FaithCraft2.HolyStone, 0, 3);
		world.setBlock(x + 7, y + 6, z + 0, FaithCraft2.HolyStone, 0, 3);
		world.setBlock(x + 8, y + 6, z + 0, FaithCraft2.HolyStone, 0, 3);
		world.setBlock(x + 9, y + 6, z + 0, FaithCraft2.HolyStone, 0, 3);
		world.setBlock(x + 10, y + 6, z + 0, FaithCraft2.HolyStone, 0, 3);
		world.setBlock(x + 11, y + 6, z + 0, FaithCraft2.HolyStone, 0, 3);
		world.setBlock(x + 0, y + 6, z + 1, FaithCraft2.HolyStone, 0, 3);
		world.setBlock(x + 1, y + 6, z + 1, FaithCraft2.HolyCobbleStone, 0, 3);
		world.setBlock(x + 2, y + 6, z + 1, FaithCraft2.HolyCobbleStone, 0, 3);
		world.setBlock(x + 5, y + 6, z + 1, FaithCraft2.Altar, 1, 3);
		world.setBlock(x + 6, y + 6, z + 1, FaithCraft2.Altar, 1, 3);
		world.setBlock(x + 9, y + 6, z + 1, FaithCraft2.HolyCobbleStone, 0, 3);
		world.setBlock(x + 10, y + 6, z + 1, FaithCraft2.HolyCobbleStone, 0, 3);
		world.setBlock(x + 11, y + 6, z + 1, FaithCraft2.HolyStone, 0, 3);
		world.setBlock(x + 0, y + 6, z + 2, FaithCraft2.HolyStone, 0, 3);
		world.setBlock(x + 1, y + 6, z + 2, FaithCraft2.HolyCobbleStone, 0, 3);
		world.setBlock(x + 10, y + 6, z + 2, FaithCraft2.HolyCobbleStone, 0, 3);
		world.setBlock(x + 11, y + 6, z + 2, FaithCraft2.HolyStone, 0, 3);
		world.setBlock(x + 0, y + 6, z + 3, FaithCraft2.HolyStone, 0, 3);
		world.setBlock(x + 1, y + 6, z + 3, Blocks.stone_brick_stairs, 3, 3);
		world.setBlock(x + 10, y + 6, z + 3, Blocks.stone_brick_stairs, 3, 3);
		world.setBlock(x + 11, y + 6, z + 3, FaithCraft2.HolyStone, 0, 3);
		world.setBlock(x + 0, y + 6, z + 4, FaithCraft2.HolyStone, 0, 3);
		world.setBlock(x + 11, y + 6, z + 4, FaithCraft2.HolyStone, 0, 3);
		world.setBlock(x + 0, y + 6, z + 5, FaithCraft2.HolyStone, 0, 3);
		world.setBlock(x + 11, y + 6, z + 5, FaithCraft2.HolyStone, 0, 3);
		world.setBlock(x + 0, y + 6, z + 6, FaithCraft2.HolyStone, 0, 3);
		world.setBlock(x + 11, y + 6, z + 6, FaithCraft2.HolyStone, 0, 3);
		world.setBlock(x + 0, y + 6, z + 7, FaithCraft2.HolyStone, 0, 3);
		world.setBlock(x + 11, y + 6, z + 7, FaithCraft2.HolyStone, 0, 3);
		world.setBlock(x + 0, y + 6, z + 8, FaithCraft2.HolyStone, 0, 3);
		world.setBlock(x + 11, y + 6, z + 8, FaithCraft2.HolyStone, 0, 3);
		world.setBlock(x + 0, y + 6, z + 9, FaithCraft2.HolyStone, 0, 3);
		world.setBlock(x + 11, y + 6, z + 9, FaithCraft2.HolyStone, 0, 3);
		world.setBlock(x + 0, y + 6, z + 10, FaithCraft2.HolyStone, 0, 3);
		world.setBlock(x + 1, y + 6, z + 10, FaithCraft2.HolyStone, 0, 3);
		world.setBlock(x + 2, y + 6, z + 10, FaithCraft2.HolyStone, 0, 3);
		world.setBlock(x + 3, y + 6, z + 10, FaithCraft2.HolyCobbleStone, 0, 3);
		world.setBlock(x + 4, y + 6, z + 10, FaithCraft2.HolyStone, 0, 3);
		world.setBlock(x + 5, y + 6, z + 10, Blocks.glass_pane, 0, 3);
		world.setBlock(x + 6, y + 6, z + 10, Blocks.glass_pane, 0, 3);
		world.setBlock(x + 7, y + 6, z + 10, FaithCraft2.HolyStone, 0, 3);
		world.setBlock(x + 8, y + 6, z + 10, FaithCraft2.HolyCobbleStone, 0, 3);
		world.setBlock(x + 9, y + 6, z + 10, FaithCraft2.HolyStone, 0, 3);
		world.setBlock(x + 10, y + 6, z + 10, FaithCraft2.HolyStone, 0, 3);
		world.setBlock(x + 11, y + 6, z + 10, FaithCraft2.HolyStone, 0, 3);
		world.setBlock(x + 0, y + 7, z + 0, FaithCraft2.HolyStone, 0, 3);
		world.setBlock(x + 1, y + 7, z + 0, FaithCraft2.HolyStone, 0, 3);
		world.setBlock(x + 2, y + 7, z + 0, FaithCraft2.HolyStone, 0, 3);
		world.setBlock(x + 3, y + 7, z + 0, Blocks.glass_pane, 0, 3);
		world.setBlock(x + 4, y + 7, z + 0, Blocks.glass_pane, 0, 3);
		world.setBlock(x + 5, y + 7, z + 0, Blocks.glass_pane, 0, 3);
		world.setBlock(x + 6, y + 7, z + 0, Blocks.glass_pane, 0, 3);
		world.setBlock(x + 7, y + 7, z + 0, Blocks.glass_pane, 0, 3);
		world.setBlock(x + 8, y + 7, z + 0, Blocks.glass_pane, 0, 3);
		world.setBlock(x + 9, y + 7, z + 0, FaithCraft2.HolyStone, 0, 3);
		world.setBlock(x + 10, y + 7, z + 0, FaithCraft2.HolyStone, 0, 3);
		world.setBlock(x + 11, y + 7, z + 0, FaithCraft2.HolyStone, 0, 3);
		world.setBlock(x + 0, y + 7, z + 1, FaithCraft2.HolyStone, 0, 3);
		world.setBlock(x + 1, y + 7, z + 1, Blocks.stonebrick, 0, 3);
		world.setBlock(x + 2, y + 7, z + 1, FaithCraft2.HolyCobbleStone, 0, 3);
		world.setBlock(x + 9, y + 7, z + 1, FaithCraft2.HolyCobbleStone, 0, 3);
		world.setBlock(x + 10, y + 7, z + 1, Blocks.stonebrick, 0, 3);
		world.setBlock(x + 11, y + 7, z + 1, FaithCraft2.HolyStone, 0, 3);
		world.setBlock(x + 0, y + 7, z + 2, FaithCraft2.HolyStone, 0, 3);
		world.setBlock(x + 1, y + 7, z + 2, Blocks.stone_brick_stairs, 3, 3);
		world.setBlock(x + 10, y + 7, z + 2, Blocks.stone_brick_stairs, 3, 3);
		world.setBlock(x + 11, y + 7, z + 2, FaithCraft2.HolyStone, 0, 3);
		world.setBlock(x + 0, y + 7, z + 3, FaithCraft2.HolyStone, 0, 3);
		world.setBlock(x + 11, y + 7, z + 3, FaithCraft2.HolyStone, 0, 3);
		world.setBlock(x + 0, y + 7, z + 4, FaithCraft2.HolyStone, 0, 3);
		world.setBlock(x + 11, y + 7, z + 4, FaithCraft2.HolyStone, 0, 3);
		world.setBlock(x + 0, y + 7, z + 5, Blocks.glowstone, 0, 3);
		world.setBlock(x + 11, y + 7, z + 5, Blocks.glowstone, 0, 3);
		world.setBlock(x + 0, y + 7, z + 6, FaithCraft2.HolyStone, 0, 3);
		world.setBlock(x + 11, y + 7, z + 6, FaithCraft2.HolyStone, 0, 3);
		world.setBlock(x + 0, y + 7, z + 7, FaithCraft2.HolyStone, 0, 3);
		world.setBlock(x + 11, y + 7, z + 7, FaithCraft2.HolyStone, 0, 3);
		world.setBlock(x + 0, y + 7, z + 8, FaithCraft2.HolyStone, 0, 3);
		world.setBlock(x + 11, y + 7, z + 8, FaithCraft2.HolyStone, 0, 3);
		world.setBlock(x + 0, y + 7, z + 9, FaithCraft2.HolyStone, 0, 3);
		world.setBlock(x + 11, y + 7, z + 9, FaithCraft2.HolyStone, 0, 3);
		world.setBlock(x + 0, y + 7, z + 10, FaithCraft2.HolyStone, 0, 3);
		world.setBlock(x + 1, y + 7, z + 10, FaithCraft2.HolyStone, 0, 3);
		world.setBlock(x + 2, y + 7, z + 10, FaithCraft2.HolyStone, 0, 3);
		world.setBlock(x + 3, y + 7, z + 10, FaithCraft2.HolyCobbleStone, 0, 3);
		world.setBlock(x + 4, y + 7, z + 10, Blocks.glass_pane, 0, 3);
		world.setBlock(x + 5, y + 7, z + 10, Blocks.glass_pane, 0, 3);
		world.setBlock(x + 6, y + 7, z + 10, Blocks.glass_pane, 0, 3);
		world.setBlock(x + 7, y + 7, z + 10, Blocks.glass_pane, 0, 3);
		world.setBlock(x + 8, y + 7, z + 10, FaithCraft2.HolyCobbleStone, 0, 3);
		world.setBlock(x + 9, y + 7, z + 10, FaithCraft2.HolyStone, 0, 3);
		world.setBlock(x + 10, y + 7, z + 10, FaithCraft2.HolyStone, 0, 3);
		world.setBlock(x + 11, y + 7, z + 10, FaithCraft2.HolyStone, 0, 3);
		world.setBlock(x + 0, y + 8, z + 0, FaithCraft2.HolyStone, 0, 3);
		world.setBlock(x + 1, y + 8, z + 0, FaithCraft2.HolyStone, 0, 3);
		world.setBlock(x + 2, y + 8, z + 0, FaithCraft2.HolyStone, 0, 3);
		world.setBlock(x + 3, y + 8, z + 0, FaithCraft2.HolyStone, 0, 3);
		world.setBlock(x + 4, y + 8, z + 0, Blocks.glass_pane, 0, 3);
		world.setBlock(x + 5, y + 8, z + 0, Blocks.glass_pane, 0, 3);
		world.setBlock(x + 6, y + 8, z + 0, Blocks.glass_pane, 0, 3);
		world.setBlock(x + 7, y + 8, z + 0, Blocks.glass_pane, 0, 3);
		world.setBlock(x + 8, y + 8, z + 0, FaithCraft2.HolyStone, 0, 3);
		world.setBlock(x + 9, y + 8, z + 0, FaithCraft2.HolyStone, 0, 3);
		world.setBlock(x + 10, y + 8, z + 0, FaithCraft2.HolyStone, 0, 3);
		world.setBlock(x + 11, y + 8, z + 0, FaithCraft2.HolyStone, 0, 3);
		world.setBlock(x + 0, y + 8, z + 1, FaithCraft2.HolyStone, 0, 3);
		world.setBlock(x + 2, y + 8, z + 1, Blocks.stone_brick_stairs, 0, 3);
		world.setBlock(x + 3, y + 8, z + 1, FaithCraft2.HolyCobbleStone, 0, 3);
		world.setBlock(x + 8, y + 8, z + 1, FaithCraft2.HolyCobbleStone, 0, 3);
		world.setBlock(x + 9, y + 8, z + 1, Blocks.stone_brick_stairs, 1, 3);
		world.setBlock(x + 11, y + 8, z + 1, FaithCraft2.HolyStone, 0, 3);
		world.setBlock(x + 0, y + 8, z + 2, FaithCraft2.HolyStone, 0, 3);
		world.setBlock(x + 11, y + 8, z + 2, FaithCraft2.HolyStone, 0, 3);
		world.setBlock(x + 0, y + 8, z + 3, FaithCraft2.HolyStone, 0, 3);
		world.setBlock(x + 11, y + 8, z + 3, FaithCraft2.HolyStone, 0, 3);
		world.setBlock(x + 0, y + 8, z + 4, FaithCraft2.HolyStone, 0, 3);
		world.setBlock(x + 11, y + 8, z + 4, FaithCraft2.HolyStone, 0, 3);
		world.setBlock(x + 0, y + 8, z + 5, Blocks.glowstone, 0, 3);
		world.setBlock(x + 11, y + 8, z + 5, Blocks.glowstone, 0, 3);
		world.setBlock(x + 0, y + 8, z + 6, FaithCraft2.HolyStone, 0, 3);
		world.setBlock(x + 11, y + 8, z + 6, FaithCraft2.HolyStone, 0, 3);
		world.setBlock(x + 0, y + 8, z + 7, FaithCraft2.HolyStone, 0, 3);
		world.setBlock(x + 11, y + 8, z + 7, FaithCraft2.HolyStone, 0, 3);
		world.setBlock(x + 0, y + 8, z + 8, FaithCraft2.HolyStone, 0, 3);
		world.setBlock(x + 11, y + 8, z + 8, FaithCraft2.HolyStone, 0, 3);
		world.setBlock(x + 0, y + 8, z + 9, FaithCraft2.HolyStone, 0, 3);
		world.setBlock(x + 11, y + 8, z + 9, FaithCraft2.HolyStone, 0, 3);
		world.setBlock(x + 0, y + 8, z + 10, FaithCraft2.HolyStone, 0, 3);
		world.setBlock(x + 1, y + 8, z + 10, FaithCraft2.HolyStone, 0, 3);
		world.setBlock(x + 2, y + 8, z + 10, FaithCraft2.HolyStone, 0, 3);
		world.setBlock(x + 3, y + 8, z + 10, FaithCraft2.HolyCobbleStone, 0, 3);
		world.setBlock(x + 4, y + 8, z + 10, Blocks.glass_pane, 0, 3);
		world.setBlock(x + 5, y + 8, z + 10, Blocks.glass_pane, 0, 3);
		world.setBlock(x + 6, y + 8, z + 10, Blocks.glass_pane, 0, 3);
		world.setBlock(x + 7, y + 8, z + 10, Blocks.glass_pane, 0, 3);
		world.setBlock(x + 8, y + 8, z + 10, FaithCraft2.HolyCobbleStone, 0, 3);
		world.setBlock(x + 9, y + 8, z + 10, FaithCraft2.HolyStone, 0, 3);
		world.setBlock(x + 10, y + 8, z + 10, FaithCraft2.HolyStone, 0, 3);
		world.setBlock(x + 11, y + 8, z + 10, FaithCraft2.HolyStone, 0, 3);
		world.setBlock(x + 0, y + 9, z + 0, FaithCraft2.HolyStone, 0, 3);
		world.setBlock(x + 1, y + 9, z + 0, FaithCraft2.HolyStone, 0, 3);
		world.setBlock(x + 2, y + 9, z + 0, FaithCraft2.HolyStone, 0, 3);
		world.setBlock(x + 3, y + 9, z + 0, FaithCraft2.HolyStone, 0, 3);
		world.setBlock(x + 4, y + 9, z + 0, FaithCraft2.HolyStone, 0, 3);
		world.setBlock(x + 5, y + 9, z + 0, Blocks.glass_pane, 0, 3);
		world.setBlock(x + 6, y + 9, z + 0, Blocks.glass_pane, 0, 3);
		world.setBlock(x + 7, y + 9, z + 0, FaithCraft2.HolyStone, 0, 3);
		world.setBlock(x + 8, y + 9, z + 0, FaithCraft2.HolyStone, 0, 3);
		world.setBlock(x + 9, y + 9, z + 0, FaithCraft2.HolyStone, 0, 3);
		world.setBlock(x + 10, y + 9, z + 0, FaithCraft2.HolyStone, 0, 3);
		world.setBlock(x + 11, y + 9, z + 0, FaithCraft2.HolyStone, 0, 3);
		world.setBlock(x + 0, y + 9, z + 1, FaithCraft2.HolyStone, 0, 3);
		world.setBlock(x + 3, y + 9, z + 1, Blocks.stone_brick_stairs, 0, 3);
		world.setBlock(x + 4, y + 9, z + 1, FaithCraft2.HolyCobbleStone, 0, 3);
		world.setBlock(x + 7, y + 9, z + 1, FaithCraft2.HolyCobbleStone, 0, 3);
		world.setBlock(x + 8, y + 9, z + 1, Blocks.stone_brick_stairs, 1, 3);
		world.setBlock(x + 11, y + 9, z + 1, FaithCraft2.HolyStone, 0, 3);
		world.setBlock(x + 0, y + 9, z + 2, FaithCraft2.HolyStone, 0, 3);
		world.setBlock(x + 11, y + 9, z + 2, FaithCraft2.HolyStone, 0, 3);
		world.setBlock(x + 0, y + 9, z + 3, FaithCraft2.HolyStone, 0, 3);
		world.setBlock(x + 11, y + 9, z + 3, FaithCraft2.HolyStone, 0, 3);
		world.setBlock(x + 0, y + 9, z + 4, Blocks.glowstone, 0, 3);
		world.setBlock(x + 11, y + 9, z + 4, Blocks.glowstone, 0, 3);
		world.setBlock(x + 0, y + 9, z + 5, Blocks.glowstone, 0, 3);
		world.setBlock(x + 11, y + 9, z + 5, Blocks.glowstone, 0, 3);
		world.setBlock(x + 0, y + 9, z + 6, Blocks.glowstone, 0, 3);
		world.setBlock(x + 11, y + 9, z + 6, Blocks.glowstone, 0, 3);
		world.setBlock(x + 0, y + 9, z + 7, FaithCraft2.HolyStone, 0, 3);
		world.setBlock(x + 11, y + 9, z + 7, FaithCraft2.HolyStone, 0, 3);
		world.setBlock(x + 0, y + 9, z + 8, FaithCraft2.HolyStone, 0, 3);
		world.setBlock(x + 11, y + 9, z + 8, FaithCraft2.HolyStone, 0, 3);
		world.setBlock(x + 0, y + 9, z + 9, FaithCraft2.HolyStone, 0, 3);
		world.setBlock(x + 11, y + 9, z + 9, FaithCraft2.HolyStone, 0, 3);
		world.setBlock(x + 0, y + 9, z + 10, FaithCraft2.HolyStone, 0, 3);
		world.setBlock(x + 1, y + 9, z + 10, FaithCraft2.HolyStone, 0, 3);
		world.setBlock(x + 2, y + 9, z + 10, FaithCraft2.HolyStone, 0, 3);
		world.setBlock(x + 3, y + 9, z + 10, FaithCraft2.HolyCobbleStone, 0, 3);
		world.setBlock(x + 4, y + 9, z + 10, FaithCraft2.HolyStone, 0, 3);
		world.setBlock(x + 5, y + 9, z + 10, Blocks.glass_pane, 0, 3);
		world.setBlock(x + 6, y + 9, z + 10, Blocks.glass_pane, 0, 3);
		world.setBlock(x + 7, y + 9, z + 10, FaithCraft2.HolyStone, 0, 3);
		world.setBlock(x + 8, y + 9, z + 10, FaithCraft2.HolyCobbleStone, 0, 3);
		world.setBlock(x + 9, y + 9, z + 10, FaithCraft2.HolyStone, 0, 3);
		world.setBlock(x + 10, y + 9, z + 10, FaithCraft2.HolyStone, 0, 3);
		world.setBlock(x + 11, y + 9, z + 10, FaithCraft2.HolyStone, 0, 3);
		world.setBlock(x + 0, y + 10, z + 0, FaithCraft2.HolyStone, 0, 3);
		world.setBlock(x + 1, y + 10, z + 0, FaithCraft2.HolyStone, 0, 3);
		world.setBlock(x + 2, y + 10, z + 0, FaithCraft2.HolyStone, 0, 3);
		world.setBlock(x + 3, y + 10, z + 0, FaithCraft2.HolyStone, 0, 3);
		world.setBlock(x + 4, y + 10, z + 0, FaithCraft2.HolyStone, 0, 3);
		world.setBlock(x + 5, y + 10, z + 0, FaithCraft2.HolyStone, 0, 3);
		world.setBlock(x + 6, y + 10, z + 0, FaithCraft2.HolyStone, 0, 3);
		world.setBlock(x + 7, y + 10, z + 0, FaithCraft2.HolyStone, 0, 3);
		world.setBlock(x + 8, y + 10, z + 0, FaithCraft2.HolyStone, 0, 3);
		world.setBlock(x + 9, y + 10, z + 0, FaithCraft2.HolyStone, 0, 3);
		world.setBlock(x + 10, y + 10, z + 0, FaithCraft2.HolyStone, 0, 3);
		world.setBlock(x + 11, y + 10, z + 0, FaithCraft2.HolyStone, 0, 3);
		world.setBlock(x + 0, y + 10, z + 1, FaithCraft2.HolyStone, 0, 3);
		world.setBlock(x + 4, y + 10, z + 1, Blocks.stone_brick_stairs, 0, 3);
		world.setBlock(x + 5, y + 10, z + 1, FaithCraft2.HolyCobbleStone, 0, 3);
		world.setBlock(x + 6, y + 10, z + 1, FaithCraft2.HolyCobbleStone, 0, 3);
		world.setBlock(x + 7, y + 10, z + 1, Blocks.stone_brick_stairs, 1, 3);
		world.setBlock(x + 11, y + 10, z + 1, FaithCraft2.HolyStone, 0, 3);
		world.setBlock(x + 0, y + 10, z + 2, FaithCraft2.HolyStone, 0, 3);
		world.setBlock(x + 11, y + 10, z + 2, FaithCraft2.HolyStone, 0, 3);
		world.setBlock(x + 0, y + 10, z + 3, FaithCraft2.HolyStone, 0, 3);
		world.setBlock(x + 11, y + 10, z + 3, FaithCraft2.HolyStone, 0, 3);
		world.setBlock(x + 0, y + 10, z + 4, FaithCraft2.HolyStone, 0, 3);
		world.setBlock(x + 11, y + 10, z + 4, FaithCraft2.HolyStone, 0, 3);
		world.setBlock(x + 0, y + 10, z + 5, Blocks.glowstone, 0, 3);
		world.setBlock(x + 11, y + 10, z + 5, Blocks.glowstone, 0, 3);
		world.setBlock(x + 0, y + 10, z + 6, FaithCraft2.HolyStone, 0, 3);
		world.setBlock(x + 11, y + 10, z + 6, FaithCraft2.HolyStone, 0, 3);
		world.setBlock(x + 0, y + 10, z + 7, FaithCraft2.HolyStone, 0, 3);
		world.setBlock(x + 11, y + 10, z + 7, FaithCraft2.HolyStone, 0, 3);
		world.setBlock(x + 0, y + 10, z + 8, FaithCraft2.HolyStone, 0, 3);
		world.setBlock(x + 11, y + 10, z + 8, FaithCraft2.HolyStone, 0, 3);
		world.setBlock(x + 0, y + 10, z + 9, FaithCraft2.HolyStone, 0, 3);
		world.setBlock(x + 11, y + 10, z + 9, FaithCraft2.HolyStone, 0, 3);
		world.setBlock(x + 0, y + 10, z + 10, FaithCraft2.HolyCobbleStone, 0, 3);
		world.setBlock(x + 1, y + 10, z + 10, FaithCraft2.HolyCobbleStone, 0, 3);
		world.setBlock(x + 2, y + 10, z + 10, FaithCraft2.HolyCobbleStone, 0, 3);
		world.setBlock(x + 3, y + 10, z + 10, Blocks.glowstone, 0, 3);
		world.setBlock(x + 4, y + 10, z + 10, FaithCraft2.HolyCobbleStone, 0, 3);
		world.setBlock(x + 5, y + 10, z + 10, FaithCraft2.HolyCobbleStone, 0, 3);
		world.setBlock(x + 6, y + 10, z + 10, FaithCraft2.HolyCobbleStone, 0, 3);
		world.setBlock(x + 7, y + 10, z + 10, FaithCraft2.HolyCobbleStone, 0, 3);
		world.setBlock(x + 8, y + 10, z + 10, Blocks.glowstone, 0, 3);
		world.setBlock(x + 9, y + 10, z + 10, FaithCraft2.HolyCobbleStone, 0, 3);
		world.setBlock(x + 10, y + 10, z + 10, FaithCraft2.HolyCobbleStone, 0, 3);
		world.setBlock(x + 11, y + 10, z + 10, FaithCraft2.HolyCobbleStone, 0, 3);
		world.setBlock(x + 0, y + 11, z + 0, FaithCraft2.HolyStone, 0, 3);
		world.setBlock(x + 1, y + 11, z + 0, FaithCraft2.HolyStone, 0, 3);
		world.setBlock(x + 2, y + 11, z + 0, FaithCraft2.HolyStone, 0, 3);
		world.setBlock(x + 3, y + 11, z + 0, FaithCraft2.HolyStone, 0, 3);
		world.setBlock(x + 4, y + 11, z + 0, FaithCraft2.HolyStone, 0, 3);
		world.setBlock(x + 5, y + 11, z + 0, FaithCraft2.HolyStone, 0, 3);
		world.setBlock(x + 6, y + 11, z + 0, FaithCraft2.HolyStone, 0, 3);
		world.setBlock(x + 7, y + 11, z + 0, FaithCraft2.HolyStone, 0, 3);
		world.setBlock(x + 8, y + 11, z + 0, FaithCraft2.HolyStone, 0, 3);
		world.setBlock(x + 9, y + 11, z + 0, FaithCraft2.HolyStone, 0, 3);
		world.setBlock(x + 10, y + 11, z + 0, FaithCraft2.HolyStone, 0, 3);
		world.setBlock(x + 11, y + 11, z + 0, FaithCraft2.HolyStone, 0, 3);
		world.setBlock(x + 0, y + 11, z + 1, FaithCraft2.HolyStone, 0, 3);
		world.setBlock(x + 1, y + 11, z + 1, FaithCraft2.HolyStone, 0, 3);
		world.setBlock(x + 5, y + 11, z + 1, Blocks.stone_brick_stairs, 0, 3);
		world.setBlock(x + 6, y + 11, z + 1, Blocks.stone_brick_stairs, 1, 3);
		world.setBlock(x + 10, y + 11, z + 1, FaithCraft2.HolyStone, 0, 3);
		world.setBlock(x + 11, y + 11, z + 1, FaithCraft2.HolyStone, 0, 3);
		world.setBlock(x + 0, y + 11, z + 2, FaithCraft2.HolyStone, 0, 3);
		world.setBlock(x + 1, y + 11, z + 2, FaithCraft2.HolyStone, 0, 3);
		world.setBlock(x + 2, y + 11, z + 2, FaithCraft2.HolyStone, 0, 3);
		world.setBlock(x + 3, y + 11, z + 2, FaithCraft2.HolyStone, 0, 3);
		world.setBlock(x + 4, y + 11, z + 2, FaithCraft2.HolyStone, 0, 3);
		world.setBlock(x + 5, y + 11, z + 2, FaithCraft2.HolyStone, 0, 3);
		world.setBlock(x + 6, y + 11, z + 2, FaithCraft2.HolyStone, 0, 3);
		world.setBlock(x + 7, y + 11, z + 2, FaithCraft2.HolyStone, 0, 3);
		world.setBlock(x + 8, y + 11, z + 2, FaithCraft2.HolyStone, 0, 3);
		world.setBlock(x + 9, y + 11, z + 2, FaithCraft2.HolyStone, 0, 3);
		world.setBlock(x + 10, y + 11, z + 2, FaithCraft2.HolyStone, 0, 3);
		world.setBlock(x + 11, y + 11, z + 2, FaithCraft2.HolyStone, 0, 3);
		world.setBlock(x + 0, y + 11, z + 3, FaithCraft2.HolyStone, 0, 3);
		world.setBlock(x + 1, y + 11, z + 3, FaithCraft2.HolyStone, 0, 3);
		world.setBlock(x + 2, y + 11, z + 3, FaithCraft2.HolyStone, 0, 3);
		world.setBlock(x + 3, y + 11, z + 3, FaithCraft2.HolyStone, 0, 3);
		world.setBlock(x + 4, y + 11, z + 3, FaithCraft2.HolyStone, 0, 3);
		world.setBlock(x + 5, y + 11, z + 3, FaithCraft2.HolyStone, 0, 3);
		world.setBlock(x + 6, y + 11, z + 3, FaithCraft2.HolyStone, 0, 3);
		world.setBlock(x + 7, y + 11, z + 3, FaithCraft2.HolyStone, 0, 3);
		world.setBlock(x + 8, y + 11, z + 3, FaithCraft2.HolyStone, 0, 3);
		world.setBlock(x + 9, y + 11, z + 3, FaithCraft2.HolyStone, 0, 3);
		world.setBlock(x + 10, y + 11, z + 3, FaithCraft2.HolyStone, 0, 3);
		world.setBlock(x + 11, y + 11, z + 3, FaithCraft2.HolyStone, 0, 3);
		world.setBlock(x + 0, y + 11, z + 4, FaithCraft2.HolyStone, 0, 3);
		world.setBlock(x + 1, y + 11, z + 4, FaithCraft2.HolyStone, 0, 3);
		world.setBlock(x + 2, y + 11, z + 4, FaithCraft2.HolyStone, 0, 3);
		world.setBlock(x + 3, y + 11, z + 4, FaithCraft2.HolyStone, 0, 3);
		world.setBlock(x + 4, y + 11, z + 4, FaithCraft2.HolyStone, 0, 3);
		world.setBlock(x + 5, y + 11, z + 4, FaithCraft2.HolyStone, 0, 3);
		world.setBlock(x + 6, y + 11, z + 4, FaithCraft2.HolyStone, 0, 3);
		world.setBlock(x + 7, y + 11, z + 4, FaithCraft2.HolyStone, 0, 3);
		world.setBlock(x + 8, y + 11, z + 4, FaithCraft2.HolyStone, 0, 3);
		world.setBlock(x + 9, y + 11, z + 4, FaithCraft2.HolyStone, 0, 3);
		world.setBlock(x + 10, y + 11, z + 4, FaithCraft2.HolyStone, 0, 3);
		world.setBlock(x + 11, y + 11, z + 4, FaithCraft2.HolyStone, 0, 3);
		world.setBlock(x + 0, y + 11, z + 5, FaithCraft2.HolyStone, 0, 3);
		world.setBlock(x + 1, y + 11, z + 5, FaithCraft2.HolyStone, 0, 3);
		world.setBlock(x + 2, y + 11, z + 5, FaithCraft2.HolyStone, 0, 3);
		world.setBlock(x + 3, y + 11, z + 5, FaithCraft2.HolyStone, 0, 3);
		world.setBlock(x + 4, y + 11, z + 5, FaithCraft2.HolyStone, 0, 3);
		world.setBlock(x + 5, y + 11, z + 5, FaithCraft2.HolyStone, 0, 3);
		world.setBlock(x + 6, y + 11, z + 5, FaithCraft2.HolyStone, 0, 3);
		world.setBlock(x + 7, y + 11, z + 5, FaithCraft2.HolyStone, 0, 3);
		world.setBlock(x + 8, y + 11, z + 5, FaithCraft2.HolyStone, 0, 3);
		world.setBlock(x + 9, y + 11, z + 5, FaithCraft2.HolyStone, 0, 3);
		world.setBlock(x + 10, y + 11, z + 5, FaithCraft2.HolyStone, 0, 3);
		world.setBlock(x + 11, y + 11, z + 5, FaithCraft2.HolyStone, 0, 3);
		world.setBlock(x + 0, y + 11, z + 6, FaithCraft2.HolyStone, 0, 3);
		world.setBlock(x + 1, y + 11, z + 6, FaithCraft2.HolyStone, 0, 3);
		world.setBlock(x + 2, y + 11, z + 6, FaithCraft2.HolyStone, 0, 3);
		world.setBlock(x + 3, y + 11, z + 6, FaithCraft2.HolyStone, 0, 3);
		world.setBlock(x + 4, y + 11, z + 6, FaithCraft2.HolyStone, 0, 3);
		world.setBlock(x + 5, y + 11, z + 6, FaithCraft2.HolyStone, 0, 3);
		world.setBlock(x + 6, y + 11, z + 6, FaithCraft2.HolyStone, 0, 3);
		world.setBlock(x + 7, y + 11, z + 6, FaithCraft2.HolyStone, 0, 3);
		world.setBlock(x + 8, y + 11, z + 6, FaithCraft2.HolyStone, 0, 3);
		world.setBlock(x + 9, y + 11, z + 6, FaithCraft2.HolyStone, 0, 3);
		world.setBlock(x + 10, y + 11, z + 6, FaithCraft2.HolyStone, 0, 3);
		world.setBlock(x + 11, y + 11, z + 6, FaithCraft2.HolyStone, 0, 3);
		world.setBlock(x + 0, y + 11, z + 7, FaithCraft2.HolyStone, 0, 3);
		world.setBlock(x + 1, y + 11, z + 7, FaithCraft2.HolyStone, 0, 3);
		world.setBlock(x + 2, y + 11, z + 7, FaithCraft2.HolyStone, 0, 3);
		world.setBlock(x + 3, y + 11, z + 7, FaithCraft2.HolyStone, 0, 3);
		world.setBlock(x + 4, y + 11, z + 7, FaithCraft2.HolyStone, 0, 3);
		world.setBlock(x + 5, y + 11, z + 7, FaithCraft2.HolyStone, 0, 3);
		world.setBlock(x + 6, y + 11, z + 7, FaithCraft2.HolyStone, 0, 3);
		world.setBlock(x + 7, y + 11, z + 7, FaithCraft2.HolyStone, 0, 3);
		world.setBlock(x + 8, y + 11, z + 7, FaithCraft2.HolyStone, 0, 3);
		world.setBlock(x + 9, y + 11, z + 7, FaithCraft2.HolyStone, 0, 3);
		world.setBlock(x + 10, y + 11, z + 7, FaithCraft2.HolyStone, 0, 3);
		world.setBlock(x + 11, y + 11, z + 7, FaithCraft2.HolyStone, 0, 3);
		world.setBlock(x + 0, y + 11, z + 8, FaithCraft2.HolyStone, 0, 3);
		world.setBlock(x + 1, y + 11, z + 8, FaithCraft2.HolyStone, 0, 3);
		world.setBlock(x + 2, y + 11, z + 8, FaithCraft2.HolyStone, 0, 3);
		world.setBlock(x + 3, y + 11, z + 8, FaithCraft2.HolyStone, 0, 3);
		world.setBlock(x + 4, y + 11, z + 8, FaithCraft2.HolyStone, 0, 3);
		world.setBlock(x + 5, y + 11, z + 8, FaithCraft2.HolyStone, 0, 3);
		world.setBlock(x + 6, y + 11, z + 8, FaithCraft2.HolyStone, 0, 3);
		world.setBlock(x + 7, y + 11, z + 8, FaithCraft2.HolyStone, 0, 3);
		world.setBlock(x + 8, y + 11, z + 8, FaithCraft2.HolyStone, 0, 3);
		world.setBlock(x + 9, y + 11, z + 8, FaithCraft2.HolyStone, 0, 3);
		world.setBlock(x + 10, y + 11, z + 8, FaithCraft2.HolyStone, 0, 3);
		world.setBlock(x + 11, y + 11, z + 8, FaithCraft2.HolyStone, 0, 3);
		world.setBlock(x + 0, y + 11, z + 9, FaithCraft2.HolyStone, 0, 3);
		world.setBlock(x + 1, y + 11, z + 9, FaithCraft2.HolyStone, 0, 3);
		world.setBlock(x + 2, y + 11, z + 9, FaithCraft2.HolyStone, 0, 3);
		world.setBlock(x + 3, y + 11, z + 9, FaithCraft2.HolyStone, 0, 3);
		world.setBlock(x + 4, y + 11, z + 9, FaithCraft2.HolyStone, 0, 3);
		world.setBlock(x + 5, y + 11, z + 9, FaithCraft2.HolyStone, 0, 3);
		world.setBlock(x + 6, y + 11, z + 9, FaithCraft2.HolyStone, 0, 3);
		world.setBlock(x + 7, y + 11, z + 9, FaithCraft2.HolyStone, 0, 3);
		world.setBlock(x + 8, y + 11, z + 9, FaithCraft2.HolyStone, 0, 3);
		world.setBlock(x + 9, y + 11, z + 9, FaithCraft2.HolyStone, 0, 3);
		world.setBlock(x + 10, y + 11, z + 9, FaithCraft2.HolyStone, 0, 3);
		world.setBlock(x + 11, y + 11, z + 9, FaithCraft2.HolyStone, 0, 3);
		world.setBlock(x + 0, y + 11, z + 10, FaithCraft2.HolyStone, 0, 3);
		world.setBlock(x + 1, y + 11, z + 10, FaithCraft2.HolyStone, 0, 3);
		world.setBlock(x + 2, y + 11, z + 10, FaithCraft2.HolyStone, 0, 3);
		world.setBlock(x + 3, y + 11, z + 10, FaithCraft2.HolyCobbleStone, 0, 3);
		world.setBlock(x + 4, y + 11, z + 10, FaithCraft2.HolyStone, 0, 3);
		world.setBlock(x + 5, y + 11, z + 10, FaithCraft2.HolyStone, 0, 3);
		world.setBlock(x + 6, y + 11, z + 10, FaithCraft2.HolyStone, 0, 3);
		world.setBlock(x + 7, y + 11, z + 10, FaithCraft2.HolyStone, 0, 3);
		world.setBlock(x + 8, y + 11, z + 10, FaithCraft2.HolyCobbleStone, 0, 3);
		world.setBlock(x + 9, y + 11, z + 10, FaithCraft2.HolyStone, 0, 3);
		world.setBlock(x + 10, y + 11, z + 10, FaithCraft2.HolyStone, 0, 3);
		world.setBlock(x + 11, y + 11, z + 10, FaithCraft2.HolyStone, 0, 3);
		world.setBlock(x + 2, y + 12, z + 0, Blocks.glass, 0, 3);
		world.setBlock(x + 3, y + 12, z + 0, Blocks.glass, 0, 3);
		world.setBlock(x + 4, y + 12, z + 0, Blocks.glass, 0, 3);
		world.setBlock(x + 5, y + 12, z + 0, Blocks.glass, 0, 3);
		world.setBlock(x + 6, y + 12, z + 0, Blocks.glass, 0, 3);
		world.setBlock(x + 7, y + 12, z + 0, Blocks.glass, 0, 3);
		world.setBlock(x + 8, y + 12, z + 0, Blocks.glass, 0, 3);
		world.setBlock(x + 9, y + 12, z + 0, Blocks.glass, 0, 3);
		world.setBlock(x + 1, y + 12, z + 1, Blocks.glass, 0, 3);
		world.setBlock(x + 10, y + 12, z + 1, Blocks.glass, 0, 3);
		world.setBlock(x + 2, y + 12, z + 2, Blocks.glass, 0, 3);
		world.setBlock(x + 9, y + 12, z + 2, Blocks.glass, 0, 3);
		world.setBlock(x + 3, y + 12, z + 3, Blocks.glass, 0, 3);
		world.setBlock(x + 8, y + 12, z + 3, Blocks.glass, 0, 3);
		world.setBlock(x + 4, y + 12, z + 4, Blocks.glass, 0, 3);
		world.setBlock(x + 5, y + 12, z + 4, Blocks.chest, 2, 3);
		world.setBlock(x + 6, y + 12, z + 4, Blocks.chest, 2, 3);
		world.setBlock(x + 7, y + 12, z + 4, Blocks.glass, 0, 3);
		world.setBlock(x + 5, y + 12, z + 5, Blocks.glass, 0, 3);
		world.setBlock(x + 6, y + 12, z + 5, Blocks.glass, 0, 3);
		world.setBlock(x + 3, y + 12, z + 10, FaithCraft2.HolyStone, 0, 3);
		world.setBlock(x + 8, y + 12, z + 10, FaithCraft2.HolyStone, 0, 3);
		world.setBlock(x + 2, y + 13, z + 0, Blocks.glass, 0, 3);
		world.setBlock(x + 3, y + 13, z + 0, Blocks.glass, 0, 3);
		world.setBlock(x + 4, y + 13, z + 0, Blocks.glass, 0, 3);
		world.setBlock(x + 5, y + 13, z + 0, Blocks.glass, 0, 3);
		world.setBlock(x + 6, y + 13, z + 0, Blocks.glass, 0, 3);
		world.setBlock(x + 7, y + 13, z + 0, Blocks.glass, 0, 3);
		world.setBlock(x + 8, y + 13, z + 0, Blocks.glass, 0, 3);
		world.setBlock(x + 9, y + 13, z + 0, Blocks.glass, 0, 3);
		world.setBlock(x + 1, y + 13, z + 1, Blocks.glass, 0, 3);
		world.setBlock(x + 10, y + 13, z + 1, Blocks.glass, 0, 3);
		world.setBlock(x + 2, y + 13, z + 2, Blocks.glass, 0, 3);
		world.setBlock(x + 9, y + 13, z + 2, Blocks.glass, 0, 3);
		world.setBlock(x + 3, y + 13, z + 3, Blocks.glass, 0, 3);
		world.setBlock(x + 8, y + 13, z + 3, Blocks.glass, 0, 3);
		world.setBlock(x + 4, y + 13, z + 4, Blocks.glowstone, 0, 3);
		world.setBlock(x + 7, y + 13, z + 4, Blocks.glowstone, 0, 3);
		world.setBlock(x + 5, y + 13, z + 5, Blocks.glass, 0, 3);
		world.setBlock(x + 6, y + 13, z + 5, Blocks.glass, 0, 3);
		world.setBlock(x + 2, y + 14, z + 0, Blocks.glass, 0, 3);
		world.setBlock(x + 3, y + 14, z + 0, Blocks.glass, 0, 3);
		world.setBlock(x + 4, y + 14, z + 0, Blocks.glass, 0, 3);
		world.setBlock(x + 5, y + 14, z + 0, Blocks.glass, 0, 3);
		world.setBlock(x + 6, y + 14, z + 0, Blocks.glass, 0, 3);
		world.setBlock(x + 7, y + 14, z + 0, Blocks.glass, 0, 3);
		world.setBlock(x + 8, y + 14, z + 0, Blocks.glass, 0, 3);
		world.setBlock(x + 9, y + 14, z + 0, Blocks.glass, 0, 3);
		world.setBlock(x + 1, y + 14, z + 1, Blocks.glass, 0, 3);
		world.setBlock(x + 10, y + 14, z + 1, Blocks.glass, 0, 3);
		world.setBlock(x + 2, y + 14, z + 2, Blocks.glass, 0, 3);
		world.setBlock(x + 9, y + 14, z + 2, Blocks.glass, 0, 3);
		world.setBlock(x + 3, y + 14, z + 3, Blocks.glass, 0, 3);
		world.setBlock(x + 8, y + 14, z + 3, Blocks.glass, 0, 3);
		world.setBlock(x + 4, y + 14, z + 4, Blocks.glass, 0, 3);
		world.setBlock(x + 7, y + 14, z + 4, Blocks.glass, 0, 3);
		world.setBlock(x + 5, y + 14, z + 5, Blocks.glass, 0, 3);
		world.setBlock(x + 6, y + 14, z + 5, Blocks.glass, 0, 3);
		world.setBlock(x + 2, y + 15, z + 1, Blocks.glass, 0, 3);
		world.setBlock(x + 3, y + 15, z + 1, Blocks.glass, 0, 3);
		world.setBlock(x + 4, y + 15, z + 1, Blocks.glass, 0, 3);
		world.setBlock(x + 5, y + 15, z + 1, Blocks.glass, 0, 3);
		world.setBlock(x + 6, y + 15, z + 1, Blocks.glass, 0, 3);
		world.setBlock(x + 7, y + 15, z + 1, Blocks.glass, 0, 3);
		world.setBlock(x + 8, y + 15, z + 1, Blocks.glass, 0, 3);
		world.setBlock(x + 9, y + 15, z + 1, Blocks.glass, 0, 3);
		world.setBlock(x + 3, y + 15, z + 2, Blocks.glass, 0, 3);
		world.setBlock(x + 4, y + 15, z + 2, Blocks.glass, 0, 3);
		world.setBlock(x + 5, y + 15, z + 2, Blocks.glass, 0, 3);
		world.setBlock(x + 6, y + 15, z + 2, Blocks.glass, 0, 3);
		world.setBlock(x + 7, y + 15, z + 2, Blocks.glass, 0, 3);
		world.setBlock(x + 8, y + 15, z + 2, Blocks.glass, 0, 3);
		world.setBlock(x + 4, y + 15, z + 3, Blocks.glass, 0, 3);
		world.setBlock(x + 5, y + 15, z + 3, Blocks.glass, 0, 3);
		world.setBlock(x + 6, y + 15, z + 3, Blocks.glass, 0, 3);
		world.setBlock(x + 7, y + 15, z + 3, Blocks.glass, 0, 3);
		world.setBlock(x + 5, y + 15, z + 4, Blocks.glass, 0, 3);
		world.setBlock(x + 6, y + 15, z + 4, Blocks.glass, 0, 3);
		world.setBlock(x + 4, y + 16, z + 1, FaithCraft2.HolyStone, 0, 3);
		world.setBlock(x + 5, y + 16, z + 1, FaithCraft2.HolyStone, 0, 3);
		world.setBlock(x + 6, y + 16, z + 1, FaithCraft2.HolyStone, 0, 3);
		world.setBlock(x + 7, y + 16, z + 1, FaithCraft2.HolyStone, 0, 3);
		world.setBlock(x + 4, y + 16, z + 2, FaithCraft2.HolyStone, 0, 3);
		world.setBlock(x + 7, y + 16, z + 2, FaithCraft2.HolyStone, 0, 3);
		world.setBlock(x + 4, y + 16, z + 3, FaithCraft2.HolyStone, 0, 3);
		world.setBlock(x + 5, y + 16, z + 3, FaithCraft2.HolyStone, 0, 3);
		world.setBlock(x + 6, y + 16, z + 3, FaithCraft2.HolyStone, 0, 3);
		world.setBlock(x + 7, y + 16, z + 3, FaithCraft2.HolyStone, 0, 3);
		world.setBlock(x + 4, y + 17, z + 1, FaithCraft2.HolyStone, 0, 3);
		world.setBlock(x + 5, y + 17, z + 1, FaithCraft2.HolyStone, 0, 3);
		world.setBlock(x + 6, y + 17, z + 1, FaithCraft2.HolyStone, 0, 3);
		world.setBlock(x + 7, y + 17, z + 1, FaithCraft2.HolyStone, 0, 3);
		world.setBlock(x + 4, y + 17, z + 2, FaithCraft2.HolyStone, 0, 3);
		world.setBlock(x + 7, y + 17, z + 2, FaithCraft2.HolyStone, 0, 3);
		world.setBlock(x + 4, y + 17, z + 3, FaithCraft2.HolyStone, 0, 3);
		world.setBlock(x + 5, y + 17, z + 3, Blocks.glass_pane, 0, 3);
		world.setBlock(x + 6, y + 17, z + 3, Blocks.glass_pane, 0, 3);
		world.setBlock(x + 7, y + 17, z + 3, FaithCraft2.HolyStone, 0, 3);
		world.setBlock(x + 4, y + 18, z + 1, FaithCraft2.HolyStone, 0, 3);
		world.setBlock(x + 5, y + 18, z + 1, FaithCraft2.HolyStone, 0, 3);
		world.setBlock(x + 6, y + 18, z + 1, FaithCraft2.HolyStone, 0, 3);
		world.setBlock(x + 7, y + 18, z + 1, FaithCraft2.HolyStone, 0, 3);
		world.setBlock(x + 4, y + 18, z + 2, FaithCraft2.HolyStone, 0, 3);
		world.setBlock(x + 7, y + 18, z + 2, FaithCraft2.HolyStone, 0, 3);
		world.setBlock(x + 4, y + 18, z + 3, FaithCraft2.HolyStone, 0, 3);
		world.setBlock(x + 5, y + 18, z + 3, Blocks.glass_pane, 0, 3);
		world.setBlock(x + 6, y + 18, z + 3, Blocks.glass_pane, 0, 3);
		world.setBlock(x + 7, y + 18, z + 3, FaithCraft2.HolyStone, 0, 3);
		world.setBlock(x + 4, y + 19, z + 1, FaithCraft2.HolyStone, 0, 3);
		world.setBlock(x + 5, y + 19, z + 1, FaithCraft2.HolyStone, 0, 3);
		world.setBlock(x + 6, y + 19, z + 1, FaithCraft2.HolyStone, 0, 3);
		world.setBlock(x + 7, y + 19, z + 1, FaithCraft2.HolyStone, 0, 3);
		world.setBlock(x + 4, y + 19, z + 2, FaithCraft2.HolyStone, 0, 3);
		world.setBlock(x + 7, y + 19, z + 2, FaithCraft2.HolyStone, 0, 3);
		world.setBlock(x + 4, y + 19, z + 3, FaithCraft2.HolyStone, 0, 3);
		world.setBlock(x + 5, y + 19, z + 3, Blocks.glass_pane, 0, 3);
		world.setBlock(x + 6, y + 19, z + 3, Blocks.glass_pane, 0, 3);
		world.setBlock(x + 7, y + 19, z + 3, FaithCraft2.HolyStone, 0, 3);
		world.setBlock(x + 4, y + 20, z + 1, FaithCraft2.HolyStone, 0, 3);
		world.setBlock(x + 5, y + 20, z + 1, FaithCraft2.HolyStone, 0, 3);
		world.setBlock(x + 6, y + 20, z + 1, FaithCraft2.HolyStone, 0, 3);
		world.setBlock(x + 7, y + 20, z + 1, FaithCraft2.HolyStone, 0, 3);
		world.setBlock(x + 4, y + 20, z + 2, FaithCraft2.HolyStone, 0, 3);
		world.setBlock(x + 7, y + 20, z + 2, FaithCraft2.HolyStone, 0, 3);
		world.setBlock(x + 4, y + 20, z + 3, FaithCraft2.HolyStone, 0, 3);
		world.setBlock(x + 5, y + 20, z + 3, FaithCraft2.HolyStone, 0, 3);
		world.setBlock(x + 6, y + 20, z + 3, FaithCraft2.HolyStone, 0, 3);
		world.setBlock(x + 7, y + 20, z + 3, FaithCraft2.HolyStone, 0, 3);
		world.setBlock(x + 4, y + 21, z + 1, Blocks.stone_brick_stairs, 0, 3);
		world.setBlock(x + 5, y + 21, z + 1, Blocks.stone_brick_stairs, 2, 3);
		world.setBlock(x + 6, y + 21, z + 1, Blocks.stone_brick_stairs, 2, 3);
		world.setBlock(x + 7, y + 21, z + 1, Blocks.stone_brick_stairs, 1, 3);
		world.setBlock(x + 4, y + 21, z + 2, Blocks.stone_brick_stairs, 0, 3);
		world.setBlock(x + 5, y + 21, z + 2, FaithCraft2.HolyStone, 0, 3);
		world.setBlock(x + 6, y + 21, z + 2, FaithCraft2.HolyStone, 0, 3);
		world.setBlock(x + 7, y + 21, z + 2, Blocks.stone_brick_stairs, 1, 3);
		world.setBlock(x + 4, y + 21, z + 3, Blocks.stone_brick_stairs, 0, 3);
		world.setBlock(x + 5, y + 21, z + 3, Blocks.stone_brick_stairs, 3, 3);
		world.setBlock(x + 6, y + 21, z + 3, Blocks.stone_brick_stairs, 3, 3);
		world.setBlock(x + 7, y + 21, z + 3, Blocks.stone_brick_stairs, 3, 3);
		world.setBlock(x + 5, y + 22, z + 2, Blocks.stonebrick, 1, 3);
		world.setBlock(x + 6, y + 22, z + 2, Blocks.stonebrick, 1, 3);
		world.setBlock(x + 5, y + 23, z + 2, Blocks.stonebrick, 1, 3);
		world.setBlock(x + 6, y + 23, z + 2, Blocks.stonebrick, 1, 3);
		world.setBlock(x + 5, y + 24, z + 2, Blocks.glowstone, 0, 3);
		world.setBlock(x + 6, y + 24, z + 2, Blocks.glowstone, 0, 3);
		world.setBlock(x + 5, y + 25, z + 2, Blocks.stone_slab, 0, 3);
		world.setBlock(x + 6, y + 25, z + 2, Blocks.stone_slab, 0, 3);
		}
	}

	@Override
	public boolean generate(World var1, Random var2, int var3, int var4,
			int var5) {
		return false;
	}
}