//Schematic to java Structure by jajo_11 | inspired by "MITHION'S .SCHEMATIC TO JAVA CONVERTING TOOL"

package FaithCraft2.Common.common.worldgen;

import java.util.Random;

import javafx.geometry.BoundingBox;
import cpw.mods.fml.common.IWorldGenerator;
import net.minecraft.block.Block;
import net.minecraft.block.material.Material;
import net.minecraft.init.Blocks;
import net.minecraft.init.Items;
import net.minecraft.item.Item;
import net.minecraft.item.ItemDoor;
import net.minecraft.item.ItemStack;
import net.minecraft.tileentity.TileEntity;
import net.minecraft.tileentity.TileEntityChest;
import net.minecraft.util.WeightedRandomChestContent;
import net.minecraft.world.World;
import net.minecraft.world.chunk.IChunkProvider;
import net.minecraft.world.gen.feature.WorldGenerator;
import net.minecraft.world.gen.structure.StructureBoundingBox;
import net.minecraftforge.common.ChestGenHooks;
import FaithCraft2.Common.common.FaithCraft2;
import FaithCraft2.Common.common.handler.ConfigHandler;

public class WorldGenChurch extends WorldGenerator implements IWorldGenerator
{

	protected Block[] GetValidSpawnBlocks()
	{
		return new Block[]
		{
			Blocks.grass,
			Blocks.dirt,
			FaithCraft2.HolyCobbleStone,
			FaithCraft2.HolyStone,
		};
	}

	public boolean LocationIsValidSpawn(World world, int x, int y, int z)
	{
		int distanceToAir = 0;
		Block checkBlock = world.getBlock(x, y, z);

		while (checkBlock != Blocks.air)
		{
			distanceToAir++;
			checkBlock = world.getBlock(x, y + distanceToAir, z);
		}

		if (distanceToAir > 1)
		{
			return false;
		}

		y += distanceToAir - 1;

		Block block = world.getBlock(x, y, z);
		Block blockAbove = world.getBlock(x, y + 1, z);
		Block blockBelow = world.getBlock(x, y - 1, z);

		for (Block i : GetValidSpawnBlocks())
		{
			if (blockAbove != Blocks.air)
			{
				return false;
			}
			if (block == i)
			{
				return true;
			}
			else if (block == Blocks.snow_layer && blockBelow == i)
			if (block.getMaterial() == Material.plants && blockBelow == i)
			{
				return true;
			}
		}
		return false;
	}

	public void generate(Random random, int chunkX, int chunkZ, World world, IChunkProvider chunkGenerator, IChunkProvider chunkProvider) {
		switch(world.provider.dimensionId)
		{
		case -1:
		generateNether(world, random, chunkX * 16, chunkZ * 16);
		break;
		case 0:
		generateSurface(world, random, chunkX * 16, chunkZ * 16);
		break;
		case 1:
		generateEnd(world, random, chunkX * 16, chunkZ * 16);
		break;
		}
	}
	
	private void generateEnd(World world, Random random, int i, int j) {
		// TODO Auto-generated method stub
		
	}

	private void generateNether(World world, Random random, int i, int j) {
		// TODO Auto-generated method stub
		
	}

	public void generateSurface(World world, Random rand, int x2, int z2)
	{

			int i = x2 + rand.nextInt(15);
			int k = z2 + rand.nextInt(15);

			int j = world.getHeightValue(i,k)-1;

			if((rand.nextInt(1000000)+1)<=500000){
			boolean place = true;

			for (int y = 0; y<27; y++)
			for (int z = 0; z<17; z++)
			for (int x = 0; x<12; x++)
			if(world.getBlock(i+x,j+y+1,k+z)!=Blocks.air)
			place = false;

			if(place){
		world.setBlock(i + 0, j + 0, k + 0, FaithCraft2.HolyStone, 0, 3);
		world.setBlock(i + 1, j + 0, k + 0, FaithCraft2.HolyStone, 0, 3);
		world.setBlock(i + 2, j + 0, k + 0, FaithCraft2.HolyStone, 0, 3);
		world.setBlock(i + 3, j + 0, k + 0, FaithCraft2.HolyStone, 0, 3);
		world.setBlock(i + 4, j + 0, k + 0, FaithCraft2.HolyStone, 0, 3);
		world.setBlock(i + 5, j + 0, k + 0, FaithCraft2.HolyStone, 0, 3);
		world.setBlock(i + 6, j + 0, k + 0, FaithCraft2.HolyStone, 0, 3);
		world.setBlock(i + 7, j + 0, k + 0, FaithCraft2.HolyStone, 0, 3);
		world.setBlock(i + 8, j + 0, k + 0, FaithCraft2.HolyStone, 0, 3);
		world.setBlock(i + 9, j + 0, k + 0, FaithCraft2.HolyStone, 0, 3);
		world.setBlock(i + 10, j + 0, k + 0, FaithCraft2.HolyStone, 0, 3);
		world.setBlock(i + 11, j + 0, k + 0, FaithCraft2.HolyStone, 0, 3);
		world.setBlock(i + 0, j + 0, k + 1, FaithCraft2.HolyStone, 0, 3);
		world.setBlock(i + 1, j + 0, k + 1, Blocks.glowstone, 0, 3);
		world.setBlock(i + 2, j + 0, k + 1, FaithCraft2.HolyStone, 0, 3);
		world.setBlock(i + 3, j + 0, k + 1, FaithCraft2.HolyStone, 0, 3);
		world.setBlock(i + 4, j + 0, k + 1, FaithCraft2.HolyStone, 0, 3);
		world.setBlock(i + 5, j + 0, k + 1, FaithCraft2.HolyStone, 0, 3);
		world.setBlock(i + 6, j + 0, k + 1, FaithCraft2.HolyStone, 0, 3);
		world.setBlock(i + 7, j + 0, k + 1, FaithCraft2.HolyStone, 0, 3);
		world.setBlock(i + 8, j + 0, k + 1, FaithCraft2.HolyStone, 0, 3);
		world.setBlock(i + 9, j + 0, k + 1, FaithCraft2.HolyStone, 0, 3);
		world.setBlock(i + 10, j + 0, k + 1, Blocks.glowstone, 0, 3);
		world.setBlock(i + 11, j + 0, k + 1, FaithCraft2.HolyStone, 0, 3);
		world.setBlock(i + 0, j + 0, k + 2, FaithCraft2.HolyStone, 0, 3);
		world.setBlock(i + 1, j + 0, k + 2, FaithCraft2.HolyStone, 0, 3);
		world.setBlock(i + 2, j + 0, k + 2, FaithCraft2.HolyStone, 0, 3);
		world.setBlock(i + 3, j + 0, k + 2, FaithCraft2.HolyStone, 0, 3);
		world.setBlock(i + 4, j + 0, k + 2, FaithCraft2.HolyStone, 0, 3);
		world.setBlock(i + 5, j + 0, k + 2, FaithCraft2.HolyStone, 0, 3);
		world.setBlock(i + 6, j + 0, k + 2, FaithCraft2.HolyStone, 0, 3);
		world.setBlock(i + 7, j + 0, k + 2, FaithCraft2.HolyStone, 0, 3);
		world.setBlock(i + 8, j + 0, k + 2, FaithCraft2.HolyStone, 0, 3);
		world.setBlock(i + 9, j + 0, k + 2, FaithCraft2.HolyStone, 0, 3);
		world.setBlock(i + 10, j + 0, k + 2, FaithCraft2.HolyStone, 0, 3);
		world.setBlock(i + 11, j + 0, k + 2, FaithCraft2.HolyStone, 0, 3);
		world.setBlock(i + 0, j + 0, k + 3, FaithCraft2.HolyStone, 0, 3);
		world.setBlock(i + 1, j + 0, k + 3, FaithCraft2.HolyStone, 0, 3);
		world.setBlock(i + 2, j + 0, k + 3, FaithCraft2.HolyStone, 0, 3);
		world.setBlock(i + 3, j + 0, k + 3, FaithCraft2.HolyStone, 0, 3);
		world.setBlock(i + 4, j + 0, k + 3, FaithCraft2.HolyStone, 0, 3);
		world.setBlock(i + 5, j + 0, k + 3, FaithCraft2.HolyStone, 0, 3);
		world.setBlock(i + 6, j + 0, k + 3, FaithCraft2.HolyStone, 0, 3);
		world.setBlock(i + 7, j + 0, k + 3, FaithCraft2.HolyStone, 0, 3);
		world.setBlock(i + 8, j + 0, k + 3, FaithCraft2.HolyStone, 0, 3);
		world.setBlock(i + 9, j + 0, k + 3, FaithCraft2.HolyStone, 0, 3);
		world.setBlock(i + 10, j + 0, k + 3, FaithCraft2.HolyStone, 0, 3);
		world.setBlock(i + 11, j + 0, k + 3, FaithCraft2.HolyStone, 0, 3);
		world.setBlock(i + 0, j + 0, k + 4, FaithCraft2.HolyStone, 0, 3);
		world.setBlock(i + 1, j + 0, k + 4, FaithCraft2.HolyStone, 0, 3);
		world.setBlock(i + 2, j + 0, k + 4, FaithCraft2.HolyStone, 0, 3);
		world.setBlock(i + 3, j + 0, k + 4, FaithCraft2.HolyStone, 0, 3);
		world.setBlock(i + 4, j + 0, k + 4, FaithCraft2.HolyStone, 0, 3);
		world.setBlock(i + 5, j + 0, k + 4, FaithCraft2.HolyStone, 0, 3);
		world.setBlock(i + 6, j + 0, k + 4, FaithCraft2.HolyStone, 0, 3);
		world.setBlock(i + 7, j + 0, k + 4, FaithCraft2.HolyStone, 0, 3);
		world.setBlock(i + 8, j + 0, k + 4, FaithCraft2.HolyStone, 0, 3);
		world.setBlock(i + 9, j + 0, k + 4, FaithCraft2.HolyStone, 0, 3);
		world.setBlock(i + 10, j + 0, k + 4, FaithCraft2.HolyStone, 0, 3);
		world.setBlock(i + 11, j + 0, k + 4, FaithCraft2.HolyStone, 0, 3);
		world.setBlock(i + 0, j + 0, k + 5, FaithCraft2.HolyStone, 0, 3);
		world.setBlock(i + 1, j + 0, k + 5, FaithCraft2.HolyStone, 0, 3);
		world.setBlock(i + 2, j + 0, k + 5, FaithCraft2.HolyStone, 0, 3);
		world.setBlock(i + 3, j + 0, k + 5, FaithCraft2.HolyStone, 0, 3);
		world.setBlock(i + 4, j + 0, k + 5, FaithCraft2.HolyStone, 0, 3);
		world.setBlock(i + 5, j + 0, k + 5, FaithCraft2.HolyStone, 0, 3);
		world.setBlock(i + 6, j + 0, k + 5, FaithCraft2.HolyStone, 0, 3);
		world.setBlock(i + 7, j + 0, k + 5, FaithCraft2.HolyStone, 0, 3);
		world.setBlock(i + 8, j + 0, k + 5, FaithCraft2.HolyStone, 0, 3);
		world.setBlock(i + 9, j + 0, k + 5, FaithCraft2.HolyStone, 0, 3);
		world.setBlock(i + 10, j + 0, k + 5, FaithCraft2.HolyStone, 0, 3);
		world.setBlock(i + 11, j + 0, k + 5, FaithCraft2.HolyStone, 0, 3);
		world.setBlock(i + 0, j + 0, k + 6, FaithCraft2.HolyStone, 0, 3);
		world.setBlock(i + 1, j + 0, k + 6, FaithCraft2.HolyStone, 0, 3);
		world.setBlock(i + 2, j + 0, k + 6, FaithCraft2.HolyStone, 0, 3);
		world.setBlock(i + 3, j + 0, k + 6, FaithCraft2.HolyStone, 0, 3);
		world.setBlock(i + 4, j + 0, k + 6, FaithCraft2.HolyStone, 0, 3);
		world.setBlock(i + 5, j + 0, k + 6, FaithCraft2.HolyStone, 0, 3);
		world.setBlock(i + 6, j + 0, k + 6, FaithCraft2.HolyStone, 0, 3);
		world.setBlock(i + 7, j + 0, k + 6, FaithCraft2.HolyStone, 0, 3);
		world.setBlock(i + 8, j + 0, k + 6, FaithCraft2.HolyStone, 0, 3);
		world.setBlock(i + 9, j + 0, k + 6, FaithCraft2.HolyStone, 0, 3);
		world.setBlock(i + 10, j + 0, k + 6, FaithCraft2.HolyStone, 0, 3);
		world.setBlock(i + 11, j + 0, k + 6, FaithCraft2.HolyStone, 0, 3);
		world.setBlock(i + 0, j + 0, k + 7, FaithCraft2.HolyStone, 0, 3);
		world.setBlock(i + 1, j + 0, k + 7, FaithCraft2.HolyStone, 0, 3);
		world.setBlock(i + 2, j + 0, k + 7, FaithCraft2.HolyStone, 0, 3);
		world.setBlock(i + 3, j + 0, k + 7, FaithCraft2.HolyStone, 0, 3);
		world.setBlock(i + 4, j + 0, k + 7, FaithCraft2.HolyStone, 0, 3);
		world.setBlock(i + 5, j + 0, k + 7, FaithCraft2.HolyStone, 0, 3);
		world.setBlock(i + 6, j + 0, k + 7, FaithCraft2.HolyStone, 0, 3);
		world.setBlock(i + 7, j + 0, k + 7, FaithCraft2.HolyStone, 0, 3);
		world.setBlock(i + 8, j + 0, k + 7, FaithCraft2.HolyStone, 0, 3);
		world.setBlock(i + 9, j + 0, k + 7, FaithCraft2.HolyStone, 0, 3);
		world.setBlock(i + 10, j + 0, k + 7, FaithCraft2.HolyStone, 0, 3);
		world.setBlock(i + 11, j + 0, k + 7, FaithCraft2.HolyStone, 0, 3);
		world.setBlock(i + 0, j + 0, k + 8, FaithCraft2.HolyStone, 0, 3);
		world.setBlock(i + 1, j + 0, k + 8, FaithCraft2.HolyStone, 0, 3);
		world.setBlock(i + 2, j + 0, k + 8, FaithCraft2.HolyStone, 0, 3);
		world.setBlock(i + 3, j + 0, k + 8, FaithCraft2.HolyStone, 0, 3);
		world.setBlock(i + 4, j + 0, k + 8, FaithCraft2.HolyStone, 0, 3);
		world.setBlock(i + 5, j + 0, k + 8, FaithCraft2.HolyStone, 0, 3);
		world.setBlock(i + 6, j + 0, k + 8, FaithCraft2.HolyStone, 0, 3);
		world.setBlock(i + 7, j + 0, k + 8, FaithCraft2.HolyStone, 0, 3);
		world.setBlock(i + 8, j + 0, k + 8, FaithCraft2.HolyStone, 0, 3);
		world.setBlock(i + 9, j + 0, k + 8, FaithCraft2.HolyStone, 0, 3);
		world.setBlock(i + 10, j + 0, k + 8, FaithCraft2.HolyStone, 0, 3);
		world.setBlock(i + 11, j + 0, k + 8, FaithCraft2.HolyStone, 0, 3);
		world.setBlock(i + 0, j + 0, k + 9, FaithCraft2.HolyStone, 0, 3);
		world.setBlock(i + 1, j + 0, k + 9, FaithCraft2.HolyStone, 0, 3);
		world.setBlock(i + 2, j + 0, k + 9, FaithCraft2.HolyStone, 0, 3);
		world.setBlock(i + 3, j + 0, k + 9, FaithCraft2.HolyStone, 0, 3);
		world.setBlock(i + 4, j + 0, k + 9, FaithCraft2.HolyStone, 0, 3);
		world.setBlock(i + 5, j + 0, k + 9, FaithCraft2.HolyStone, 0, 3);
		world.setBlock(i + 6, j + 0, k + 9, FaithCraft2.HolyStone, 0, 3);
		world.setBlock(i + 7, j + 0, k + 9, FaithCraft2.HolyStone, 0, 3);
		world.setBlock(i + 8, j + 0, k + 9, FaithCraft2.HolyStone, 0, 3);
		world.setBlock(i + 9, j + 0, k + 9, FaithCraft2.HolyStone, 0, 3);
		world.setBlock(i + 10, j + 0, k + 9, FaithCraft2.HolyStone, 0, 3);
		world.setBlock(i + 11, j + 0, k + 9, FaithCraft2.HolyStone, 0, 3);
		world.setBlock(i + 0, j + 0, k + 10, FaithCraft2.HolyStone, 0, 3);
		world.setBlock(i + 1, j + 0, k + 10, FaithCraft2.HolyStone, 0, 3);
		world.setBlock(i + 2, j + 0, k + 10, FaithCraft2.HolyStone, 0, 3);
		world.setBlock(i + 3, j + 0, k + 10, FaithCraft2.HolyStone, 0, 3);
		world.setBlock(i + 4, j + 0, k + 10, FaithCraft2.HolyStone, 0, 3);
		world.setBlock(i + 5, j + 0, k + 10, FaithCraft2.HolyStone, 0, 3);
		world.setBlock(i + 6, j + 0, k + 10, FaithCraft2.HolyStone, 0, 3);
		world.setBlock(i + 7, j + 0, k + 10, FaithCraft2.HolyStone, 0, 3);
		world.setBlock(i + 8, j + 0, k + 10, FaithCraft2.HolyStone, 0, 3);
		world.setBlock(i + 9, j + 0, k + 10, FaithCraft2.HolyStone, 0, 3);
		world.setBlock(i + 10, j + 0, k + 10, FaithCraft2.HolyStone, 0, 3);
		world.setBlock(i + 11, j + 0, k + 10, FaithCraft2.HolyStone, 0, 3);
		world.setBlock(i + 0, j + 0, k + 11, FaithCraft2.HolyStone, 0, 3);
		world.setBlock(i + 1, j + 0, k + 11, FaithCraft2.HolyStone, 0, 3);
		world.setBlock(i + 2, j + 0, k + 11, FaithCraft2.HolyStone, 0, 3);
		world.setBlock(i + 3, j + 0, k + 11, FaithCraft2.HolyStone, 0, 3);
		world.setBlock(i + 4, j + 0, k + 11, FaithCraft2.HolyStone, 0, 3);
		world.setBlock(i + 5, j + 0, k + 11, FaithCraft2.HolyStone, 0, 3);
		world.setBlock(i + 6, j + 0, k + 11, FaithCraft2.HolyStone, 0, 3);
		world.setBlock(i + 7, j + 0, k + 11, FaithCraft2.HolyStone, 0, 3);
		world.setBlock(i + 8, j + 0, k + 11, FaithCraft2.HolyStone, 0, 3);
		world.setBlock(i + 9, j + 0, k + 11, FaithCraft2.HolyStone, 0, 3);
		world.setBlock(i + 10, j + 0, k + 11, FaithCraft2.HolyStone, 0, 3);
		world.setBlock(i + 11, j + 0, k + 11, FaithCraft2.HolyStone, 0, 3);
		world.setBlock(i + 0, j + 0, k + 12, FaithCraft2.HolyStone, 0, 3);
		world.setBlock(i + 1, j + 0, k + 12, FaithCraft2.HolyStone, 0, 3);
		world.setBlock(i + 2, j + 0, k + 12, FaithCraft2.HolyStone, 0, 3);
		world.setBlock(i + 3, j + 0, k + 12, FaithCraft2.HolyStone, 0, 3);
		world.setBlock(i + 4, j + 0, k + 12, FaithCraft2.HolyStone, 0, 3);
		world.setBlock(i + 5, j + 0, k + 12, FaithCraft2.HolyStone, 0, 3);
		world.setBlock(i + 6, j + 0, k + 12, FaithCraft2.HolyStone, 0, 3);
		world.setBlock(i + 7, j + 0, k + 12, FaithCraft2.HolyStone, 0, 3);
		world.setBlock(i + 8, j + 0, k + 12, FaithCraft2.HolyStone, 0, 3);
		world.setBlock(i + 9, j + 0, k + 12, FaithCraft2.HolyStone, 0, 3);
		world.setBlock(i + 10, j + 0, k + 12, FaithCraft2.HolyStone, 0, 3);
		world.setBlock(i + 11, j + 0, k + 12, FaithCraft2.HolyStone, 0, 3);
		world.setBlock(i + 0, j + 0, k + 13, FaithCraft2.HolyStone, 0, 3);
		world.setBlock(i + 1, j + 0, k + 13, FaithCraft2.HolyStone, 0, 3);
		world.setBlock(i + 2, j + 0, k + 13, FaithCraft2.HolyStone, 0, 3);
		world.setBlock(i + 3, j + 0, k + 13, FaithCraft2.HolyStone, 0, 3);
		world.setBlock(i + 4, j + 0, k + 13, FaithCraft2.HolyStone, 0, 3);
		world.setBlock(i + 5, j + 0, k + 13, FaithCraft2.HolyStone, 0, 3);
		world.setBlock(i + 6, j + 0, k + 13, FaithCraft2.HolyStone, 0, 3);
		world.setBlock(i + 7, j + 0, k + 13, FaithCraft2.HolyStone, 0, 3);
		world.setBlock(i + 8, j + 0, k + 13, FaithCraft2.HolyStone, 0, 3);
		world.setBlock(i + 9, j + 0, k + 13, FaithCraft2.HolyStone, 0, 3);
		world.setBlock(i + 10, j + 0, k + 13, FaithCraft2.HolyStone, 0, 3);
		world.setBlock(i + 11, j + 0, k + 13, FaithCraft2.HolyStone, 0, 3);
		world.setBlock(i + 0, j + 0, k + 14, FaithCraft2.HolyStone, 0, 3);
		world.setBlock(i + 1, j + 0, k + 14, FaithCraft2.HolyStone, 0, 3);
		world.setBlock(i + 2, j + 0, k + 14, FaithCraft2.HolyStone, 0, 3);
		world.setBlock(i + 3, j + 0, k + 14, FaithCraft2.HolyStone, 0, 3);
		world.setBlock(i + 4, j + 0, k + 14, FaithCraft2.HolyStone, 0, 3);
		world.setBlock(i + 5, j + 0, k + 14, FaithCraft2.HolyStone, 0, 3);
		world.setBlock(i + 6, j + 0, k + 14, FaithCraft2.HolyStone, 0, 3);
		world.setBlock(i + 7, j + 0, k + 14, FaithCraft2.HolyStone, 0, 3);
		world.setBlock(i + 8, j + 0, k + 14, FaithCraft2.HolyStone, 0, 3);
		world.setBlock(i + 9, j + 0, k + 14, FaithCraft2.HolyStone, 0, 3);
		world.setBlock(i + 10, j + 0, k + 14, FaithCraft2.HolyStone, 0, 3);
		world.setBlock(i + 11, j + 0, k + 14, FaithCraft2.HolyStone, 0, 3);
		world.setBlock(i + 0, j + 0, k + 15, FaithCraft2.HolyStone, 0, 3);
		world.setBlock(i + 1, j + 0, k + 15, FaithCraft2.HolyStone, 0, 3);
		world.setBlock(i + 2, j + 0, k + 15, FaithCraft2.HolyStone, 0, 3);
		world.setBlock(i + 3, j + 0, k + 15, FaithCraft2.HolyStone, 0, 3);
		world.setBlock(i + 4, j + 0, k + 15, FaithCraft2.HolyStone, 0, 3);
		world.setBlock(i + 5, j + 0, k + 15, FaithCraft2.HolyStone, 0, 3);
		world.setBlock(i + 6, j + 0, k + 15, FaithCraft2.HolyStone, 0, 3);
		world.setBlock(i + 7, j + 0, k + 15, FaithCraft2.HolyStone, 0, 3);
		world.setBlock(i + 8, j + 0, k + 15, FaithCraft2.HolyStone, 0, 3);
		world.setBlock(i + 9, j + 0, k + 15, FaithCraft2.HolyStone, 0, 3);
		world.setBlock(i + 10, j + 0, k + 15, FaithCraft2.HolyStone, 0, 3);
		world.setBlock(i + 11, j + 0, k + 15, FaithCraft2.HolyStone, 0, 3);
		world.setBlock(i + 0, j + 0, k + 16, Blocks.stone_slab, 0, 3);
		world.setBlock(i + 1, j + 0, k + 16, Blocks.stone_slab, 0, 3);
		world.setBlock(i + 2, j + 0, k + 16, Blocks.stone_slab, 0, 3);
		world.setBlock(i + 3, j + 0, k + 16, Blocks.stone_slab, 0, 3);
		world.setBlock(i + 4, j + 0, k + 16, Blocks.stone_slab, 0, 3);
		world.setBlock(i + 5, j + 0, k + 16, Blocks.stone_slab, 0, 3);
		world.setBlock(i + 6, j + 0, k + 16, Blocks.stone_slab, 0, 3);
		world.setBlock(i + 7, j + 0, k + 16, Blocks.stone_slab, 0, 3);
		world.setBlock(i + 8, j + 0, k + 16, Blocks.stone_slab, 0, 3);
		world.setBlock(i + 9, j + 0, k + 16, Blocks.stone_slab, 0, 3);
		world.setBlock(i + 10, j + 0, k + 16, Blocks.stone_slab, 0, 3);
		world.setBlock(i + 11, j + 0, k + 16, Blocks.stone_slab, 0, 3);
		world.setBlock(i + 0, j + 1, k + 0, FaithCraft2.HolyStone, 0, 3);
		world.setBlock(i + 1, j + 1, k + 0, FaithCraft2.HolyStone, 0, 3);
		world.setBlock(i + 2, j + 1, k + 0, FaithCraft2.HolyStone, 0, 3);
		world.setBlock(i + 3, j + 1, k + 0, FaithCraft2.HolyStone, 0, 3);
		world.setBlock(i + 4, j + 1, k + 0, FaithCraft2.HolyStone, 0, 3);
		world.setBlock(i + 5, j + 1, k + 0, FaithCraft2.HolyStone, 0, 3);
		world.setBlock(i + 6, j + 1, k + 0, FaithCraft2.HolyStone, 0, 3);
		world.setBlock(i + 7, j + 1, k + 0, FaithCraft2.HolyStone, 0, 3);
		world.setBlock(i + 8, j + 1, k + 0, FaithCraft2.HolyStone, 0, 3);
		world.setBlock(i + 9, j + 1, k + 0, FaithCraft2.HolyStone, 0, 3);
		world.setBlock(i + 10, j + 1, k + 0, FaithCraft2.HolyStone, 0, 3);
		world.setBlock(i + 11, j + 1, k + 0, FaithCraft2.HolyStone, 0, 3);
		world.setBlock(i + 0, j + 1, k + 1, FaithCraft2.HolyStone, 0, 3);
		world.setBlock(i + 11, j + 1, k + 1, FaithCraft2.HolyStone, 0, 3);
		world.setBlock(i + 0, j + 1, k + 2, FaithCraft2.HolyStone, 0, 3);
		world.setBlock(i + 11, j + 1, k + 2, FaithCraft2.HolyStone, 0, 3);
		world.setBlock(i + 0, j + 1, k + 3, FaithCraft2.HolyStone, 0, 3);
		world.setBlock(i + 11, j + 1, k + 3, FaithCraft2.HolyStone, 0, 3);
		world.setBlock(i + 0, j + 1, k + 4, FaithCraft2.HolyStone, 0, 3);
		world.setBlock(i + 11, j + 1, k + 4, FaithCraft2.HolyStone, 0, 3);
		world.setBlock(i + 0, j + 1, k + 5, FaithCraft2.HolyStone, 0, 3);
		world.setBlock(i + 11, j + 1, k + 5, FaithCraft2.HolyStone, 0, 3);
		world.setBlock(i + 0, j + 1, k + 6, FaithCraft2.HolyStone, 0, 3);
		world.setBlock(i + 11, j + 1, k + 6, FaithCraft2.HolyStone, 0, 3);
		world.setBlock(i + 0, j + 1, k + 7, FaithCraft2.HolyStone, 0, 3);
		world.setBlock(i + 11, j + 1, k + 7, FaithCraft2.HolyStone, 0, 3);
		world.setBlock(i + 0, j + 1, k + 8, FaithCraft2.HolyStone, 0, 3);
		world.setBlock(i + 2, j + 1, k + 8, FaithCraft2.HolyCobbleStone, 0, 3);
		world.setBlock(i + 9, j + 1, k + 8, FaithCraft2.HolyCobbleStone, 0, 3);
		world.setBlock(i + 11, j + 1, k + 8, FaithCraft2.HolyStone, 0, 3);
		world.setBlock(i + 0, j + 1, k + 9, FaithCraft2.HolyStone, 0, 3);
		world.setBlock(i + 3, j + 1, k + 9, Blocks.stone_brick_stairs, 1, 3);
		world.setBlock(i + 5, j + 1, k + 9, Blocks.stone_pressure_plate, 0, 3);
		world.setBlock(i + 6, j + 1, k + 9, Blocks.stone_pressure_plate, 0, 3);
		world.setBlock(i + 8, j + 1, k + 9, Blocks.stone_brick_stairs, 0, 3);
		world.setBlock(i + 11, j + 1, k + 9, FaithCraft2.HolyStone, 0, 3);
		world.setBlock(i + 0, j + 1, k + 10, FaithCraft2.HolyStone, 0, 3);
		world.setBlock(i + 1, j + 1, k + 10, FaithCraft2.HolyStone, 0, 3);
		world.setBlock(i + 2, j + 1, k + 10, FaithCraft2.HolyStone, 0, 3);
		world.setBlock(i + 3, j + 1, k + 10, FaithCraft2.HolyCobbleStone, 0, 3);
		world.setBlock(i + 4, j + 1, k + 10, FaithCraft2.HolyStone, 0, 3);
		world.setBlock(i + 7, j + 1, k + 10, FaithCraft2.HolyStone, 0, 3);
		world.setBlock(i + 8, j + 1, k + 10, FaithCraft2.HolyCobbleStone, 0, 3);
		world.setBlock(i + 9, j + 1, k + 10, FaithCraft2.HolyStone, 0, 3);
		world.setBlock(i + 10, j + 1, k + 10, FaithCraft2.HolyStone, 0, 3);
		world.setBlock(i + 11, j + 1, k + 10, FaithCraft2.HolyStone, 0, 3);
		world.setBlock(i + 0, j + 1, k + 11, FaithCraft2.HolyStone, 0, 3);
		world.setBlock(i + 5, j + 1, k + 11, Blocks.stone_pressure_plate, 0, 3);
		world.setBlock(i + 6, j + 1, k + 11, Blocks.stone_pressure_plate, 0, 3);
		world.setBlock(i + 11, j + 1, k + 11, FaithCraft2.HolyStone, 0, 3);
		world.setBlock(i + 0, j + 1, k + 12, FaithCraft2.HolyStone, 0, 3);
		world.setBlock(i + 11, j + 1, k + 12, FaithCraft2.HolyStone, 0, 3);
		world.setBlock(i + 0, j + 1, k + 13, FaithCraft2.HolyStone, 0, 3);
		world.setBlock(i + 11, j + 1, k + 13, FaithCraft2.HolyStone, 0, 3);
		world.setBlock(i + 0, j + 2, k + 0, FaithCraft2.HolyStone, 0, 3);
		world.setBlock(i + 1, j + 2, k + 0, FaithCraft2.HolyStone, 0, 3);
		world.setBlock(i + 2, j + 2, k + 0, FaithCraft2.HolyStone, 0, 3);
		world.setBlock(i + 3, j + 2, k + 0, FaithCraft2.HolyStone, 0, 3);
		world.setBlock(i + 4, j + 2, k + 0, FaithCraft2.HolyStone, 0, 3);
		world.setBlock(i + 5, j + 2, k + 0, FaithCraft2.HolyStone, 0, 3);
		world.setBlock(i + 6, j + 2, k + 0, FaithCraft2.HolyStone, 0, 3);
		world.setBlock(i + 7, j + 2, k + 0, FaithCraft2.HolyStone, 0, 3);
		world.setBlock(i + 8, j + 2, k + 0, FaithCraft2.HolyStone, 0, 3);
		world.setBlock(i + 9, j + 2, k + 0, FaithCraft2.HolyStone, 0, 3);
		world.setBlock(i + 10, j + 2, k + 0, FaithCraft2.HolyStone, 0, 3);
		world.setBlock(i + 11, j + 2, k + 0, FaithCraft2.HolyStone, 0, 3);
		world.setBlock(i + 0, j + 2, k + 1, FaithCraft2.HolyStone, 0, 3);
		world.setBlock(i + 11, j + 2, k + 1, FaithCraft2.HolyStone, 0, 3);
		world.setBlock(i + 0, j + 2, k + 2, FaithCraft2.HolyStone, 0, 3);
		world.setBlock(i + 11, j + 2, k + 2, FaithCraft2.HolyStone, 0, 3);
		world.setBlock(i + 0, j + 2, k + 3, FaithCraft2.HolyStone, 0, 3);
		world.setBlock(i + 11, j + 2, k + 3, FaithCraft2.HolyStone, 0, 3);
		world.setBlock(i + 0, j + 2, k + 4, FaithCraft2.HolyStone, 0, 3);
		world.setBlock(i + 11, j + 2, k + 4, FaithCraft2.HolyStone, 0, 3);
		world.setBlock(i + 0, j + 2, k + 5, FaithCraft2.HolyStone, 0, 3);
		world.setBlock(i + 11, j + 2, k + 5, FaithCraft2.HolyStone, 0, 3);
		world.setBlock(i + 0, j + 2, k + 6, FaithCraft2.HolyStone, 0, 3);
		world.setBlock(i + 11, j + 2, k + 6, FaithCraft2.HolyStone, 0, 3);
		world.setBlock(i + 0, j + 2, k + 7, FaithCraft2.HolyStone, 0, 3);
		world.setBlock(i + 11, j + 2, k + 7, FaithCraft2.HolyStone, 0, 3);
		world.setBlock(i + 0, j + 2, k + 8, FaithCraft2.HolyStone, 0, 3);
		world.setBlock(i + 2, j + 2, k + 8, FaithCraft2.HolyCobbleStone, 0, 3);
		world.setBlock(i + 9, j + 2, k + 8, FaithCraft2.HolyCobbleStone, 0, 3);
		world.setBlock(i + 11, j + 2, k + 8, FaithCraft2.HolyStone, 0, 3);
		world.setBlock(i + 0, j + 2, k + 9, FaithCraft2.HolyStone, 0, 3);
		world.setBlock(i + 1, j + 2, k + 9, Blocks.stonebrick, 0, 3);
		world.setBlock(i + 2, j + 2, k + 9, Blocks.stone_brick_stairs, 1, 3);
		world.setBlock(i + 9, j + 2, k + 9, Blocks.stone_brick_stairs, 0, 3);
		world.setBlock(i + 10, j + 2, k + 9, Blocks.stonebrick, 0, 3);
		world.setBlock(i + 11, j + 2, k + 9, FaithCraft2.HolyStone, 0, 3);
		world.setBlock(i + 0, j + 2, k + 10, FaithCraft2.HolyStone, 0, 3);
		world.setBlock(i + 1, j + 2, k + 10, FaithCraft2.HolyStone, 0, 3);
		world.setBlock(i + 2, j + 2, k + 10, FaithCraft2.HolyStone, 0, 3);
		world.setBlock(i + 3, j + 2, k + 10, FaithCraft2.HolyCobbleStone, 0, 3);
		world.setBlock(i + 4, j + 2, k + 10, FaithCraft2.HolyStone, 0, 3);
		world.setBlock(i + 7, j + 2, k + 10, FaithCraft2.HolyStone, 0, 3);
		world.setBlock(i + 8, j + 2, k + 10, FaithCraft2.HolyCobbleStone, 0, 3);
		world.setBlock(i + 9, j + 2, k + 10, FaithCraft2.HolyStone, 0, 3);
		world.setBlock(i + 10, j + 2, k + 10, FaithCraft2.HolyStone, 0, 3);
		world.setBlock(i + 11, j + 2, k + 10, FaithCraft2.HolyStone, 0, 3);
		world.setBlock(i + 0, j + 2, k + 11, FaithCraft2.HolyStone, 0, 3);
		world.setBlock(i + 11, j + 2, k + 11, FaithCraft2.HolyStone, 0, 3);
		world.setBlock(i + 0, j + 2, k + 12, FaithCraft2.HolyStone, 0, 3);
		world.setBlock(i + 11, j + 2, k + 12, FaithCraft2.HolyStone, 0, 3);
		world.setBlock(i + 0, j + 3, k + 0, FaithCraft2.HolyStone, 0, 3);
		world.setBlock(i + 1, j + 3, k + 0, FaithCraft2.HolyStone, 0, 3);
		world.setBlock(i + 2, j + 3, k + 0, FaithCraft2.HolyStone, 0, 3);
		world.setBlock(i + 3, j + 3, k + 0, FaithCraft2.HolyStone, 0, 3);
		world.setBlock(i + 4, j + 3, k + 0, FaithCraft2.HolyStone, 0, 3);
		world.setBlock(i + 5, j + 3, k + 0, FaithCraft2.HolyStone, 0, 3);
		world.setBlock(i + 6, j + 3, k + 0, FaithCraft2.HolyStone, 0, 3);
		world.setBlock(i + 7, j + 3, k + 0, FaithCraft2.HolyStone, 0, 3);
		world.setBlock(i + 8, j + 3, k + 0, FaithCraft2.HolyStone, 0, 3);
		world.setBlock(i + 9, j + 3, k + 0, FaithCraft2.HolyStone, 0, 3);
		world.setBlock(i + 10, j + 3, k + 0, FaithCraft2.HolyStone, 0, 3);
		world.setBlock(i + 11, j + 3, k + 0, FaithCraft2.HolyStone, 0, 3);
		world.setBlock(i + 0, j + 3, k + 1, FaithCraft2.HolyStone, 0, 3);
		world.setBlock(i + 11, j + 3, k + 1, FaithCraft2.HolyStone, 0, 3);
		world.setBlock(i + 0, j + 3, k + 2, FaithCraft2.HolyStone, 0, 3);
		world.setBlock(i + 11, j + 3, k + 2, FaithCraft2.HolyStone, 0, 3);
		world.setBlock(i + 0, j + 3, k + 3, FaithCraft2.HolyStone, 0, 3);
		world.setBlock(i + 11, j + 3, k + 3, FaithCraft2.HolyStone, 0, 3);
		world.setBlock(i + 0, j + 3, k + 4, FaithCraft2.HolyStone, 0, 3);
		world.setBlock(i + 11, j + 3, k + 4, FaithCraft2.HolyStone, 0, 3);
		world.setBlock(i + 0, j + 3, k + 5, FaithCraft2.HolyStone, 0, 3);
		world.setBlock(i + 11, j + 3, k + 5, FaithCraft2.HolyStone, 0, 3);
		world.setBlock(i + 0, j + 3, k + 6, FaithCraft2.HolyStone, 0, 3);
		world.setBlock(i + 11, j + 3, k + 6, FaithCraft2.HolyStone, 0, 3);
		world.setBlock(i + 0, j + 3, k + 7, FaithCraft2.HolyStone, 0, 3);
		world.setBlock(i + 11, j + 3, k + 7, FaithCraft2.HolyStone, 0, 3);
		world.setBlock(i + 0, j + 3, k + 8, FaithCraft2.HolyStone, 0, 3);
		world.setBlock(i + 1, j + 3, k + 8, Blocks.stone_brick_stairs, 3, 3);
		world.setBlock(i + 2, j + 3, k + 8, FaithCraft2.HolyCobbleStone, 0, 3);
		world.setBlock(i + 9, j + 3, k + 8, FaithCraft2.HolyCobbleStone, 0, 3);
		world.setBlock(i + 10, j + 3, k + 8, Blocks.stone_brick_stairs, 3, 3);
		world.setBlock(i + 11, j + 3, k + 8, FaithCraft2.HolyStone, 0, 3);
		world.setBlock(i + 0, j + 3, k + 9, FaithCraft2.HolyStone, 0, 3);
		world.setBlock(i + 11, j + 3, k + 9, FaithCraft2.HolyStone, 0, 3);
		world.setBlock(i + 0, j + 3, k + 10, FaithCraft2.HolyCobbleStone, 0, 3);
		world.setBlock(i + 1, j + 3, k + 10, FaithCraft2.HolyCobbleStone, 0, 3);
		world.setBlock(i + 2, j + 3, k + 10, FaithCraft2.HolyCobbleStone, 0, 3);
		world.setBlock(i + 3, j + 3, k + 10, FaithCraft2.HolyCobbleStone, 0, 3);
		world.setBlock(i + 4, j + 3, k + 10, FaithCraft2.HolyCobbleStone, 0, 3);
		world.setBlock(i + 5, j + 3, k + 10, FaithCraft2.HolyCobbleStone, 0, 3);
		world.setBlock(i + 6, j + 3, k + 10, FaithCraft2.HolyCobbleStone, 0, 3);
		world.setBlock(i + 7, j + 3, k + 10, FaithCraft2.HolyCobbleStone, 0, 3);
		world.setBlock(i + 8, j + 3, k + 10, FaithCraft2.HolyCobbleStone, 0, 3);
		world.setBlock(i + 9, j + 3, k + 10, FaithCraft2.HolyCobbleStone, 0, 3);
		world.setBlock(i + 10, j + 3, k + 10, FaithCraft2.HolyCobbleStone, 0, 3);
		world.setBlock(i + 11, j + 3, k + 10, FaithCraft2.HolyCobbleStone, 0, 3);
		world.setBlock(i + 0, j + 3, k + 11, FaithCraft2.HolyStone, 0, 3);
		world.setBlock(i + 11, j + 3, k + 11, FaithCraft2.HolyStone, 0, 3);
		world.setBlock(i + 0, j + 4, k + 0, FaithCraft2.HolyStone, 0, 3);
		world.setBlock(i + 1, j + 4, k + 0, FaithCraft2.HolyStone, 0, 3);
		world.setBlock(i + 2, j + 4, k + 0, FaithCraft2.HolyStone, 0, 3);
		world.setBlock(i + 3, j + 4, k + 0, FaithCraft2.HolyStone, 0, 3);
		world.setBlock(i + 4, j + 4, k + 0, FaithCraft2.HolyStone, 0, 3);
		world.setBlock(i + 5, j + 4, k + 0, FaithCraft2.HolyStone, 0, 3);
		world.setBlock(i + 6, j + 4, k + 0, FaithCraft2.HolyStone, 0, 3);
		world.setBlock(i + 7, j + 4, k + 0, FaithCraft2.HolyStone, 0, 3);
		world.setBlock(i + 8, j + 4, k + 0, FaithCraft2.HolyStone, 0, 3);
		world.setBlock(i + 9, j + 4, k + 0, FaithCraft2.HolyStone, 0, 3);
		world.setBlock(i + 10, j + 4, k + 0, FaithCraft2.HolyStone, 0, 3);
		world.setBlock(i + 11, j + 4, k + 0, FaithCraft2.HolyStone, 0, 3);
		world.setBlock(i + 0, j + 4, k + 1, FaithCraft2.HolyStone, 0, 3);
		world.setBlock(i + 11, j + 4, k + 1, FaithCraft2.HolyStone, 0, 3);
		world.setBlock(i + 0, j + 4, k + 2, FaithCraft2.HolyStone, 0, 3);
		world.setBlock(i + 11, j + 4, k + 2, FaithCraft2.HolyStone, 0, 3);
		world.setBlock(i + 0, j + 4, k + 3, FaithCraft2.HolyStone, 0, 3);
		world.setBlock(i + 11, j + 4, k + 3, FaithCraft2.HolyStone, 0, 3);
		world.setBlock(i + 0, j + 4, k + 4, FaithCraft2.HolyStone, 0, 3);
		world.setBlock(i + 11, j + 4, k + 4, FaithCraft2.HolyStone, 0, 3);
		world.setBlock(i + 0, j + 4, k + 5, FaithCraft2.HolyStone, 0, 3);
		world.setBlock(i + 11, j + 4, k + 5, FaithCraft2.HolyStone, 0, 3);
		world.setBlock(i + 0, j + 4, k + 6, FaithCraft2.HolyStone, 0, 3);
		world.setBlock(i + 11, j + 4, k + 6, FaithCraft2.HolyStone, 0, 3);
		world.setBlock(i + 0, j + 4, k + 7, FaithCraft2.HolyStone, 0, 3);
		world.setBlock(i + 1, j + 4, k + 7, Blocks.stone_brick_stairs, 3, 3);
		world.setBlock(i + 2, j + 4, k + 7, FaithCraft2.HolyCobbleStone, 0, 3);
		world.setBlock(i + 9, j + 4, k + 7, FaithCraft2.HolyCobbleStone, 0, 3);
		world.setBlock(i + 10, j + 4, k + 7, Blocks.stone_brick_stairs, 3, 3);
		world.setBlock(i + 11, j + 4, k + 7, FaithCraft2.HolyStone, 0, 3);
		world.setBlock(i + 0, j + 4, k + 8, FaithCraft2.HolyStone, 0, 3);
		world.setBlock(i + 2, j + 4, k + 8, FaithCraft2.HolyCobbleStone, 0, 3);
		world.setBlock(i + 9, j + 4, k + 8, FaithCraft2.HolyCobbleStone, 0, 3);
		world.setBlock(i + 11, j + 4, k + 8, FaithCraft2.HolyStone, 0, 3);
		world.setBlock(i + 0, j + 4, k + 9, FaithCraft2.HolyStone, 0, 3);
		world.setBlock(i + 11, j + 4, k + 9, FaithCraft2.HolyStone, 0, 3);
		world.setBlock(i + 0, j + 4, k + 10, FaithCraft2.HolyStone, 0, 3);
		world.setBlock(i + 1, j + 4, k + 10, FaithCraft2.HolyStone, 0, 3);
		world.setBlock(i + 2, j + 4, k + 10, FaithCraft2.HolyStone, 0, 3);
		world.setBlock(i + 3, j + 4, k + 10, Blocks.glowstone, 0, 3);
		world.setBlock(i + 4, j + 4, k + 10, FaithCraft2.HolyStone, 0, 3);
		world.setBlock(i + 5, j + 4, k + 10, FaithCraft2.HolyStone, 0, 3);
		world.setBlock(i + 6, j + 4, k + 10, FaithCraft2.HolyStone, 0, 3);
		world.setBlock(i + 7, j + 4, k + 10, FaithCraft2.HolyStone, 0, 3);
		world.setBlock(i + 8, j + 4, k + 10, Blocks.glowstone, 0, 3);
		world.setBlock(i + 9, j + 4, k + 10, FaithCraft2.HolyStone, 0, 3);
		world.setBlock(i + 10, j + 4, k + 10, FaithCraft2.HolyStone, 0, 3);
		world.setBlock(i + 11, j + 4, k + 10, FaithCraft2.HolyStone, 0, 3);
		world.setBlock(i + 0, j + 5, k + 0, FaithCraft2.HolyStone, 0, 3);
		world.setBlock(i + 1, j + 5, k + 0, FaithCraft2.HolyStone, 0, 3);
		world.setBlock(i + 2, j + 5, k + 0, FaithCraft2.HolyStone, 0, 3);
		world.setBlock(i + 3, j + 5, k + 0, FaithCraft2.HolyStone, 0, 3);
		world.setBlock(i + 4, j + 5, k + 0, FaithCraft2.HolyStone, 0, 3);
		world.setBlock(i + 5, j + 5, k + 0, FaithCraft2.HolyStone, 0, 3);
		world.setBlock(i + 6, j + 5, k + 0, FaithCraft2.HolyStone, 0, 3);
		world.setBlock(i + 7, j + 5, k + 0, FaithCraft2.HolyStone, 0, 3);
		world.setBlock(i + 8, j + 5, k + 0, FaithCraft2.HolyStone, 0, 3);
		world.setBlock(i + 9, j + 5, k + 0, FaithCraft2.HolyStone, 0, 3);
		world.setBlock(i + 10, j + 5, k + 0, FaithCraft2.HolyStone, 0, 3);
		world.setBlock(i + 11, j + 5, k + 0, FaithCraft2.HolyStone, 0, 3);
		world.setBlock(i + 0, j + 5, k + 1, FaithCraft2.HolyStone, 0, 3);
		world.setBlock(i + 1, j + 5, k + 1, FaithCraft2.HolyStone, 0, 3);
		world.setBlock(i + 2, j + 5, k + 1, FaithCraft2.HolyStone, 0, 3);
		world.setBlock(i + 3, j + 5, k + 1, FaithCraft2.HolyStone, 0, 3);
		world.setBlock(i + 4, j + 5, k + 1, Blocks.glowstone, 0, 3);
		world.setBlock(i + 5, j + 5, k + 1, Blocks.glowstone, 0, 3);
		world.setBlock(i + 6, j + 5, k + 1, Blocks.glowstone, 0, 3);
		world.setBlock(i + 7, j + 5, k + 1, Blocks.glowstone, 0, 3);
		world.setBlock(i + 8, j + 5, k + 1, FaithCraft2.HolyStone, 0, 3);
		world.setBlock(i + 9, j + 5, k + 1, FaithCraft2.HolyStone, 0, 3);
		world.setBlock(i + 10, j + 5, k + 1, FaithCraft2.HolyStone, 0, 3);
		world.setBlock(i + 11, j + 5, k + 1, FaithCraft2.HolyStone, 0, 3);
		world.setBlock(i + 0, j + 5, k + 2, FaithCraft2.HolyStone, 0, 3);
		world.setBlock(i + 1, j + 5, k + 2, FaithCraft2.HolyStone, 0, 3);
		world.setBlock(i + 2, j + 5, k + 2, FaithCraft2.HolyStone, 0, 3);
		world.setBlock(i + 3, j + 5, k + 2, FaithCraft2.HolyStone, 0, 3);
		world.setBlock(i + 4, j + 5, k + 2, FaithCraft2.HolyStone, 0, 3);
		world.setBlock(i + 5, j + 5, k + 2, FaithCraft2.HolyStone, 0, 3);
		world.setBlock(i + 6, j + 5, k + 2, FaithCraft2.HolyStone, 0, 3);
		world.setBlock(i + 7, j + 5, k + 2, FaithCraft2.HolyStone, 0, 3);
		world.setBlock(i + 8, j + 5, k + 2, FaithCraft2.HolyStone, 0, 3);
		world.setBlock(i + 9, j + 5, k + 2, FaithCraft2.HolyStone, 0, 3);
		world.setBlock(i + 10, j + 5, k + 2, FaithCraft2.HolyStone, 0, 3);
		world.setBlock(i + 11, j + 5, k + 2, FaithCraft2.HolyStone, 0, 3);
		world.setBlock(i + 0, j + 5, k + 3, FaithCraft2.HolyStone, 0, 3);
		world.setBlock(i + 1, j + 5, k + 3, FaithCraft2.HolyStone, 0, 3);
		world.setBlock(i + 2, j + 5, k + 3, FaithCraft2.HolyStone, 0, 3);
		world.setBlock(i + 3, j + 5, k + 3, FaithCraft2.HolyStone, 0, 3);
		world.setBlock(i + 4, j + 5, k + 3, FaithCraft2.HolyStone, 0, 3);
		world.setBlock(i + 5, j + 5, k + 3, FaithCraft2.HolyStone, 0, 3);
		world.setBlock(i + 6, j + 5, k + 3, FaithCraft2.HolyStone, 0, 3);
		world.setBlock(i + 7, j + 5, k + 3, FaithCraft2.HolyStone, 0, 3);
		world.setBlock(i + 8, j + 5, k + 3, FaithCraft2.HolyStone, 0, 3);
		world.setBlock(i + 9, j + 5, k + 3, FaithCraft2.HolyStone, 0, 3);
		world.setBlock(i + 10, j + 5, k + 3, FaithCraft2.HolyStone, 0, 3);
		world.setBlock(i + 11, j + 5, k + 3, FaithCraft2.HolyStone, 0, 3);
		world.setBlock(i + 0, j + 5, k + 4, FaithCraft2.HolyStone, 0, 3);
		world.setBlock(i + 1, j + 5, k + 4, FaithCraft2.HolyStone, 0, 3);
		world.setBlock(i + 2, j + 5, k + 4, FaithCraft2.HolyStone, 0, 3);
		world.setBlock(i + 3, j + 5, k + 4, FaithCraft2.HolyStone, 0, 3);
		world.setBlock(i + 4, j + 5, k + 4, FaithCraft2.HolyStone, 0, 3);
		world.setBlock(i + 5, j + 5, k + 4, FaithCraft2.HolyStone, 0, 3);
		world.setBlock(i + 6, j + 5, k + 4, FaithCraft2.HolyStone, 0, 3);
		world.setBlock(i + 7, j + 5, k + 4, FaithCraft2.HolyStone, 0, 3);
		world.setBlock(i + 8, j + 5, k + 4, FaithCraft2.HolyStone, 0, 3);
		world.setBlock(i + 9, j + 5, k + 4, FaithCraft2.HolyStone, 0, 3);
		world.setBlock(i + 10, j + 5, k + 4, FaithCraft2.HolyStone, 0, 3);
		world.setBlock(i + 11, j + 5, k + 4, FaithCraft2.HolyStone, 0, 3);
		world.setBlock(i + 0, j + 5, k + 5, FaithCraft2.HolyStone, 0, 3);
		world.setBlock(i + 1, j + 5, k + 5, FaithCraft2.HolyStone, 0, 3);
		world.setBlock(i + 2, j + 5, k + 5, FaithCraft2.HolyStone, 0, 3);
		world.setBlock(i + 3, j + 5, k + 5, FaithCraft2.HolyStone, 0, 3);
		world.setBlock(i + 4, j + 5, k + 5, FaithCraft2.HolyStone, 0, 3);
		world.setBlock(i + 5, j + 5, k + 5, FaithCraft2.HolyStone, 0, 3);
		world.setBlock(i + 6, j + 5, k + 5, FaithCraft2.HolyStone, 0, 3);
		world.setBlock(i + 7, j + 5, k + 5, FaithCraft2.HolyStone, 0, 3);
		world.setBlock(i + 8, j + 5, k + 5, FaithCraft2.HolyStone, 0, 3);
		world.setBlock(i + 9, j + 5, k + 5, FaithCraft2.HolyStone, 0, 3);
		world.setBlock(i + 10, j + 5, k + 5, FaithCraft2.HolyStone, 0, 3);
		world.setBlock(i + 11, j + 5, k + 5, FaithCraft2.HolyStone, 0, 3);
		world.setBlock(i + 0, j + 5, k + 6, FaithCraft2.HolyStone, 0, 3);
		world.setBlock(i + 1, j + 5, k + 6, Blocks.stone_brick_stairs, 3, 3);
		world.setBlock(i + 2, j + 5, k + 6, FaithCraft2.HolyStone, 0, 3);
		world.setBlock(i + 3, j + 5, k + 6, FaithCraft2.HolyStone, 0, 3);
		world.setBlock(i + 4, j + 5, k + 6, FaithCraft2.HolyStone, 0, 3);
		world.setBlock(i + 5, j + 5, k + 6, FaithCraft2.HolyStone, 0, 3);
		world.setBlock(i + 6, j + 5, k + 6, FaithCraft2.HolyStone, 0, 3);
		world.setBlock(i + 7, j + 5, k + 6, FaithCraft2.HolyStone, 0, 3);
		world.setBlock(i + 8, j + 5, k + 6, FaithCraft2.HolyStone, 0, 3);
		world.setBlock(i + 9, j + 5, k + 6, FaithCraft2.HolyStone, 0, 3);
		world.setBlock(i + 10, j + 5, k + 6, Blocks.stone_brick_stairs, 3, 3);
		world.setBlock(i + 11, j + 5, k + 6, FaithCraft2.HolyStone, 0, 3);
		world.setBlock(i + 0, j + 5, k + 7, FaithCraft2.HolyStone, 0, 3);
		world.setBlock(i + 2, j + 5, k + 7, FaithCraft2.HolyStone, 0, 3);
		world.setBlock(i + 3, j + 5, k + 7, FaithCraft2.HolyStone, 0, 3);
		world.setBlock(i + 4, j + 5, k + 7, FaithCraft2.HolyStone, 0, 3);
		world.setBlock(i + 5, j + 5, k + 7, FaithCraft2.HolyStone, 0, 3);
		world.setBlock(i + 6, j + 5, k + 7, FaithCraft2.HolyStone, 0, 3);
		world.setBlock(i + 7, j + 5, k + 7, FaithCraft2.HolyStone, 0, 3);
		world.setBlock(i + 8, j + 5, k + 7, FaithCraft2.HolyStone, 0, 3);
		world.setBlock(i + 9, j + 5, k + 7, FaithCraft2.HolyStone, 0, 3);
		world.setBlock(i + 11, j + 5, k + 7, FaithCraft2.HolyStone, 0, 3);
		world.setBlock(i + 0, j + 5, k + 8, FaithCraft2.HolyStone, 0, 3);
		world.setBlock(i + 2, j + 5, k + 8, FaithCraft2.HolyStone, 0, 3);
		world.setBlock(i + 3, j + 5, k + 8, FaithCraft2.HolyStone, 0, 3);
		world.setBlock(i + 4, j + 5, k + 8, FaithCraft2.HolyStone, 0, 3);
		world.setBlock(i + 5, j + 5, k + 8, FaithCraft2.HolyStone, 0, 3);
		world.setBlock(i + 6, j + 5, k + 8, FaithCraft2.HolyStone, 0, 3);
		world.setBlock(i + 7, j + 5, k + 8, FaithCraft2.HolyStone, 0, 3);
		world.setBlock(i + 8, j + 5, k + 8, FaithCraft2.HolyStone, 0, 3);
		world.setBlock(i + 9, j + 5, k + 8, FaithCraft2.HolyStone, 0, 3);
		world.setBlock(i + 11, j + 5, k + 8, FaithCraft2.HolyStone, 0, 3);
		world.setBlock(i + 0, j + 5, k + 9, FaithCraft2.HolyStone, 0, 3);
		world.setBlock(i + 2, j + 5, k + 9, FaithCraft2.HolyStone, 0, 3);
		world.setBlock(i + 3, j + 5, k + 9, FaithCraft2.HolyStone, 0, 3);
		world.setBlock(i + 4, j + 5, k + 9, FaithCraft2.HolyStone, 0, 3);
		world.setBlock(i + 5, j + 5, k + 9, FaithCraft2.HolyStone, 0, 3);
		world.setBlock(i + 6, j + 5, k + 9, FaithCraft2.HolyStone, 0, 3);
		world.setBlock(i + 7, j + 5, k + 9, FaithCraft2.HolyStone, 0, 3);
		world.setBlock(i + 8, j + 5, k + 9, FaithCraft2.HolyStone, 0, 3);
		world.setBlock(i + 9, j + 5, k + 9, FaithCraft2.HolyStone, 0, 3);
		world.setBlock(i + 11, j + 5, k + 9, FaithCraft2.HolyStone, 0, 3);
		world.setBlock(i + 0, j + 5, k + 10, FaithCraft2.HolyStone, 0, 3);
		world.setBlock(i + 1, j + 5, k + 10, FaithCraft2.HolyStone, 0, 3);
		world.setBlock(i + 2, j + 5, k + 10, FaithCraft2.HolyStone, 0, 3);
		world.setBlock(i + 3, j + 5, k + 10, FaithCraft2.HolyCobbleStone, 0, 3);
		world.setBlock(i + 4, j + 5, k + 10, FaithCraft2.HolyStone, 0, 3);
		world.setBlock(i + 5, j + 5, k + 10, FaithCraft2.HolyStone, 0, 3);
		world.setBlock(i + 6, j + 5, k + 10, FaithCraft2.HolyStone, 0, 3);
		world.setBlock(i + 7, j + 5, k + 10, FaithCraft2.HolyStone, 0, 3);
		world.setBlock(i + 8, j + 5, k + 10, FaithCraft2.HolyCobbleStone, 0, 3);
		world.setBlock(i + 9, j + 5, k + 10, FaithCraft2.HolyStone, 0, 3);
		world.setBlock(i + 10, j + 5, k + 10, FaithCraft2.HolyStone, 0, 3);
		world.setBlock(i + 11, j + 5, k + 10, FaithCraft2.HolyStone, 0, 3);
		world.setBlock(i + 0, j + 6, k + 0, FaithCraft2.HolyStone, 0, 3);
		world.setBlock(i + 1, j + 6, k + 0, FaithCraft2.HolyStone, 0, 3);
		world.setBlock(i + 2, j + 6, k + 0, FaithCraft2.HolyStone, 0, 3);
		world.setBlock(i + 3, j + 6, k + 0, FaithCraft2.HolyStone, 0, 3);
		world.setBlock(i + 4, j + 6, k + 0, FaithCraft2.HolyStone, 0, 3);
		world.setBlock(i + 5, j + 6, k + 0, FaithCraft2.HolyStone, 0, 3);
		world.setBlock(i + 6, j + 6, k + 0, FaithCraft2.HolyStone, 0, 3);
		world.setBlock(i + 7, j + 6, k + 0, FaithCraft2.HolyStone, 0, 3);
		world.setBlock(i + 8, j + 6, k + 0, FaithCraft2.HolyStone, 0, 3);
		world.setBlock(i + 9, j + 6, k + 0, FaithCraft2.HolyStone, 0, 3);
		world.setBlock(i + 10, j + 6, k + 0, FaithCraft2.HolyStone, 0, 3);
		world.setBlock(i + 11, j + 6, k + 0, FaithCraft2.HolyStone, 0, 3);
		world.setBlock(i + 0, j + 6, k + 1, FaithCraft2.HolyStone, 0, 3);
		world.setBlock(i + 1, j + 6, k + 1, FaithCraft2.HolyCobbleStone, 0, 3);
		world.setBlock(i + 2, j + 6, k + 1, FaithCraft2.HolyCobbleStone, 0, 3);
		world.setBlock(i + 5, j + 6, k + 1, FaithCraft2.Altar, 1, 3);
		world.setBlock(i + 6, j + 6, k + 1, FaithCraft2.Altar, 1, 3);
		world.setBlock(i + 9, j + 6, k + 1, FaithCraft2.HolyCobbleStone, 0, 3);
		world.setBlock(i + 10, j + 6, k + 1, FaithCraft2.HolyCobbleStone, 0, 3);
		world.setBlock(i + 11, j + 6, k + 1, FaithCraft2.HolyStone, 0, 3);
		world.setBlock(i + 0, j + 6, k + 2, FaithCraft2.HolyStone, 0, 3);
		world.setBlock(i + 1, j + 6, k + 2, FaithCraft2.HolyCobbleStone, 0, 3);
		world.setBlock(i + 10, j + 6, k + 2, FaithCraft2.HolyCobbleStone, 0, 3);
		world.setBlock(i + 11, j + 6, k + 2, FaithCraft2.HolyStone, 0, 3);
		world.setBlock(i + 0, j + 6, k + 3, FaithCraft2.HolyStone, 0, 3);
		world.setBlock(i + 1, j + 6, k + 3, Blocks.stone_brick_stairs, 3, 3);
		world.setBlock(i + 10, j + 6, k + 3, Blocks.stone_brick_stairs, 3, 3);
		world.setBlock(i + 11, j + 6, k + 3, FaithCraft2.HolyStone, 0, 3);
		world.setBlock(i + 0, j + 6, k + 4, FaithCraft2.HolyStone, 0, 3);
		world.setBlock(i + 11, j + 6, k + 4, FaithCraft2.HolyStone, 0, 3);
		world.setBlock(i + 0, j + 6, k + 5, FaithCraft2.HolyStone, 0, 3);
		world.setBlock(i + 11, j + 6, k + 5, FaithCraft2.HolyStone, 0, 3);
		world.setBlock(i + 0, j + 6, k + 6, FaithCraft2.HolyStone, 0, 3);
		world.setBlock(i + 11, j + 6, k + 6, FaithCraft2.HolyStone, 0, 3);
		world.setBlock(i + 0, j + 6, k + 7, FaithCraft2.HolyStone, 0, 3);
		world.setBlock(i + 11, j + 6, k + 7, FaithCraft2.HolyStone, 0, 3);
		world.setBlock(i + 0, j + 6, k + 8, FaithCraft2.HolyStone, 0, 3);
		world.setBlock(i + 11, j + 6, k + 8, FaithCraft2.HolyStone, 0, 3);
		world.setBlock(i + 0, j + 6, k + 9, FaithCraft2.HolyStone, 0, 3);
		world.setBlock(i + 11, j + 6, k + 9, FaithCraft2.HolyStone, 0, 3);
		world.setBlock(i + 0, j + 6, k + 10, FaithCraft2.HolyStone, 0, 3);
		world.setBlock(i + 1, j + 6, k + 10, FaithCraft2.HolyStone, 0, 3);
		world.setBlock(i + 2, j + 6, k + 10, FaithCraft2.HolyStone, 0, 3);
		world.setBlock(i + 3, j + 6, k + 10, FaithCraft2.HolyCobbleStone, 0, 3);
		world.setBlock(i + 4, j + 6, k + 10, FaithCraft2.HolyStone, 0, 3);
		world.setBlock(i + 5, j + 6, k + 10, Blocks.glass_pane, 0, 3);
		world.setBlock(i + 6, j + 6, k + 10, Blocks.glass_pane, 0, 3);
		world.setBlock(i + 7, j + 6, k + 10, FaithCraft2.HolyStone, 0, 3);
		world.setBlock(i + 8, j + 6, k + 10, FaithCraft2.HolyCobbleStone, 0, 3);
		world.setBlock(i + 9, j + 6, k + 10, FaithCraft2.HolyStone, 0, 3);
		world.setBlock(i + 10, j + 6, k + 10, FaithCraft2.HolyStone, 0, 3);
		world.setBlock(i + 11, j + 6, k + 10, FaithCraft2.HolyStone, 0, 3);
		world.setBlock(i + 0, j + 7, k + 0, FaithCraft2.HolyStone, 0, 3);
		world.setBlock(i + 1, j + 7, k + 0, FaithCraft2.HolyStone, 0, 3);
		world.setBlock(i + 2, j + 7, k + 0, FaithCraft2.HolyStone, 0, 3);
		world.setBlock(i + 3, j + 7, k + 0, Blocks.glass_pane, 0, 3);
		world.setBlock(i + 4, j + 7, k + 0, Blocks.glass_pane, 0, 3);
		world.setBlock(i + 5, j + 7, k + 0, Blocks.glass_pane, 0, 3);
		world.setBlock(i + 6, j + 7, k + 0, Blocks.glass_pane, 0, 3);
		world.setBlock(i + 7, j + 7, k + 0, Blocks.glass_pane, 0, 3);
		world.setBlock(i + 8, j + 7, k + 0, Blocks.glass_pane, 0, 3);
		world.setBlock(i + 9, j + 7, k + 0, FaithCraft2.HolyStone, 0, 3);
		world.setBlock(i + 10, j + 7, k + 0, FaithCraft2.HolyStone, 0, 3);
		world.setBlock(i + 11, j + 7, k + 0, FaithCraft2.HolyStone, 0, 3);
		world.setBlock(i + 0, j + 7, k + 1, FaithCraft2.HolyStone, 0, 3);
		world.setBlock(i + 1, j + 7, k + 1, Blocks.stonebrick, 0, 3);
		world.setBlock(i + 2, j + 7, k + 1, FaithCraft2.HolyCobbleStone, 0, 3);
		world.setBlock(i + 9, j + 7, k + 1, FaithCraft2.HolyCobbleStone, 0, 3);
		world.setBlock(i + 10, j + 7, k + 1, Blocks.stonebrick, 0, 3);
		world.setBlock(i + 11, j + 7, k + 1, FaithCraft2.HolyStone, 0, 3);
		world.setBlock(i + 0, j + 7, k + 2, FaithCraft2.HolyStone, 0, 3);
		world.setBlock(i + 1, j + 7, k + 2, Blocks.stone_brick_stairs, 3, 3);
		world.setBlock(i + 10, j + 7, k + 2, Blocks.stone_brick_stairs, 3, 3);
		world.setBlock(i + 11, j + 7, k + 2, FaithCraft2.HolyStone, 0, 3);
		world.setBlock(i + 0, j + 7, k + 3, FaithCraft2.HolyStone, 0, 3);
		world.setBlock(i + 11, j + 7, k + 3, FaithCraft2.HolyStone, 0, 3);
		world.setBlock(i + 0, j + 7, k + 4, FaithCraft2.HolyStone, 0, 3);
		world.setBlock(i + 11, j + 7, k + 4, FaithCraft2.HolyStone, 0, 3);
		world.setBlock(i + 0, j + 7, k + 5, Blocks.glowstone, 0, 3);
		world.setBlock(i + 11, j + 7, k + 5, Blocks.glowstone, 0, 3);
		world.setBlock(i + 0, j + 7, k + 6, FaithCraft2.HolyStone, 0, 3);
		world.setBlock(i + 11, j + 7, k + 6, FaithCraft2.HolyStone, 0, 3);
		world.setBlock(i + 0, j + 7, k + 7, FaithCraft2.HolyStone, 0, 3);
		world.setBlock(i + 11, j + 7, k + 7, FaithCraft2.HolyStone, 0, 3);
		world.setBlock(i + 0, j + 7, k + 8, FaithCraft2.HolyStone, 0, 3);
		world.setBlock(i + 11, j + 7, k + 8, FaithCraft2.HolyStone, 0, 3);
		world.setBlock(i + 0, j + 7, k + 9, FaithCraft2.HolyStone, 0, 3);
		world.setBlock(i + 11, j + 7, k + 9, FaithCraft2.HolyStone, 0, 3);
		world.setBlock(i + 0, j + 7, k + 10, FaithCraft2.HolyStone, 0, 3);
		world.setBlock(i + 1, j + 7, k + 10, FaithCraft2.HolyStone, 0, 3);
		world.setBlock(i + 2, j + 7, k + 10, FaithCraft2.HolyStone, 0, 3);
		world.setBlock(i + 3, j + 7, k + 10, FaithCraft2.HolyCobbleStone, 0, 3);
		world.setBlock(i + 4, j + 7, k + 10, Blocks.glass_pane, 0, 3);
		world.setBlock(i + 5, j + 7, k + 10, Blocks.glass_pane, 0, 3);
		world.setBlock(i + 6, j + 7, k + 10, Blocks.glass_pane, 0, 3);
		world.setBlock(i + 7, j + 7, k + 10, Blocks.glass_pane, 0, 3);
		world.setBlock(i + 8, j + 7, k + 10, FaithCraft2.HolyCobbleStone, 0, 3);
		world.setBlock(i + 9, j + 7, k + 10, FaithCraft2.HolyStone, 0, 3);
		world.setBlock(i + 10, j + 7, k + 10, FaithCraft2.HolyStone, 0, 3);
		world.setBlock(i + 11, j + 7, k + 10, FaithCraft2.HolyStone, 0, 3);
		world.setBlock(i + 0, j + 8, k + 0, FaithCraft2.HolyStone, 0, 3);
		world.setBlock(i + 1, j + 8, k + 0, FaithCraft2.HolyStone, 0, 3);
		world.setBlock(i + 2, j + 8, k + 0, FaithCraft2.HolyStone, 0, 3);
		world.setBlock(i + 3, j + 8, k + 0, FaithCraft2.HolyStone, 0, 3);
		world.setBlock(i + 4, j + 8, k + 0, Blocks.glass_pane, 0, 3);
		world.setBlock(i + 5, j + 8, k + 0, Blocks.glass_pane, 0, 3);
		world.setBlock(i + 6, j + 8, k + 0, Blocks.glass_pane, 0, 3);
		world.setBlock(i + 7, j + 8, k + 0, Blocks.glass_pane, 0, 3);
		world.setBlock(i + 8, j + 8, k + 0, FaithCraft2.HolyStone, 0, 3);
		world.setBlock(i + 9, j + 8, k + 0, FaithCraft2.HolyStone, 0, 3);
		world.setBlock(i + 10, j + 8, k + 0, FaithCraft2.HolyStone, 0, 3);
		world.setBlock(i + 11, j + 8, k + 0, FaithCraft2.HolyStone, 0, 3);
		world.setBlock(i + 0, j + 8, k + 1, FaithCraft2.HolyStone, 0, 3);
		world.setBlock(i + 2, j + 8, k + 1, Blocks.stone_brick_stairs, 0, 3);
		world.setBlock(i + 3, j + 8, k + 1, FaithCraft2.HolyCobbleStone, 0, 3);
		world.setBlock(i + 8, j + 8, k + 1, FaithCraft2.HolyCobbleStone, 0, 3);
		world.setBlock(i + 9, j + 8, k + 1, Blocks.stone_brick_stairs, 1, 3);
		world.setBlock(i + 11, j + 8, k + 1, FaithCraft2.HolyStone, 0, 3);
		world.setBlock(i + 0, j + 8, k + 2, FaithCraft2.HolyStone, 0, 3);
		world.setBlock(i + 11, j + 8, k + 2, FaithCraft2.HolyStone, 0, 3);
		world.setBlock(i + 0, j + 8, k + 3, FaithCraft2.HolyStone, 0, 3);
		world.setBlock(i + 11, j + 8, k + 3, FaithCraft2.HolyStone, 0, 3);
		world.setBlock(i + 0, j + 8, k + 4, FaithCraft2.HolyStone, 0, 3);
		world.setBlock(i + 11, j + 8, k + 4, FaithCraft2.HolyStone, 0, 3);
		world.setBlock(i + 0, j + 8, k + 5, Blocks.glowstone, 0, 3);
		world.setBlock(i + 11, j + 8, k + 5, Blocks.glowstone, 0, 3);
		world.setBlock(i + 0, j + 8, k + 6, FaithCraft2.HolyStone, 0, 3);
		world.setBlock(i + 11, j + 8, k + 6, FaithCraft2.HolyStone, 0, 3);
		world.setBlock(i + 0, j + 8, k + 7, FaithCraft2.HolyStone, 0, 3);
		world.setBlock(i + 11, j + 8, k + 7, FaithCraft2.HolyStone, 0, 3);
		world.setBlock(i + 0, j + 8, k + 8, FaithCraft2.HolyStone, 0, 3);
		world.setBlock(i + 11, j + 8, k + 8, FaithCraft2.HolyStone, 0, 3);
		world.setBlock(i + 0, j + 8, k + 9, FaithCraft2.HolyStone, 0, 3);
		world.setBlock(i + 11, j + 8, k + 9, FaithCraft2.HolyStone, 0, 3);
		world.setBlock(i + 0, j + 8, k + 10, FaithCraft2.HolyStone, 0, 3);
		world.setBlock(i + 1, j + 8, k + 10, FaithCraft2.HolyStone, 0, 3);
		world.setBlock(i + 2, j + 8, k + 10, FaithCraft2.HolyStone, 0, 3);
		world.setBlock(i + 3, j + 8, k + 10, FaithCraft2.HolyCobbleStone, 0, 3);
		world.setBlock(i + 4, j + 8, k + 10, Blocks.glass_pane, 0, 3);
		world.setBlock(i + 5, j + 8, k + 10, Blocks.glass_pane, 0, 3);
		world.setBlock(i + 6, j + 8, k + 10, Blocks.glass_pane, 0, 3);
		world.setBlock(i + 7, j + 8, k + 10, Blocks.glass_pane, 0, 3);
		world.setBlock(i + 8, j + 8, k + 10, FaithCraft2.HolyCobbleStone, 0, 3);
		world.setBlock(i + 9, j + 8, k + 10, FaithCraft2.HolyStone, 0, 3);
		world.setBlock(i + 10, j + 8, k + 10, FaithCraft2.HolyStone, 0, 3);
		world.setBlock(i + 11, j + 8, k + 10, FaithCraft2.HolyStone, 0, 3);
		world.setBlock(i + 0, j + 9, k + 0, FaithCraft2.HolyStone, 0, 3);
		world.setBlock(i + 1, j + 9, k + 0, FaithCraft2.HolyStone, 0, 3);
		world.setBlock(i + 2, j + 9, k + 0, FaithCraft2.HolyStone, 0, 3);
		world.setBlock(i + 3, j + 9, k + 0, FaithCraft2.HolyStone, 0, 3);
		world.setBlock(i + 4, j + 9, k + 0, FaithCraft2.HolyStone, 0, 3);
		world.setBlock(i + 5, j + 9, k + 0, Blocks.glass_pane, 0, 3);
		world.setBlock(i + 6, j + 9, k + 0, Blocks.glass_pane, 0, 3);
		world.setBlock(i + 7, j + 9, k + 0, FaithCraft2.HolyStone, 0, 3);
		world.setBlock(i + 8, j + 9, k + 0, FaithCraft2.HolyStone, 0, 3);
		world.setBlock(i + 9, j + 9, k + 0, FaithCraft2.HolyStone, 0, 3);
		world.setBlock(i + 10, j + 9, k + 0, FaithCraft2.HolyStone, 0, 3);
		world.setBlock(i + 11, j + 9, k + 0, FaithCraft2.HolyStone, 0, 3);
		world.setBlock(i + 0, j + 9, k + 1, FaithCraft2.HolyStone, 0, 3);
		world.setBlock(i + 3, j + 9, k + 1, Blocks.stone_brick_stairs, 0, 3);
		world.setBlock(i + 4, j + 9, k + 1, FaithCraft2.HolyCobbleStone, 0, 3);
		world.setBlock(i + 7, j + 9, k + 1, FaithCraft2.HolyCobbleStone, 0, 3);
		world.setBlock(i + 8, j + 9, k + 1, Blocks.stone_brick_stairs, 1, 3);
		world.setBlock(i + 11, j + 9, k + 1, FaithCraft2.HolyStone, 0, 3);
		world.setBlock(i + 0, j + 9, k + 2, FaithCraft2.HolyStone, 0, 3);
		world.setBlock(i + 11, j + 9, k + 2, FaithCraft2.HolyStone, 0, 3);
		world.setBlock(i + 0, j + 9, k + 3, FaithCraft2.HolyStone, 0, 3);
		world.setBlock(i + 11, j + 9, k + 3, FaithCraft2.HolyStone, 0, 3);
		world.setBlock(i + 0, j + 9, k + 4, Blocks.glowstone, 0, 3);
		world.setBlock(i + 11, j + 9, k + 4, Blocks.glowstone, 0, 3);
		world.setBlock(i + 0, j + 9, k + 5, Blocks.glowstone, 0, 3);
		world.setBlock(i + 11, j + 9, k + 5, Blocks.glowstone, 0, 3);
		world.setBlock(i + 0, j + 9, k + 6, Blocks.glowstone, 0, 3);
		world.setBlock(i + 11, j + 9, k + 6, Blocks.glowstone, 0, 3);
		world.setBlock(i + 0, j + 9, k + 7, FaithCraft2.HolyStone, 0, 3);
		world.setBlock(i + 11, j + 9, k + 7, FaithCraft2.HolyStone, 0, 3);
		world.setBlock(i + 0, j + 9, k + 8, FaithCraft2.HolyStone, 0, 3);
		world.setBlock(i + 11, j + 9, k + 8, FaithCraft2.HolyStone, 0, 3);
		world.setBlock(i + 0, j + 9, k + 9, FaithCraft2.HolyStone, 0, 3);
		world.setBlock(i + 11, j + 9, k + 9, FaithCraft2.HolyStone, 0, 3);
		world.setBlock(i + 0, j + 9, k + 10, FaithCraft2.HolyStone, 0, 3);
		world.setBlock(i + 1, j + 9, k + 10, FaithCraft2.HolyStone, 0, 3);
		world.setBlock(i + 2, j + 9, k + 10, FaithCraft2.HolyStone, 0, 3);
		world.setBlock(i + 3, j + 9, k + 10, FaithCraft2.HolyCobbleStone, 0, 3);
		world.setBlock(i + 4, j + 9, k + 10, FaithCraft2.HolyStone, 0, 3);
		world.setBlock(i + 5, j + 9, k + 10, Blocks.glass_pane, 0, 3);
		world.setBlock(i + 6, j + 9, k + 10, Blocks.glass_pane, 0, 3);
		world.setBlock(i + 7, j + 9, k + 10, FaithCraft2.HolyStone, 0, 3);
		world.setBlock(i + 8, j + 9, k + 10, FaithCraft2.HolyCobbleStone, 0, 3);
		world.setBlock(i + 9, j + 9, k + 10, FaithCraft2.HolyStone, 0, 3);
		world.setBlock(i + 10, j + 9, k + 10, FaithCraft2.HolyStone, 0, 3);
		world.setBlock(i + 11, j + 9, k + 10, FaithCraft2.HolyStone, 0, 3);
		world.setBlock(i + 0, j + 10, k + 0, FaithCraft2.HolyStone, 0, 3);
		world.setBlock(i + 1, j + 10, k + 0, FaithCraft2.HolyStone, 0, 3);
		world.setBlock(i + 2, j + 10, k + 0, FaithCraft2.HolyStone, 0, 3);
		world.setBlock(i + 3, j + 10, k + 0, FaithCraft2.HolyStone, 0, 3);
		world.setBlock(i + 4, j + 10, k + 0, FaithCraft2.HolyStone, 0, 3);
		world.setBlock(i + 5, j + 10, k + 0, FaithCraft2.HolyStone, 0, 3);
		world.setBlock(i + 6, j + 10, k + 0, FaithCraft2.HolyStone, 0, 3);
		world.setBlock(i + 7, j + 10, k + 0, FaithCraft2.HolyStone, 0, 3);
		world.setBlock(i + 8, j + 10, k + 0, FaithCraft2.HolyStone, 0, 3);
		world.setBlock(i + 9, j + 10, k + 0, FaithCraft2.HolyStone, 0, 3);
		world.setBlock(i + 10, j + 10, k + 0, FaithCraft2.HolyStone, 0, 3);
		world.setBlock(i + 11, j + 10, k + 0, FaithCraft2.HolyStone, 0, 3);
		world.setBlock(i + 0, j + 10, k + 1, FaithCraft2.HolyStone, 0, 3);
		world.setBlock(i + 4, j + 10, k + 1, Blocks.stone_brick_stairs, 0, 3);
		world.setBlock(i + 5, j + 10, k + 1, FaithCraft2.HolyCobbleStone, 0, 3);
		world.setBlock(i + 6, j + 10, k + 1, FaithCraft2.HolyCobbleStone, 0, 3);
		world.setBlock(i + 7, j + 10, k + 1, Blocks.stone_brick_stairs, 1, 3);
		world.setBlock(i + 11, j + 10, k + 1, FaithCraft2.HolyStone, 0, 3);
		world.setBlock(i + 0, j + 10, k + 2, FaithCraft2.HolyStone, 0, 3);
		world.setBlock(i + 11, j + 10, k + 2, FaithCraft2.HolyStone, 0, 3);
		world.setBlock(i + 0, j + 10, k + 3, FaithCraft2.HolyStone, 0, 3);
		world.setBlock(i + 11, j + 10, k + 3, FaithCraft2.HolyStone, 0, 3);
		world.setBlock(i + 0, j + 10, k + 4, FaithCraft2.HolyStone, 0, 3);
		world.setBlock(i + 11, j + 10, k + 4, FaithCraft2.HolyStone, 0, 3);
		world.setBlock(i + 0, j + 10, k + 5, Blocks.glowstone, 0, 3);
		world.setBlock(i + 11, j + 10, k + 5, Blocks.glowstone, 0, 3);
		world.setBlock(i + 0, j + 10, k + 6, FaithCraft2.HolyStone, 0, 3);
		world.setBlock(i + 11, j + 10, k + 6, FaithCraft2.HolyStone, 0, 3);
		world.setBlock(i + 0, j + 10, k + 7, FaithCraft2.HolyStone, 0, 3);
		world.setBlock(i + 11, j + 10, k + 7, FaithCraft2.HolyStone, 0, 3);
		world.setBlock(i + 0, j + 10, k + 8, FaithCraft2.HolyStone, 0, 3);
		world.setBlock(i + 11, j + 10, k + 8, FaithCraft2.HolyStone, 0, 3);
		world.setBlock(i + 0, j + 10, k + 9, FaithCraft2.HolyStone, 0, 3);
		world.setBlock(i + 11, j + 10, k + 9, FaithCraft2.HolyStone, 0, 3);
		world.setBlock(i + 0, j + 10, k + 10, FaithCraft2.HolyCobbleStone, 0, 3);
		world.setBlock(i + 1, j + 10, k + 10, FaithCraft2.HolyCobbleStone, 0, 3);
		world.setBlock(i + 2, j + 10, k + 10, FaithCraft2.HolyCobbleStone, 0, 3);
		world.setBlock(i + 3, j + 10, k + 10, Blocks.glowstone, 0, 3);
		world.setBlock(i + 4, j + 10, k + 10, FaithCraft2.HolyCobbleStone, 0, 3);
		world.setBlock(i + 5, j + 10, k + 10, FaithCraft2.HolyCobbleStone, 0, 3);
		world.setBlock(i + 6, j + 10, k + 10, FaithCraft2.HolyCobbleStone, 0, 3);
		world.setBlock(i + 7, j + 10, k + 10, FaithCraft2.HolyCobbleStone, 0, 3);
		world.setBlock(i + 8, j + 10, k + 10, Blocks.glowstone, 0, 3);
		world.setBlock(i + 9, j + 10, k + 10, FaithCraft2.HolyCobbleStone, 0, 3);
		world.setBlock(i + 10, j + 10, k + 10, FaithCraft2.HolyCobbleStone, 0, 3);
		world.setBlock(i + 11, j + 10, k + 10, FaithCraft2.HolyCobbleStone, 0, 3);
		world.setBlock(i + 0, j + 11, k + 0, FaithCraft2.HolyStone, 0, 3);
		world.setBlock(i + 1, j + 11, k + 0, FaithCraft2.HolyStone, 0, 3);
		world.setBlock(i + 2, j + 11, k + 0, FaithCraft2.HolyStone, 0, 3);
		world.setBlock(i + 3, j + 11, k + 0, FaithCraft2.HolyStone, 0, 3);
		world.setBlock(i + 4, j + 11, k + 0, FaithCraft2.HolyStone, 0, 3);
		world.setBlock(i + 5, j + 11, k + 0, FaithCraft2.HolyStone, 0, 3);
		world.setBlock(i + 6, j + 11, k + 0, FaithCraft2.HolyStone, 0, 3);
		world.setBlock(i + 7, j + 11, k + 0, FaithCraft2.HolyStone, 0, 3);
		world.setBlock(i + 8, j + 11, k + 0, FaithCraft2.HolyStone, 0, 3);
		world.setBlock(i + 9, j + 11, k + 0, FaithCraft2.HolyStone, 0, 3);
		world.setBlock(i + 10, j + 11, k + 0, FaithCraft2.HolyStone, 0, 3);
		world.setBlock(i + 11, j + 11, k + 0, FaithCraft2.HolyStone, 0, 3);
		world.setBlock(i + 0, j + 11, k + 1, FaithCraft2.HolyStone, 0, 3);
		world.setBlock(i + 1, j + 11, k + 1, FaithCraft2.HolyStone, 0, 3);
		world.setBlock(i + 5, j + 11, k + 1, Blocks.stone_brick_stairs, 0, 3);
		world.setBlock(i + 6, j + 11, k + 1, Blocks.stone_brick_stairs, 1, 3);
		world.setBlock(i + 10, j + 11, k + 1, FaithCraft2.HolyStone, 0, 3);
		world.setBlock(i + 11, j + 11, k + 1, FaithCraft2.HolyStone, 0, 3);
		world.setBlock(i + 0, j + 11, k + 2, FaithCraft2.HolyStone, 0, 3);
		world.setBlock(i + 1, j + 11, k + 2, FaithCraft2.HolyStone, 0, 3);
		world.setBlock(i + 2, j + 11, k + 2, FaithCraft2.HolyStone, 0, 3);
		world.setBlock(i + 3, j + 11, k + 2, FaithCraft2.HolyStone, 0, 3);
		world.setBlock(i + 4, j + 11, k + 2, FaithCraft2.HolyStone, 0, 3);
		world.setBlock(i + 5, j + 11, k + 2, FaithCraft2.HolyStone, 0, 3);
		world.setBlock(i + 6, j + 11, k + 2, FaithCraft2.HolyStone, 0, 3);
		world.setBlock(i + 7, j + 11, k + 2, FaithCraft2.HolyStone, 0, 3);
		world.setBlock(i + 8, j + 11, k + 2, FaithCraft2.HolyStone, 0, 3);
		world.setBlock(i + 9, j + 11, k + 2, FaithCraft2.HolyStone, 0, 3);
		world.setBlock(i + 10, j + 11, k + 2, FaithCraft2.HolyStone, 0, 3);
		world.setBlock(i + 11, j + 11, k + 2, FaithCraft2.HolyStone, 0, 3);
		world.setBlock(i + 0, j + 11, k + 3, FaithCraft2.HolyStone, 0, 3);
		world.setBlock(i + 1, j + 11, k + 3, FaithCraft2.HolyStone, 0, 3);
		world.setBlock(i + 2, j + 11, k + 3, FaithCraft2.HolyStone, 0, 3);
		world.setBlock(i + 3, j + 11, k + 3, FaithCraft2.HolyStone, 0, 3);
		world.setBlock(i + 4, j + 11, k + 3, FaithCraft2.HolyStone, 0, 3);
		world.setBlock(i + 5, j + 11, k + 3, FaithCraft2.HolyStone, 0, 3);
		world.setBlock(i + 6, j + 11, k + 3, FaithCraft2.HolyStone, 0, 3);
		world.setBlock(i + 7, j + 11, k + 3, FaithCraft2.HolyStone, 0, 3);
		world.setBlock(i + 8, j + 11, k + 3, FaithCraft2.HolyStone, 0, 3);
		world.setBlock(i + 9, j + 11, k + 3, FaithCraft2.HolyStone, 0, 3);
		world.setBlock(i + 10, j + 11, k + 3, FaithCraft2.HolyStone, 0, 3);
		world.setBlock(i + 11, j + 11, k + 3, FaithCraft2.HolyStone, 0, 3);
		world.setBlock(i + 0, j + 11, k + 4, FaithCraft2.HolyStone, 0, 3);
		world.setBlock(i + 1, j + 11, k + 4, FaithCraft2.HolyStone, 0, 3);
		world.setBlock(i + 2, j + 11, k + 4, FaithCraft2.HolyStone, 0, 3);
		world.setBlock(i + 3, j + 11, k + 4, FaithCraft2.HolyStone, 0, 3);
		world.setBlock(i + 4, j + 11, k + 4, FaithCraft2.HolyStone, 0, 3);
		world.setBlock(i + 5, j + 11, k + 4, FaithCraft2.HolyStone, 0, 3);
		world.setBlock(i + 6, j + 11, k + 4, FaithCraft2.HolyStone, 0, 3);
		world.setBlock(i + 7, j + 11, k + 4, FaithCraft2.HolyStone, 0, 3);
		world.setBlock(i + 8, j + 11, k + 4, FaithCraft2.HolyStone, 0, 3);
		world.setBlock(i + 9, j + 11, k + 4, FaithCraft2.HolyStone, 0, 3);
		world.setBlock(i + 10, j + 11, k + 4, FaithCraft2.HolyStone, 0, 3);
		world.setBlock(i + 11, j + 11, k + 4, FaithCraft2.HolyStone, 0, 3);
		world.setBlock(i + 0, j + 11, k + 5, FaithCraft2.HolyStone, 0, 3);
		world.setBlock(i + 1, j + 11, k + 5, FaithCraft2.HolyStone, 0, 3);
		world.setBlock(i + 2, j + 11, k + 5, FaithCraft2.HolyStone, 0, 3);
		world.setBlock(i + 3, j + 11, k + 5, FaithCraft2.HolyStone, 0, 3);
		world.setBlock(i + 4, j + 11, k + 5, FaithCraft2.HolyStone, 0, 3);
		world.setBlock(i + 5, j + 11, k + 5, FaithCraft2.HolyStone, 0, 3);
		world.setBlock(i + 6, j + 11, k + 5, FaithCraft2.HolyStone, 0, 3);
		world.setBlock(i + 7, j + 11, k + 5, FaithCraft2.HolyStone, 0, 3);
		world.setBlock(i + 8, j + 11, k + 5, FaithCraft2.HolyStone, 0, 3);
		world.setBlock(i + 9, j + 11, k + 5, FaithCraft2.HolyStone, 0, 3);
		world.setBlock(i + 10, j + 11, k + 5, FaithCraft2.HolyStone, 0, 3);
		world.setBlock(i + 11, j + 11, k + 5, FaithCraft2.HolyStone, 0, 3);
		world.setBlock(i + 0, j + 11, k + 6, FaithCraft2.HolyStone, 0, 3);
		world.setBlock(i + 1, j + 11, k + 6, FaithCraft2.HolyStone, 0, 3);
		world.setBlock(i + 2, j + 11, k + 6, FaithCraft2.HolyStone, 0, 3);
		world.setBlock(i + 3, j + 11, k + 6, FaithCraft2.HolyStone, 0, 3);
		world.setBlock(i + 4, j + 11, k + 6, FaithCraft2.HolyStone, 0, 3);
		world.setBlock(i + 5, j + 11, k + 6, FaithCraft2.HolyStone, 0, 3);
		world.setBlock(i + 6, j + 11, k + 6, FaithCraft2.HolyStone, 0, 3);
		world.setBlock(i + 7, j + 11, k + 6, FaithCraft2.HolyStone, 0, 3);
		world.setBlock(i + 8, j + 11, k + 6, FaithCraft2.HolyStone, 0, 3);
		world.setBlock(i + 9, j + 11, k + 6, FaithCraft2.HolyStone, 0, 3);
		world.setBlock(i + 10, j + 11, k + 6, FaithCraft2.HolyStone, 0, 3);
		world.setBlock(i + 11, j + 11, k + 6, FaithCraft2.HolyStone, 0, 3);
		world.setBlock(i + 0, j + 11, k + 7, FaithCraft2.HolyStone, 0, 3);
		world.setBlock(i + 1, j + 11, k + 7, FaithCraft2.HolyStone, 0, 3);
		world.setBlock(i + 2, j + 11, k + 7, FaithCraft2.HolyStone, 0, 3);
		world.setBlock(i + 3, j + 11, k + 7, FaithCraft2.HolyStone, 0, 3);
		world.setBlock(i + 4, j + 11, k + 7, FaithCraft2.HolyStone, 0, 3);
		world.setBlock(i + 5, j + 11, k + 7, FaithCraft2.HolyStone, 0, 3);
		world.setBlock(i + 6, j + 11, k + 7, FaithCraft2.HolyStone, 0, 3);
		world.setBlock(i + 7, j + 11, k + 7, FaithCraft2.HolyStone, 0, 3);
		world.setBlock(i + 8, j + 11, k + 7, FaithCraft2.HolyStone, 0, 3);
		world.setBlock(i + 9, j + 11, k + 7, FaithCraft2.HolyStone, 0, 3);
		world.setBlock(i + 10, j + 11, k + 7, FaithCraft2.HolyStone, 0, 3);
		world.setBlock(i + 11, j + 11, k + 7, FaithCraft2.HolyStone, 0, 3);
		world.setBlock(i + 0, j + 11, k + 8, FaithCraft2.HolyStone, 0, 3);
		world.setBlock(i + 1, j + 11, k + 8, FaithCraft2.HolyStone, 0, 3);
		world.setBlock(i + 2, j + 11, k + 8, FaithCraft2.HolyStone, 0, 3);
		world.setBlock(i + 3, j + 11, k + 8, FaithCraft2.HolyStone, 0, 3);
		world.setBlock(i + 4, j + 11, k + 8, FaithCraft2.HolyStone, 0, 3);
		world.setBlock(i + 5, j + 11, k + 8, FaithCraft2.HolyStone, 0, 3);
		world.setBlock(i + 6, j + 11, k + 8, FaithCraft2.HolyStone, 0, 3);
		world.setBlock(i + 7, j + 11, k + 8, FaithCraft2.HolyStone, 0, 3);
		world.setBlock(i + 8, j + 11, k + 8, FaithCraft2.HolyStone, 0, 3);
		world.setBlock(i + 9, j + 11, k + 8, FaithCraft2.HolyStone, 0, 3);
		world.setBlock(i + 10, j + 11, k + 8, FaithCraft2.HolyStone, 0, 3);
		world.setBlock(i + 11, j + 11, k + 8, FaithCraft2.HolyStone, 0, 3);
		world.setBlock(i + 0, j + 11, k + 9, FaithCraft2.HolyStone, 0, 3);
		world.setBlock(i + 1, j + 11, k + 9, FaithCraft2.HolyStone, 0, 3);
		world.setBlock(i + 2, j + 11, k + 9, FaithCraft2.HolyStone, 0, 3);
		world.setBlock(i + 3, j + 11, k + 9, FaithCraft2.HolyStone, 0, 3);
		world.setBlock(i + 4, j + 11, k + 9, FaithCraft2.HolyStone, 0, 3);
		world.setBlock(i + 5, j + 11, k + 9, FaithCraft2.HolyStone, 0, 3);
		world.setBlock(i + 6, j + 11, k + 9, FaithCraft2.HolyStone, 0, 3);
		world.setBlock(i + 7, j + 11, k + 9, FaithCraft2.HolyStone, 0, 3);
		world.setBlock(i + 8, j + 11, k + 9, FaithCraft2.HolyStone, 0, 3);
		world.setBlock(i + 9, j + 11, k + 9, FaithCraft2.HolyStone, 0, 3);
		world.setBlock(i + 10, j + 11, k + 9, FaithCraft2.HolyStone, 0, 3);
		world.setBlock(i + 11, j + 11, k + 9, FaithCraft2.HolyStone, 0, 3);
		world.setBlock(i + 0, j + 11, k + 10, FaithCraft2.HolyStone, 0, 3);
		world.setBlock(i + 1, j + 11, k + 10, FaithCraft2.HolyStone, 0, 3);
		world.setBlock(i + 2, j + 11, k + 10, FaithCraft2.HolyStone, 0, 3);
		world.setBlock(i + 3, j + 11, k + 10, FaithCraft2.HolyCobbleStone, 0, 3);
		world.setBlock(i + 4, j + 11, k + 10, FaithCraft2.HolyStone, 0, 3);
		world.setBlock(i + 5, j + 11, k + 10, FaithCraft2.HolyStone, 0, 3);
		world.setBlock(i + 6, j + 11, k + 10, FaithCraft2.HolyStone, 0, 3);
		world.setBlock(i + 7, j + 11, k + 10, FaithCraft2.HolyStone, 0, 3);
		world.setBlock(i + 8, j + 11, k + 10, FaithCraft2.HolyCobbleStone, 0, 3);
		world.setBlock(i + 9, j + 11, k + 10, FaithCraft2.HolyStone, 0, 3);
		world.setBlock(i + 10, j + 11, k + 10, FaithCraft2.HolyStone, 0, 3);
		world.setBlock(i + 11, j + 11, k + 10, FaithCraft2.HolyStone, 0, 3);
		world.setBlock(i + 2, j + 12, k + 0, Blocks.glass, 0, 3);
		world.setBlock(i + 3, j + 12, k + 0, Blocks.glass, 0, 3);
		world.setBlock(i + 4, j + 12, k + 0, Blocks.glass, 0, 3);
		world.setBlock(i + 5, j + 12, k + 0, Blocks.glass, 0, 3);
		world.setBlock(i + 6, j + 12, k + 0, Blocks.glass, 0, 3);
		world.setBlock(i + 7, j + 12, k + 0, Blocks.glass, 0, 3);
		world.setBlock(i + 8, j + 12, k + 0, Blocks.glass, 0, 3);
		world.setBlock(i + 9, j + 12, k + 0, Blocks.glass, 0, 3);
		world.setBlock(i + 1, j + 12, k + 1, Blocks.glass, 0, 3);
		world.setBlock(i + 10, j + 12, k + 1, Blocks.glass, 0, 3);
		world.setBlock(i + 2, j + 12, k + 2, Blocks.glass, 0, 3);
		world.setBlock(i + 9, j + 12, k + 2, Blocks.glass, 0, 3);
		world.setBlock(i + 3, j + 12, k + 3, Blocks.glass, 0, 3);
		world.setBlock(i + 8, j + 12, k + 3, Blocks.glass, 0, 3);
		world.setBlock(i + 4, j + 12, k + 4, Blocks.glass, 0, 3);
		world.setBlock(i + 5, j + 12, k + 4, Blocks.chest, 2, 3);
		world.setBlock(i + 6, j + 12, k + 4, Blocks.chest, 2, 3);
		TileEntityChest tileentitychest = (TileEntityChest)world.getTileEntity(i+6, j+12, k+4);
		 int l3 = 0;
		 do
		 {
			 if (l3 >= 20)
			 {
				 break;
			 }
			 ItemStack itemstack = pickCheckLootItem(rand);
			 if (itemstack != null)
			 {
				 tileentitychest.setInventorySlotContents(rand.nextInt(tileentitychest.getSizeInventory()), itemstack);
			 }
			 l3++;
		 }
		 while (true);
		 tileentitychest.setInventorySlotContents(7, new ItemStack(FaithCraft2.Cross));
		 tileentitychest.setInventorySlotContents(10, new ItemStack(Items.diamond));
		 tileentitychest.setInventorySlotContents(13, new ItemStack(FaithCraft2.HolyCross));
		world.setBlock(i + 7, j + 12, k + 4, Blocks.glass, 0, 3);
		world.setBlock(i + 5, j + 12, k + 5, Blocks.glass, 0, 3);
		world.setBlock(i + 6, j + 12, k + 5, Blocks.glass, 0, 3);
		world.setBlock(i + 3, j + 12, k + 10, FaithCraft2.HolyStone, 0, 3);
		world.setBlock(i + 8, j + 12, k + 10, FaithCraft2.HolyStone, 0, 3);
		world.setBlock(i + 2, j + 13, k + 0, Blocks.glass, 0, 3);
		world.setBlock(i + 3, j + 13, k + 0, Blocks.glass, 0, 3);
		world.setBlock(i + 4, j + 13, k + 0, Blocks.glass, 0, 3);
		world.setBlock(i + 5, j + 13, k + 0, Blocks.glass, 0, 3);
		world.setBlock(i + 6, j + 13, k + 0, Blocks.glass, 0, 3);
		world.setBlock(i + 7, j + 13, k + 0, Blocks.glass, 0, 3);
		world.setBlock(i + 8, j + 13, k + 0, Blocks.glass, 0, 3);
		world.setBlock(i + 9, j + 13, k + 0, Blocks.glass, 0, 3);
		world.setBlock(i + 1, j + 13, k + 1, Blocks.glass, 0, 3);
		world.setBlock(i + 10, j + 13, k + 1, Blocks.glass, 0, 3);
		world.setBlock(i + 2, j + 13, k + 2, Blocks.glass, 0, 3);
		world.setBlock(i + 9, j + 13, k + 2, Blocks.glass, 0, 3);
		world.setBlock(i + 3, j + 13, k + 3, Blocks.glass, 0, 3);
		world.setBlock(i + 8, j + 13, k + 3, Blocks.glass, 0, 3);
		world.setBlock(i + 4, j + 13, k + 4, Blocks.glowstone, 0, 3);
		world.setBlock(i + 7, j + 13, k + 4, Blocks.glowstone, 0, 3);
		world.setBlock(i + 5, j + 13, k + 5, Blocks.glass, 0, 3);
		world.setBlock(i + 6, j + 13, k + 5, Blocks.glass, 0, 3);
		world.setBlock(i + 2, j + 14, k + 0, Blocks.glass, 0, 3);
		world.setBlock(i + 3, j + 14, k + 0, Blocks.glass, 0, 3);
		world.setBlock(i + 4, j + 14, k + 0, Blocks.glass, 0, 3);
		world.setBlock(i + 5, j + 14, k + 0, Blocks.glass, 0, 3);
		world.setBlock(i + 6, j + 14, k + 0, Blocks.glass, 0, 3);
		world.setBlock(i + 7, j + 14, k + 0, Blocks.glass, 0, 3);
		world.setBlock(i + 8, j + 14, k + 0, Blocks.glass, 0, 3);
		world.setBlock(i + 9, j + 14, k + 0, Blocks.glass, 0, 3);
		world.setBlock(i + 1, j + 14, k + 1, Blocks.glass, 0, 3);
		world.setBlock(i + 10, j + 14, k + 1, Blocks.glass, 0, 3);
		world.setBlock(i + 2, j + 14, k + 2, Blocks.glass, 0, 3);
		world.setBlock(i + 9, j + 14, k + 2, Blocks.glass, 0, 3);
		world.setBlock(i + 3, j + 14, k + 3, Blocks.glass, 0, 3);
		world.setBlock(i + 8, j + 14, k + 3, Blocks.glass, 0, 3);
		world.setBlock(i + 4, j + 14, k + 4, Blocks.glass, 0, 3);
		world.setBlock(i + 7, j + 14, k + 4, Blocks.glass, 0, 3);
		world.setBlock(i + 5, j + 14, k + 5, Blocks.glass, 0, 3);
		world.setBlock(i + 6, j + 14, k + 5, Blocks.glass, 0, 3);
		world.setBlock(i + 2, j + 15, k + 1, Blocks.glass, 0, 3);
		world.setBlock(i + 3, j + 15, k + 1, Blocks.glass, 0, 3);
		world.setBlock(i + 4, j + 15, k + 1, Blocks.glass, 0, 3);
		world.setBlock(i + 5, j + 15, k + 1, Blocks.glass, 0, 3);
		world.setBlock(i + 6, j + 15, k + 1, Blocks.glass, 0, 3);
		world.setBlock(i + 7, j + 15, k + 1, Blocks.glass, 0, 3);
		world.setBlock(i + 8, j + 15, k + 1, Blocks.glass, 0, 3);
		world.setBlock(i + 9, j + 15, k + 1, Blocks.glass, 0, 3);
		world.setBlock(i + 3, j + 15, k + 2, Blocks.glass, 0, 3);
		world.setBlock(i + 4, j + 15, k + 2, Blocks.glass, 0, 3);
		world.setBlock(i + 5, j + 15, k + 2, Blocks.glass, 0, 3);
		world.setBlock(i + 6, j + 15, k + 2, Blocks.glass, 0, 3);
		world.setBlock(i + 7, j + 15, k + 2, Blocks.glass, 0, 3);
		world.setBlock(i + 8, j + 15, k + 2, Blocks.glass, 0, 3);
		world.setBlock(i + 4, j + 15, k + 3, Blocks.glass, 0, 3);
		world.setBlock(i + 5, j + 15, k + 3, Blocks.glass, 0, 3);
		world.setBlock(i + 6, j + 15, k + 3, Blocks.glass, 0, 3);
		world.setBlock(i + 7, j + 15, k + 3, Blocks.glass, 0, 3);
		world.setBlock(i + 5, j + 15, k + 4, Blocks.glass, 0, 3);
		world.setBlock(i + 6, j + 15, k + 4, Blocks.glass, 0, 3);
		world.setBlock(i + 4, j + 16, k + 1, FaithCraft2.HolyStone, 0, 3);
		world.setBlock(i + 5, j + 16, k + 1, FaithCraft2.HolyStone, 0, 3);
		world.setBlock(i + 6, j + 16, k + 1, FaithCraft2.HolyStone, 0, 3);
		world.setBlock(i + 7, j + 16, k + 1, FaithCraft2.HolyStone, 0, 3);
		world.setBlock(i + 4, j + 16, k + 2, FaithCraft2.HolyStone, 0, 3);
		world.setBlock(i + 7, j + 16, k + 2, FaithCraft2.HolyStone, 0, 3);
		world.setBlock(i + 4, j + 16, k + 3, FaithCraft2.HolyStone, 0, 3);
		world.setBlock(i + 5, j + 16, k + 3, FaithCraft2.HolyStone, 0, 3);
		world.setBlock(i + 6, j + 16, k + 3, FaithCraft2.HolyStone, 0, 3);
		world.setBlock(i + 7, j + 16, k + 3, FaithCraft2.HolyStone, 0, 3);
		world.setBlock(i + 4, j + 17, k + 1, FaithCraft2.HolyStone, 0, 3);
		world.setBlock(i + 5, j + 17, k + 1, FaithCraft2.HolyStone, 0, 3);
		world.setBlock(i + 6, j + 17, k + 1, FaithCraft2.HolyStone, 0, 3);
		world.setBlock(i + 7, j + 17, k + 1, FaithCraft2.HolyStone, 0, 3);
		world.setBlock(i + 4, j + 17, k + 2, FaithCraft2.HolyStone, 0, 3);
		world.setBlock(i + 7, j + 17, k + 2, FaithCraft2.HolyStone, 0, 3);
		world.setBlock(i + 4, j + 17, k + 3, FaithCraft2.HolyStone, 0, 3);
		world.setBlock(i + 5, j + 17, k + 3, Blocks.glass_pane, 0, 3);
		world.setBlock(i + 6, j + 17, k + 3, Blocks.glass_pane, 0, 3);
		world.setBlock(i + 7, j + 17, k + 3, FaithCraft2.HolyStone, 0, 3);
		world.setBlock(i + 4, j + 18, k + 1, FaithCraft2.HolyStone, 0, 3);
		world.setBlock(i + 5, j + 18, k + 1, FaithCraft2.HolyStone, 0, 3);
		world.setBlock(i + 6, j + 18, k + 1, FaithCraft2.HolyStone, 0, 3);
		world.setBlock(i + 7, j + 18, k + 1, FaithCraft2.HolyStone, 0, 3);
		world.setBlock(i + 4, j + 18, k + 2, FaithCraft2.HolyStone, 0, 3);
		world.setBlock(i + 7, j + 18, k + 2, FaithCraft2.HolyStone, 0, 3);
		world.setBlock(i + 4, j + 18, k + 3, FaithCraft2.HolyStone, 0, 3);
		world.setBlock(i + 5, j + 18, k + 3, Blocks.glass_pane, 0, 3);
		world.setBlock(i + 6, j + 18, k + 3, Blocks.glass_pane, 0, 3);
		world.setBlock(i + 7, j + 18, k + 3, FaithCraft2.HolyStone, 0, 3);
		world.setBlock(i + 4, j + 19, k + 1, FaithCraft2.HolyStone, 0, 3);
		world.setBlock(i + 5, j + 19, k + 1, FaithCraft2.HolyStone, 0, 3);
		world.setBlock(i + 6, j + 19, k + 1, FaithCraft2.HolyStone, 0, 3);
		world.setBlock(i + 7, j + 19, k + 1, FaithCraft2.HolyStone, 0, 3);
		world.setBlock(i + 4, j + 19, k + 2, FaithCraft2.HolyStone, 0, 3);
		world.setBlock(i + 7, j + 19, k + 2, FaithCraft2.HolyStone, 0, 3);
		world.setBlock(i + 4, j + 19, k + 3, FaithCraft2.HolyStone, 0, 3);
		world.setBlock(i + 5, j + 19, k + 3, Blocks.glass_pane, 0, 3);
		world.setBlock(i + 6, j + 19, k + 3, Blocks.glass_pane, 0, 3);
		world.setBlock(i + 7, j + 19, k + 3, FaithCraft2.HolyStone, 0, 3);
		world.setBlock(i + 4, j + 20, k + 1, FaithCraft2.HolyStone, 0, 3);
		world.setBlock(i + 5, j + 20, k + 1, FaithCraft2.HolyStone, 0, 3);
		world.setBlock(i + 6, j + 20, k + 1, FaithCraft2.HolyStone, 0, 3);
		world.setBlock(i + 7, j + 20, k + 1, FaithCraft2.HolyStone, 0, 3);
		world.setBlock(i + 4, j + 20, k + 2, FaithCraft2.HolyStone, 0, 3);
		world.setBlock(i + 7, j + 20, k + 2, FaithCraft2.HolyStone, 0, 3);
		world.setBlock(i + 4, j + 20, k + 3, FaithCraft2.HolyStone, 0, 3);
		world.setBlock(i + 5, j + 20, k + 3, FaithCraft2.HolyStone, 0, 3);
		world.setBlock(i + 6, j + 20, k + 3, FaithCraft2.HolyStone, 0, 3);
		world.setBlock(i + 7, j + 20, k + 3, FaithCraft2.HolyStone, 0, 3);
		world.setBlock(i + 4, j + 21, k + 1, Blocks.stone_brick_stairs, 0, 3);
		world.setBlock(i + 5, j + 21, k + 1, Blocks.stone_brick_stairs, 2, 3);
		world.setBlock(i + 6, j + 21, k + 1, Blocks.stone_brick_stairs, 2, 3);
		world.setBlock(i + 7, j + 21, k + 1, Blocks.stone_brick_stairs, 1, 3);
		world.setBlock(i + 4, j + 21, k + 2, Blocks.stone_brick_stairs, 0, 3);
		world.setBlock(i + 5, j + 21, k + 2, FaithCraft2.HolyStone, 0, 3);
		world.setBlock(i + 6, j + 21, k + 2, FaithCraft2.HolyStone, 0, 3);
		world.setBlock(i + 7, j + 21, k + 2, Blocks.stone_brick_stairs, 1, 3);
		world.setBlock(i + 4, j + 21, k + 3, Blocks.stone_brick_stairs, 0, 3);
		world.setBlock(i + 5, j + 21, k + 3, Blocks.stone_brick_stairs, 3, 3);
		world.setBlock(i + 6, j + 21, k + 3, Blocks.stone_brick_stairs, 3, 3);
		world.setBlock(i + 7, j + 21, k + 3, Blocks.stone_brick_stairs, 3, 3);
		world.setBlock(i + 5, j + 22, k + 2, Blocks.stonebrick, 1, 3);
		world.setBlock(i + 6, j + 22, k + 2, Blocks.stonebrick, 1, 3);
		world.setBlock(i + 5, j + 23, k + 2, Blocks.stonebrick, 1, 3);
		world.setBlock(i + 6, j + 23, k + 2, Blocks.stonebrick, 1, 3);
		world.setBlock(i + 5, j + 24, k + 2, Blocks.glowstone, 0, 3);
		world.setBlock(i + 6, j + 24, k + 2, Blocks.glowstone, 0, 3);
		world.setBlock(i + 5, j + 25, k + 2, Blocks.stone_slab, 0, 3);
		world.setBlock(i + 6, j + 25, k + 2, Blocks.stone_slab, 0, 3);
		
		ItemDoor.placeDoorBlock(world, i + 5, j + 1, k + 10, 3, Blocks.iron_door);
		ItemDoor.placeDoorBlock(world, i + 6, j + 1, k + 10, 3, Blocks.iron_door);
			
			}
		}
	}

	private ItemStack pickCheckLootItem(Random rand) {
		return null;
	}

	private void generateStructureChestContents(World world, Random rand,
			int i, int j, int k, WeightedRandomChestContent[] churchGenChest,
			int l) {
		
	}

	@Override
	public boolean generate(World var1, Random var2, int var3, int var4,
			int var5) {
		return false;
	}
	
	protected static final WeightedRandomChestContent[] Church_Gen_Chest = new WeightedRandomChestContent[] {
			new WeightedRandomChestContent(Items.diamond, 0, 1, 3, 5),
			new WeightedRandomChestContent(new ItemStack(FaithCraft2.Cross), 1, 7, 100),
			new WeightedRandomChestContent(new ItemStack(FaithCraft2.HolyCross), 1, 1, 1000)};
}